File: Data/Susceptibility/EuPd3S4_MvT_051019Powder_74p93mg_090623.dat
[Header]
; MPMS3 Data File (default extension .dat)
; Copyright (c) 2007, Quantum Design, Inc. All rights reserved.
TITLE,
FILEOPENTIME,3903160051.17246,09/06/2023,11:07 am
BYAPP,MPMS3 w/ AC,1.0,1.1
INFO,MPMS3 Measurement Release 1.1.16 Build 419, MultiVu Release 2.3.4.15,APPNAME
INFO,Linear Motor Servo Controller,MOTOR_MODULE_NAME
INFO,3101-100 F0,MOTOR_HW_VERSION
INFO,MMC1118,MOTOR_SERIAL_NUMBER
INFO,01.04.28,MOTOR_SOFTWARE_VERSION
INFO,Quantum Design Squid Module,SQUID_MODULE_NAME
INFO,3101-501 B0,SQUID_HW_VERSION
INFO,SQM313,SQUID_SERIAL_NUMBER
INFO,01.03.04,SQUID_SOFTWARE_VERSION
INFO,Quantum Design VSM Oven,OVEN_MODULE_NAME
INFO,3101-201 A3,OVEN_HW_VERSION
INFO,OVB345,OVEN_SERIAL_NUMBER
INFO,01.07.07,OVEN_SOFTWARE_VERSION
INFO,SQUID AC,AC_MODULE_NAME
INFO,3101-401 G0,AC_HW_VERSION
INFO,SAC210,AC_SERIAL_NUMBER
INFO,SQUID AC 00.95.07,AC_SOFTWARE_VERSION
INFO,TCI318,COIL_SERIAL_NUMBER
INFO,0,MOMENT_UNITS
INFO,EuPd3S4,SAMPLE_MATERIAL
INFO,Powder,SAMPLE_COMMENT
INFO,74.93,SAMPLE_MASS
INFO,,SAMPLE_VOLUME
INFO,,SAMPLE_MOLECULAR_WEIGHT
INFO,,SAMPLE_SIZE
INFO,,SAMPLE_SHAPE
INFO,Straw,SAMPLE_HOLDER
INFO,Standard,SAMPLE_HOLDER_DETAIL
INFO,70.27,SAMPLE_OFFSET
DATATYPE,COMMENT,1
DATATYPE,TIME,2
STARTUPAXIS,X,2
STARTUPAXIS,Y1,5
FIELDGROUP, VSM,2,3,4,5,6,8,9,10,11,14,15
FIELDGROUP, DC, 2,3,4,14,56,57,58,59,60,61,62,63,64,65,66,67,68,69
FIELDGROUP, AC, 2,3,4,11,16,17,18,19,20,21,22,23,24,25,26,27,28,29,30
STARTUPGROUP, All
[Data]
Comment,Time Stamp (sec),Temperature (K),Magnetic Field (Oe),Moment (emu),M. Std. Err. (emu),Transport Action,Averaging Time (sec),Frequency (Hz),Peak Amplitude (mm),Center Position (mm),Lockin Signal' (V),Lockin Signal (V),Range,M. Quad. Signal (emu),AC Moment (emu),AC M. Std Err. (emu),AC Phase (deg),AC Phase Std. Err. (deg),AC Susceptibility (emu/Oe),AC Suscept. Std Err. (emu/Oe),AC X' (emu/Oe),AC X' Std Err. (emu/Oe),AC X'' (emu/Oe),AC X'' Std Err. (emu/Oe),AC Drive (Oe),AC Frequency (Hz),AC Averaging Time (sec),AC Cycles,AC Range,AC Measure Type,AC Signal' (V),AC Signal'' (V),AC Trim Coil Ratio,AC Trim Coil Phase,Min. Temperature (K),Max. Temperature (K),Min. Field (Oe),Max. Field (Oe),Mass (grams),Motor Lag (deg),Pressure (Torr),Measure Count,Measurement Number,SQUID Status (code),Motor Status (code),Measure Status (code),Motor Current (amps),Motor Temp. (C),Temp. Status (code),Field Status (code),Chamber Status (code),Chamber Temp (K),Redirection State,Evercool Status,Average Temp (K),Rotation Angle (deg),Rotator state,DC Moment Fixed Ctr (emu),DC Moment Err Fixed Ctr (emu),DC Moment Free Ctr (emu),DC Moment Err Free Ctr (emu),DC Fixed Fit,DC Free Fit,DC Calculated Center (mm),DC Calculated Center Err (mm),DC Scan Length (mm),DC Scan Time (s),DC Number of Points,DC Squid Drift,DC Min V (V),DC Max V (V),DC Scans per Measure,Map 01,Map 02,Map 03,Map 04,Map 05,Map 06,Map 07,Map 08,Map 09,Map 10,Map 11,Map 12,Map 13,Map 14,Map 15,Map 16
,3903161302.83762,2.00031185150146,500.010986328125,,,3,,,,28.0456981658936,,,,,,,,,,,,,,,,,,,,,,,,,2.00031185150146,2.00031185150146,500.010986328125,500.010986328125,,,2.98672223091126,,0,,,,,,5,1,1,2.00031185150146,0,0,0,,,,,,,,,,,,,,,,,,,,,,,,,,,,,,,,,
,3903161363.19344,2.42677867412567,500.010986328125,,,6,,,,28.0456981658936,,,100,,,,,,,,,,,,,,,,,,,,,,2.39751505851746,2.4382312297821,500.010986328125,500.010986328125,,,3.23944115638733,,1,0,0,0,0,28.3479976654053,6,1,1,2.45604228973389,0,4232058112,2.41395533084869,,,0.111151016035247,0.00547631431571595,0.111153518477174,0.00547631996694858,0.989599943161011,0.991925299167633,28.0208644866943,,30,1,200,-0.0155828343704343,-4.30274057388306,0.920334935188294,1,,,,,,,,,,,,,,,,
,3903161396.58815,2.91129124164581,500.010986328125,,,6,,,,28.0456981658936,,,100,,,,,,,,,,,,,,,,,,,,,,2.88254761695862,2.92327213287354,500.010986328125,500.010986328125,,,3.54596853256226,,1,0,0,0,0,27.3704795837402,6,1,1,2.94003486633301,0,4232058400,2.89883607625961,,,0.113700537645083,0.00560200104863091,0.113704639116365,0.0056020043026588,0.988392412662506,0.992014944553375,28.0137729644775,0.395496070384979,30,1,200,-0.0173690486699343,-4.40700054168701,0.935835838317871,1,,,,,,,,,,,,,,,,
,3903161430.33738,3.40905296802521,500.010986328125,,,6,,,,28.0456981658936,,,100,,,,,,,,,,,,,,,,,,,,,,3.37868642807007,3.42063236236572,500.010986328125,500.010986328125,,,3.78959393501282,,1,0,0,0,0,28.3479976654053,6,1,1,3.43941950798035,0,4232058336,3.39600157737732,,,0.100163957012587,0.00493519718345628,0.100167974617046,0.00493520064296511,0.986134529113769,0.989348888397217,28.0120582580566,0,30,1,200,-0.020253935828805,-3.91960144042969,0.814132034778595,1,,,,,,,,,,,,,,,,
,3903161463.93061,3.91249370574951,500.010986328125,,,6,,,,28.0456981658936,,,100,,,,,,,,,,,,,,,,,,,,,,3.8814013004303,3.92678713798523,500.010986328125,500.010986328125,,,4.03230714797974,,1,0,0,0,0,28.8367557525635,6,1,1,3.94358611106873,0,4232058144,3.90090209245682,,,0.0840906581194497,0.00414326705983981,0.084094057139446,0.00414327466981296,0.985799431800842,0.988841950893402,28.0124092102051,3.51887433680531E-6,30,1,200,-0.0170250404626131,-3.28480386734009,0.691715002059937,1,,,,,,,,,,,,,,,,
,3903161503.59081,4.51103901863098,500.010986328125,,,6,,,,28.0507625650634,,,100,,,,,,,,,,,,,,,,,,,,,,4.48070907592773,4.52577686309814,500.010986328125,500.010986328125,,,4.26332712173462,,1,0,0,0,0,28.8367557525635,6,1,1,4.54136896133423,0,4232058080,4.50121963024139,,,0.0696552294194084,0.00343203870854541,0.0696588354113913,0.00343204902519425,0.98529702425003,0.989106476306915,28.0133399963379,0,30,1,200,-0.0134695991873741,-2.72397327423096,0.56820410490036,1,,,,,,,,,,,,,,,,
,3903161537.07409,5.03364086151123,500.010986328125,,,6,,,,28.0507625650634,,,100,,,,,,,,,,,,,,,,,,,,,,5.00244045257568,5.04580020904541,500.010986328125,500.010986328125,,,4.4458270072937,,1,0,0,0,0,28.8367557525635,6,1,1,5.06484127044678,0,4232058464,5.02296888828278,,,0.0603912497377789,0.00297556213824114,0.0603941675266986,0.0029755681660882,0.98582136631012,0.989585041999817,28.0142993927002,0.18632672727108,30,1,200,-0.0112087465822697,-2.36221432685852,0.489687830209732,1,,,,,,,,,,,,,,,,
,3903161570.84937,5.54186201095581,500.010986328125,,,6,,,,28.0507625650634,,,100,,,,,,,,,,,,,,,,,,,,,,5.51066160202026,5.55360269546509,500.010986328125,500.010986328125,,,4.61141633987427,,1,0,0,0,0,28.3479976654053,6,1,1,5.57306241989136,0,4232058144,5.53276216983795,,,0.0533089404938996,0.00262659139839562,0.0533114560935795,0.00262659875894607,0.986244022846222,0.989976584911346,28.0150566101074,0,30,1,200,-0.00977871101349592,-2.0865638256073,0.430601507425308,1,,,,,,,,,,,,,,,,
,3903161604.35459,6.04979133605957,500.010986328125,,,6,,,,28.0507625650634,,,100,,,,,,,,,,,,,,,,,,,,,,6.01613998413086,6.06394720077515,500.010986328125,500.010986328125,,,4.74841642379761,,1,0,0,0,0,28.8367557525635,6,1,1,6.08344268798828,0,4232058304,6.03972542285919,,,0.047752426934874,0.00235280515621401,0.0477545472978742,0.00235280873396178,0.986587643623352,0.990297436714172,28.0156650543213,0.101904407143593,30,1,200,-0.00851387158036232,-1.86309254169464,0.391921430826187,1,,,,,,,,,,,,,,,,
,3903161638.077,6.56557488441467,500.010986328125,,,6,,,,28.0507625650634,,,100,,,,,,,,,,,,,,,,,,,,,,6.53254222869873,6.5809326171875,500.010986328125,500.010986328125,,,4.87080240249634,,1,0,0,0,0,26.881721496582,6,1,1,6.59860754013062,0,4232058144,6.55761349201202,,,0.0431127897232063,0.00212420036597919,0.0431146594825679,0.00212420355130598,0.986762821674347,0.990434646606445,28.0160865783691,5.29302263259888,30,1,200,-0.00761372270062566,-1.68311059474945,0.353730738162994,1,,,,,,,,,,,,,,,,
,3903161671.85411,7.09552764892578,500.010986328125,,,6,,,,28.0507625650634,,,100,,,,,,,,,,,,,,,,,,,,,,7.0647029876709,7.10758543014526,500.010986328125,500.010986328125,,,4.98989677429199,,1,0,0,0,0,28.3479976654053,6,1,1,7.12635231018066,0,4232058464,7.08664095401764,,,0.0392476970910649,0.00193375773440053,0.0392493610941957,0.00193376164395216,0.987063109874725,0.990692794322968,28.0167064666748,,30,1,200,-0.0068371114321053,-1.52892172336578,0.320102453231812,1,,,,,,,,,,,,,,,,
,3903161705.38081,7.59807729721069,500.010986328125,,,6,,,,28.0507625650634,,,100,,,,,,,,,,,,,,,,,,,,,,7.57493019104004,7.61311531066895,500.010986328125,500.010986328125,,,5.09020900726318,,1,0,0,0,0,28.3479976654053,6,1,1,7.62539529800415,0,4232058336,7.59377038478851,,,0.0361310734016676,0.0017801923599705,0.0361325333295762,0.001780194931857,0.987347185611725,0.990934669971466,28.0173091888428,,30,1,200,-0.00618340820074081,-1.41148924827576,0.296399533748627,1,,,,,,,,,,,,,,,,
,3903161739.18779,8.12476015090942,500.010986328125,,,6,,,,28.0507625650634,,,100,,,,,,,,,,,,,,,,,,,,,,8.09914875030518,8.14295864105225,500.010986328125,500.010986328125,,,5.17963409423828,,1,0,0,0,0,28.3479976654053,6,1,1,8.15616035461426,0,4232058112,8.12091159820557,,,0.0333591478037355,0.00164361729049693,0.0333604708186497,0.00164362018758442,0.987423658370972,0.990923583507538,28.0177688598633,0,30,1,200,-0.0057464730925858,-1.29549741744995,0.275135964155197,1,,,,,,,,,,,,,,,,
,3903161772.43326,8.6613507270813,500.010986328125,,,6,,,,28.0507625650634,,,100,,,,,,,,,,,,,,,,,,,,,,8.62436771392822,8.67375087738037,500.010986328125,500.010986328125,,,5.2672061920166,,1,0,0,0,0,29.3255138397217,6,1,1,8.69833374023437,0,4232058336,8.65025162696838,,,0.0309666184461446,0.00152573383338948,0.0309678129283131,0.00152573616710846,0.987565279006958,0.991025269031525,28.0181446075439,5.36743450164795,30,1,200,-0.00529005704447627,-1.20310497283936,0.25454843044281,1,,,,,,,,,,,,,,,,
,3903161805.65102,9.18899011611938,500.010986328125,,,6,,,,28.0507625650634,,,100,,,,,,,,,,,,,,,,,,,,,,9.1596212387085,9.20904350280762,500.010986328125,500.010986328125,,,5.34868574142456,,1,0,0,0,0,28.3479976654053,6,1,1,9.21835899353027,0,4232058176,9.18561887741089,,,0.0288962324314341,0.00142372276780158,0.0288973048521443,0.00142372442454316,0.987734198570252,0.99113655090332,28.018627166748,2.0053294065292E-5,30,1,200,-0.00489334762096405,-1.12156426906586,0.238054722547531,1,,,,,,,,,,,,,,,,
,3903161839.43013,9.73563385009766,500.010986328125,,,6,,,,28.0507625650634,,,100,,,,,,,,,,,,,,,,,,,,,,9.70557594299316,9.74854755401611,500.010986328125,500.010986328125,,,5.42131090164185,,1,0,0,0,0,28.3479976654053,6,1,1,9.76569175720215,0,4232058176,9.72706270217896,,,0.0270613007566607,0.00133331307714465,0.0270622953104451,0.00133331549512197,0.987862050533295,0.991198718547821,28.0190830230713,0.186314597725868,30,1,200,-0.00455346377566457,-1.05921685695648,0.222145333886147,1,,,,,,,,,,,,,,,,
,3903161873.16268,10.2685070037842,500.010986328125,,,6,,,,28.0507625650634,,,100,,,,,,,,,,,,,,,,,,,,,,10.2354354858398,10.287992477417,500.010986328125,500.010986328125,,,5.49826574325562,,1,0,0,0,0,28.3479976654053,6,1,1,10.3015785217285,0,4232058336,10.2640075683594,,,0.0254449974082871,0.00125367502204599,0.0254459067498422,0.00125367753489931,0.98800539970398,0.991258561611176,28.0196361541748,,30,1,200,-0.00425231503322721,-0.993436872959137,0.212015822529793,1,,,,,,,,,,,,,,,,
,3903161906.63422,10.8097705841064,500.010986328125,,,6,,,,28.0507625650634,,,100,,,,,,,,,,,,,,,,,,,,,,10.7756481170654,10.8275899887085,500.010986328125,500.010986328125,,,5.56451988220215,,1,0,0,0,0,28.3479976654053,6,1,1,10.8438930511475,0,4232058176,10.8033518791199,,,0.0240129144840665,0.00118311437626291,0.0240137277960126,0.00118311588955804,0.988147556781769,0.991322040557861,28.0201663970947,2.41216724816695E-7,30,1,200,-0.00399870378896594,-0.933960437774658,0.195148304104805,1,,,,,,,,,,,,,,,,
,3903161946.43862,11.4541425704956,500.010986328125,,,6,,,,28.055771571655,,,100,,,,,,,,,,,,,,,,,,,,,,11.420599937439,11.4743585586548,500.010986328125,500.010986328125,,,5.63543462753296,,1,0,0,0,0,28.3479976654053,6,1,1,11.4876852035522,0,4232058336,11.449809551239,,,0.0225059564643627,0.0011088778525732,0.022506949098008,0.00110887906402592,0.987332999706268,0.991372227668762,28.0206203460693,0,30,1,200,-0.00375710078515112,-0.871888279914856,0.18621289730072,1,,,,,,,,,,,,,,,,
,3903161979.77273,11.9906740188599,500.010986328125,,,6,,,,28.055771571655,,,100,,,,,,,,,,,,,,,,,,,,,,11.9562673568726,12.0079641342163,500.010986328125,500.010986328125,,,5.69173955917358,,1,0,0,0,0,28.8367557525635,6,1,1,12.0250806808472,0,4232058176,11.9842665195465,,,0.0213862985098219,0.00105371086877138,0.021387223155757,0.00105371201432493,0.987425088882446,0.991406738758087,28.0209770202637,3.9091382859624E-6,30,1,200,-0.00353522086516023,-0.834080517292023,0.171200945973396,1,,,,,,,,,,,,,,,,
,3903162013.16801,12.5360584259033,500.010986328125,,,6,,,,28.055771571655,,,100,,,,,,,,,,,,,,,,,,,,,,12.5045852661133,12.5513029098511,500.010986328125,500.010986328125,,,5.74561977386475,,1,0,0,0,0,28.8367557525635,6,1,1,12.5675315856934,0,4232058176,12.5283985137939,,,0.0203655963022043,0.00100341869830975,0.0203664454083729,0.00100341939337468,0.987537860870361,0.991437613964081,28.0214576721191,5.36787605285645,30,1,200,-0.00339843332767487,-0.788731873035431,0.16843655705452,1,,,,,,,,,,,,,,,,
,3903162046.81434,13.0786185264587,500.010986328125,,,6,,,,28.055771571655,,,100,,,,,,,,,,,,,,,,,,,,,,13.0455665588379,13.0982141494751,500.010986328125,500.010986328125,,,5.80030536651611,,1,0,0,0,0,28.3479976654053,6,1,1,13.1116704940796,0,4232058208,13.0739583969116,,,0.0194279202478887,0.000957217311370424,0.0194287137118026,0.000957218665941343,0.987696826457977,0.991483807563782,28.0221176147461,1.36409937567805E-6,30,1,200,-0.00316527718678117,-0.757125020027161,0.155842840671539,1,,,,,,,,,,,,,,,,
,3903162080.4213,13.6288151741028,500.010986328125,,,6,,,,28.055771571655,,,100,,,,,,,,,,,,,,,,,,,,,,13.5957021713257,13.6453857421875,500.010986328125,500.010986328125,,,5.84537124633789,,1,0,0,0,0,28.3479976654053,6,1,1,13.6619281768799,0,4232058176,13.6212556362152,,,0.0185735352348097,0.000915120811816981,0.0185742735973972,0.000915121877599265,0.987768650054932,0.991488993167877,28.0224781036377,0,30,1,200,-0.00302893086336553,-0.72828471660614,0.154141202569008,1,,,,,,,,,,,,,,,,
,3903162114.12181,14.1798334121704,500.010986328125,,,6,,,,28.055771571655,,,100,,,,,,,,,,,,,,,,,,,,,,14.1456356048584,14.198616027832,500.010986328125,500.010986328125,,,5.89145660400391,,1,0,0,0,0,28.8367557525635,6,1,1,14.2140312194824,0,4232058176,14.1728990077972,,,0.0177903571342675,0.00087653258864298,0.0177910390050189,0.000876533422174478,0.987862169742584,0.991480469703674,28.023006439209,0,30,1,200,-0.00293301185593009,-0.691096842288971,0.144788786768913,1,,,,,,,,,,,,,,,,
,3903162147.65898,14.7273812294006,500.010986328125,,,6,,,,28.055771571655,,,100,,,,,,,,,,,,,,,,,,,,,,14.6963233947754,14.7485275268555,500.010986328125,500.010986328125,,,5.92508602142334,,1,0,0,0,0,28.3479976654053,6,1,1,14.7584390640259,0,4232058240,14.7227623462677,,,0.0170727328342068,0.000841173711807145,0.0170733607240515,0.000841174423953684,0.98800665140152,0.991515398025513,28.0236473083496,0,30,1,200,-0.00280712079256773,-0.667062163352966,0.134961992502213,1,,,,,,,,,,,,,,,,
,3903162181.10927,15.3163976669312,500.010986328125,,,6,,,,28.055771571655,,,100,,,,,,,,,,,,,,,,,,,,,,15.2698392868042,15.3427276611328,500.010986328125,500.010986328125,,,5.97369956970215,,1,0,0,0,0,28.8367557525635,2,1,1,15.3629560470581,0,4232058144,15.3092064857483,,,0.0163611274285565,0.000806111672526716,0.0163617095457644,0.000806112481217022,0.988130629062653,0.991530120372772,28.0242576599121,1,30,1,200,-0.00271836714819074,-0.632421791553497,0.136228963732719,1,,,,,,,,,,,,,,,,
,3903162214.49794,15.8772649765015,500.010986328125,,,6,,,,28.055771571655,,,100,,,,,,,,,,,,,,,,,,,,,,15.8435220718384,15.8967027664185,500.010986328125,500.010986328125,,,5.98693656921387,,1,0,0,0,0,28.3479976654053,2,1,1,15.9110078811646,0,4232058112,15.8696343898773,,,0.0157464262667552,0.000775825138021664,0.0157469835586666,0.000775825979500828,0.988149225711822,0.991524398326874,28.0243797302246,0,30,1,200,-0.00255766534246504,-0.611777484416962,0.127809956669807,1,,,,,,,,,,,,,,,,
,3903162248.04621,16.4280138015747,500.010986328125,,,6,,,,28.055771571655,,,100,,,,,,,,,,,,,,,,,,,,,,16.3979358673096,16.4457263946533,500.010986328125,500.010986328125,,,6.00503253936768,,1,0,0,0,0,27.8592376708984,2,1,1,16.4613265991211,0,4232058208,16.4222259521484,,,0.015177855007527,0.000747811529282362,0.0151783793273403,0.000747811978205152,0.988195240497589,0.991545915603638,28.0245475769043,,30,1,200,-0.00248642405495048,-0.592907547950745,0.119880601763725,1,,,,,,,,,,,,,,,,
,3903162281.74143,16.9789514541626,500.010986328125,,,6,,,,28.055771571655,,,100,,,,,,,,,,,,,,,,,,,,,,16.9446258544922,16.999137878418,500.010986328125,500.010986328125,,,6.02179718017578,,1,0,0,0,0,28.3479976654053,2,1,1,17.013277053833,0,4232058304,16.9728598594666,,,0.0146479887269424,0.000721704058757008,0.014648485432546,0.000721704641434651,0.988296031951904,0.99158650636673,28.0249366760254,,30,1,200,-0.00237045367248356,-0.57596743106842,0.122138127684593,1,,,,,,,,,,,,,,,,
,3903162315.15654,17.531063079834,500.010986328125,,,6,,,,28.055771571655,,,100,,,,,,,,,,,,,,,,,,,,,,17.4979228973389,17.5502185821533,500.010986328125,500.010986328125,,,6.04848146438599,,1,0,0,0,0,28.3479976654053,2,1,1,17.5642032623291,0,4232058272,17.5235209465027,,,0.0141617275692825,0.000697745912861385,0.0141622048073129,0.000697746735437666,0.988338768482208,0.991576731204987,28.0252056121826,2.48030772809216E-7,30,1,200,-0.00228805677033961,-0.549245595932007,0.11575148254633,1,,,,,,,,,,,,,,,,
,3903162349.2027,18.0842313766479,500.010986328125,,,6,,,,28.055771571655,,,100,,,,,,,,,,,,,,,,,,,,,,18.0512523651123,18.1055545806885,500.010986328125,500.010986328125,,,6.06982707977295,,1,0,0,0,0,28.8367557525635,2,1,1,18.1172103881836,0,4232058208,18.0788254737854,,,0.0137004993510235,0.000675020325679021,0.0137009461992478,0.000675020931331678,0.988402605056763,0.991569638252258,28.0255889892578,,30,1,200,-0.00219042110256851,-0.534032762050629,0.109276928007603,1,,,,,,,,,,,,,,,,
,3903162382.60729,18.6345052719116,500.010986328125,,,6,,,,28.055771571655,,,100,,,,,,,,,,,,,,,,,,,,,,18.6002902984619,18.6534996032715,500.010986328125,500.010986328125,,,6.09399223327637,,1,0,0,0,0,28.8367557525635,2,1,1,18.6687202453613,0,4232058208,18.6263928413391,,,0.0132761686130324,0.000654113294360979,0.0132765931890655,0.000654114065950766,0.988491773605347,0.991582989692688,28.0260257720947,,30,1,200,-0.00211593299172819,-0.520037829875946,0.103264160454273,1,,,,,,,,,,,,,,,,
,3903162416.20335,19.1833086013794,500.010986328125,,,6,,,,28.055771571655,,,100,,,,,,,,,,,,,,,,,,,,,,19.1498908996582,19.2030410766602,500.010986328125,500.010986328125,,,6.11809873580933,,1,0,0,0,0,28.3479976654053,2,1,1,19.2167263031006,0,4232058208,19.1777262687683,,,0.0128750276812476,0.000634348440378632,0.0128754254419528,0.000634348985812561,0.988551199436188,0.991573035717011,28.0263996124268,0.18631374835968,30,1,200,-0.00206961669027805,-0.506730258464813,0.10813020914793,1,,,,,,,,,,,,,,,,
,3903162449.43351,19.7308502197266,500.010986328125,,,6,,,,28.055771571655,,,100,,,,,,,,,,,,,,,,,,,,,,19.6992988586426,19.7521419525146,500.010986328125,500.010986328125,,,6.14130735397339,,1,0,0,0,0,28.3479976654053,2,1,1,19.7624015808105,0,4232058432,19.7268147468567,,,0.0125003982866176,0.000615890048450084,0.0125007710850168,0.000615890577316595,0.988655269145966,0.991586863994598,28.0269260406494,0,30,1,200,-0.0019890065304935,-0.483460545539856,0.10338731855154,1,,,,,,,,,,,,,,,,
,3903162482.9848,20.2849559783936,500.010986328125,,,6,,,,28.055771571655,,,100,,,,,,,,,,,,,,,,,,,,,,20.2508926391602,20.3091773986816,500.010986328125,500.010986328125,,,6.16130256652832,,1,0,0,0,0,28.8367557525635,2,1,1,20.3210754394531,0,4232058240,20.2805323600769,,,0.0121432961342577,0.000598295146900982,0.0121436485164829,0.0005982957616468,0.988752067089081,0.991601169109345,28.0274181365967,5.36777448654175,30,1,200,-0.00192744331434369,-0.471728414297104,0.098355270922184,1,,,,,,,,,,,,,,,,
,3903162516.43015,20.8378190994263,500.010986328125,,,6,,,,28.055771571655,,,100,,,,,,,,,,,,,,,,,,,,,,20.8035430908203,20.853443145752,500.010986328125,500.010986328125,,,6.18441724777222,,1,0,0,0,0,28.3479976654053,2,1,1,20.8720951080322,0,4232058272,20.8298759460449,,,0.011807590234527,0.000581754616452547,0.0118079151139289,0.000581754978447021,0.988831341266632,0.991576194763184,28.0279769897461,,30,1,200,-0.0018794487696141,-0.46070384979248,0.0935892835259438,1,,,,,,,,,,,,,,,,
,3903162549.98256,21.3852205276489,500.010986328125,,,6,,,,28.055771571655,,,100,,,,,,,,,,,,,,,,,,,,,,21.3523120880127,21.4047374725342,500.010986328125,500.010986328125,,,6.20579051971436,,1,0,0,0,0,28.3479976654053,2,1,1,21.4181289672852,0,4232058240,21.379542350769,,,0.0114925278916399,0.000566230877213524,0.0114928319651701,0.000566231232690617,0.98894590139389,0.991601347923279,28.0285339355469,2.31906909675672E-7,30,1,200,-0.00182500167284161,-0.450323641300201,0.0891357734799385,1,,,,,,,,,,,,,,,,
,3903162583.58214,21.9390621185303,500.010986328125,,,6,,,,28.055771571655,,,100,,,,,,,,,,,,,,,,,,,,,,21.911714553833,21.9627285003662,500.010986328125,500.010986328125,,,6.22778797149658,,1,0,0,0,0,28.3479976654053,2,1,1,21.9718112945557,0,4232058208,21.9380030632019,,,0.0111935113416363,0.000551497914166978,0.0111937955534916,0.000551498334661483,0.989040553569794,0.991582274436951,28.0291748046875,0.123908519744873,30,1,200,-0.00176370702683926,-0.440456449985504,0.0955396965146065,1,,,,,,,,,,,,,,,,
,3903162623.26963,22.5863008499146,500.010986328125,,,6,,,,28.0607783611585,,,100,,,,,,,,,,,,,,,,,,,,,,22.5528507232666,22.6032199859619,500.010986328125,500.010986328125,,,6.24823713302612,,1,0,0,0,0,28.3479976654053,2,1,1,22.6197509765625,0,4232058464,22.5794277191162,,,0.0108603323689205,0.000535086809765618,0.0108607123194444,0.000535087707925281,0.988288819789886,0.991600811481476,28.0298461914062,3.75092849935754E-6,30,1,200,-0.00168577383738011,-0.418439537286758,0.0913091823458672,1,,,,,,,,,,,,,,,,
,3903162656.58289,23.1316995620728,500.010986328125,,,6,,,,28.0607783611585,,,100,,,,,,,,,,,,,,,,,,,,,,23.0995635986328,23.1506633758545,500.010986328125,500.010986328125,,,6.27049493789673,,1,0,0,0,0,28.3479976654053,2,1,1,23.1638355255127,0,4232058208,23.1259841918945,,,0.0105958644802921,0.000522055678110452,0.0105962139584625,0.000522056298781807,0.988408923149109,0.991587281227112,28.0305614471436,0,30,1,200,-0.00168582703918219,-0.409648895263672,0.0876651033759117,1,,,,,,,,,,,,,,,,
,3903162689.98066,23.6654205322266,500.010986328125,,,6,,,,28.0607783611585,,,100,,,,,,,,,,,,,,,,,,,,,,23.6341209411621,23.6810607910156,500.010986328125,500.010986328125,,,6.28511571884155,,1,0,0,0,0,28.8367557525635,2,1,1,23.696720123291,0,4232058304,23.6576991081238,,,0.010349338425772,0.000509908964735102,0.0103496638817523,0.000509909407061384,0.988507986068726,0.991578876972199,28.0311412811279,5.29444456100464,30,1,200,-0.00162754568737,-0.401083648204803,0.0846014246344566,1,,,,,,,,,,,,,,,,
,3903162723.33528,24.2275676727295,500.010986328125,,,6,,,,28.0607783611585,,,100,,,,,,,,,,,,,,,,,,,,,,24.1985473632813,24.2456970214844,500.010986328125,500.010986328125,,,6.30445528030396,,1,0,0,0,0,27.8592376708984,2,1,1,24.2565879821777,0,4232058464,24.2213621139526,,,0.0101023088553815,0.000497737247785835,0.0101026175865237,0.000497737917911872,0.988626897335053,0.991578221321106,28.031810760498,0,30,1,200,-0.00158760172780603,-0.392910420894623,0.0812394246459007,1,,,,,,,,,,,,,,,,
,3903162756.82334,24.7779169082642,500.010986328125,,,6,,,,28.0607783611585,,,100,,,,,,,,,,,,,,,,,,,,,,24.7436103820801,24.7959327697754,500.010986328125,500.010986328125,,,6.32218217849731,,1,0,0,0,0,26.3929634094238,2,1,1,24.8122234344482,0,4232058272,24.7711391448975,,,0.00987070724590407,0.000486325630406633,0.00987099631381493,0.000486326342382047,0.988762617111206,0.991595089435577,28.032506942749,INF,30,1,200,-0.00155790778808296,-0.385391682386398,0.0778407678008079,1,,,,,,,,,,,,,,,,
,3903162790.23159,25.3276605606079,500.010986328125,,,6,,,,28.0607783611585,,,100,,,,,,,,,,,,,,,,,,,,,,25.2917461395264,25.3481273651123,500.010986328125,500.010986328125,,,6.34081983566284,,1,0,0,0,0,28.3479976654053,2,1,1,25.3635749816895,0,4232058240,25.3211297988892,,,0.00965155880429219,0.000475527309769618,0.00965182048449343,0.000475527877670855,0.988929867744446,0.991590678691864,28.0334930419922,,30,1,200,-0.00151925324462354,-0.378275632858276,0.0746925994753838,1,,,,,,,,,,,,,,,,
,3903162823.97898,25.8834676742554,500.010986328125,,,6,,,,28.0607783611585,,,100,,,,,,,,,,,,,,,,,,,,,,25.8498191833496,25.9021911621094,500.010986328125,500.010986328125,,,6.36088466644287,,1,0,0,0,0,28.8367557525635,2,1,1,25.9171161651611,0,4232058336,25.8770108222961,,,0.00944014828568905,0.000465110744413401,0.00944039252988264,0.000465111380355112,0.98905223608017,0.991582930088043,28.0342464447021,0.311332166194916,30,1,200,-0.00150845560710877,-0.371394127607346,0.0716509744524956,1,,,,,,,,,,,,,,,,
,3903162857.88893,26.4427680969238,500.010986328125,,,6,,,,28.0607783611585,,,100,,,,,,,,,,,,,,,,,,,,,,26.4103107452393,26.459774017334,500.010986328125,500.010986328125,,,6.37894105911255,,1,0,0,0,0,28.8367557525635,2,1,1,26.4752254486084,0,4232058272,26.4351673126221,,,0.00923704557236587,0.000455103017026542,0.00923726570167472,0.000455103462491585,0.98921012878418,0.99159038066864,28.0351581573486,,30,1,200,-0.00144497118890286,-0.364735156297684,0.0794186517596245,1,,,,,,,,,,,,,,,,
,3903162891.58417,26.9927864074707,500.010986328125,,,6,,,,28.0607783611585,,,100,,,,,,,,,,,,,,,,,,,,,,26.9589805603027,27.009485244751,500.010986328125,500.010986328125,,,6.39256954193115,,1,0,0,0,0,29.3255138397217,2,1,1,27.0265922546387,0,4232058208,26.983850479126,,,0.00904458956695016,0.000445620195365433,0.00904478841248678,0.000445620454907989,0.989344894886017,0.991589844226837,28.0359840393066,0,30,1,200,-0.00144080177415162,-0.347347438335419,0.0770822241902351,1,,,,,,,,,,,,,,,,
,3903162925.09619,27.544638633728,500.010986328125,,,6,,,,28.0607783611585,,,100,,,,,,,,,,,,,,,,,,,,,,27.5140552520752,27.5643615722656,500.010986328125,500.010986328125,,,6.40895366668701,,1,0,0,0,0,28.3479976654053,2,1,1,27.5792999267578,0,4232058240,27.5387597084045,,,0.00886036011440852,0.000436542898490129,0.00886054553504281,0.000436543251935699,0.989453375339508,0.991573810577393,28.0367393493652,,30,1,200,-0.00138274463824928,-0.341334372758865,0.0744737014174461,1,,,,,,,,,,,,,,,,
,3903162958.93743,28.1016120910645,500.010986328125,,,6,,,,28.0607783611585,,,100,,,,,,,,,,,,,,,,,,,,,,28.0700302124023,28.1228351593018,500.010986328125,500.010986328125,,,6.42626333236694,,1,0,0,0,0,28.3479976654053,2,1,1,28.1331939697266,0,4232058560,28.0973525047302,,,0.00868250044043843,0.000427779213415479,0.00868266376879094,0.000427779363937941,0.989613950252533,0.991576552391052,28.0377521514893,0,30,1,200,-0.00137074035592377,-0.335476368665695,0.0719626322388649,1,,,,,,,,,,,,,,,,
,3903162992.40354,28.6507434844971,500.010986328125,,,6,,,,28.0607783611585,,,100,,,,,,,,,,,,,,,,,,,,,,28.6163272857666,28.6693572998047,500.010986328125,500.010986328125,,,6.44110870361328,,1,0,0,0,0,28.3479976654053,2,1,1,28.6851596832275,0,4232058432,28.6443719863892,,,0.00851318947243514,0.00041943683406267,0.00851334141024698,0.000419437154259446,0.989739656448364,0.991567313671112,28.0386257171631,0,30,1,200,-0.00134172278922051,-0.329996168613434,0.0694851651787758,1,,,,,,,,,,,,,,,,
,3903163025.86103,29.198977470398,500.010986328125,,,6,,,,28.0607783611585,,,100,,,,,,,,,,,,,,,,,,,,,,29.1651439666748,29.2170886993408,500.010986328125,500.010986328125,,,6.45491123199463,,1,0,0,0,0,28.3479976654053,2,1,1,29.2328109741211,0,4232058304,29.1909947395325,,,0.00835156590988006,0.000411473045154011,0.00835170296561626,0.000411473382141315,0.989911377429962,0.991597652435303,28.0396137237549,0.186315283179283,30,1,200,-0.00129723432473838,-0.324720323085785,0.0671756342053413,1,,,,,,,,,,,,,,,,
,3903163059.47909,29.7540817260742,500.010986328125,,,6,,,,28.0607783611585,,,100,,,,,,,,,,,,,,,,,,,,,,29.7232723236084,29.774787902832,500.010986328125,500.010986328125,,,6.46982097625732,,1,0,0,0,0,27.8592376708984,2,1,1,29.7882118225098,0,4232058272,29.7480821609497,,,0.0081950989639352,0.000403763624665584,0.00819522134213008,0.000403763887569939,0.990036189556122,0.991590678691864,28.0405235290527,0,30,1,200,-0.00128431792836636,-0.319633603096008,0.0649281665682793,1,,,,,,,,,,,,,,,,
,3903163092.82859,30.304404258728,500.010986328125,,,6,,,,28.0607783611585,,,100,,,,,,,,,,,,,,,,,,,,,,30.2715301513672,30.3234157562256,500.010986328125,500.010986328125,,,6.48291540145874,,1,0,0,0,0,28.3479976654053,2,1,1,30.3372783660889,0,4232058272,30.2986969947815,,,0.00804537542174445,0.000396386275564033,0.00804548356243025,0.000396386493969873,0.990174770355225,0.991588294506073,28.0415363311768,0,30,1,200,-0.00125567405484617,-0.314793169498444,0.0627403035759926,1,,,,,,,,,,,,,,,,
,3903163132.66092,30.9558296203613,500.010986328125,,,6,,,,28.0658197516053,,,100,,,,,,,,,,,,,,,,,,,,,,30.9230175018311,30.9769344329834,500.010986328125,500.010986328125,,,6.49553489685059,,1,0,0,0,0,28.3479976654053,2,1,1,30.9886417388916,0,4232058304,30.9503598213196,,,0.00787412237827942,0.000387951122252243,0.00787427388248468,0.000387951348411518,0.989606499671936,0.991590857505798,28.0426692962646,5.36733055114746,30,1,200,-0.00123009481467307,-0.30917102098465,0.0603087320923805,1,,,,,,,,,,,,,,,,
,3903163166.0756,31.5092077255249,500.010986328125,,,6,,,,28.0658197516053,,,100,,,,,,,,,,,,,,,,,,,,,,31.4761962890625,31.5291061401367,500.010986328125,500.010986328125,,,6.51233720779419,,1,0,0,0,0,28.8367557525635,2,1,1,31.5422191619873,0,4232058400,31.5036058425903,,,0.00773557549537359,0.000381124554529353,0.00773571066647327,0.000381124671647471,0.989732921123505,0.991568982601166,28.0436134338379,0.186308965086937,30,1,200,-0.0012083527399227,-0.304652333259583,0.0583010949194431,1,,,,,,,,,,,,,,,,
,3903163199.727,32.0628299713135,500.010986328125,,,6,,,,28.0658197516053,,,100,,,,,,,,,,,,,,,,,,,,,,32.0310707092285,32.0816383361816,500.010986328125,500.010986328125,,,6.52115535736084,,1,0,0,0,0,27.8592376708984,2,1,1,32.0945892333984,0,4232058272,32.0570192337036,,,0.00760175810570968,0.000374530840381029,0.00760187490924947,0.000374530819683208,0.989897429943085,0.991560578346252,28.0447731018066,,30,1,200,-0.00119425007142127,-0.30032742023468,0.0563762374222279,1,,,,,,,,,,,,,,,,
,3903163233.26353,32.6147060394287,500.010986328125,,,6,,,,28.0658197516053,,,100,,,,,,,,,,,,,,,,,,,,,,32.5808753967285,32.6271438598633,500.010986328125,500.010986328125,,,6.53534317016602,,1,0,0,0,0,28.3479976654053,2,1,1,32.6485366821289,0,4232058304,32.6066560745239,,,0.00747289887319383,0.000368181510325603,0.00747300581351965,0.000368181620209376,0.99005651473999,0.991582691669464,28.0457572937012,0.101280406117439,30,1,200,-0.00118252169340849,-0.296126693487167,0.0545210428535938,1,,,,,,,,,,,,,,,,
,3903163266.60298,33.1637382507324,500.010986328125,,,6,,,,28.0658197516053,,,100,,,,,,,,,,,,,,,,,,,,,,33.1288833618164,33.1824493408203,500.010986328125,500.010986328125,,,6.54778051376343,,1,0,0,0,0,28.3479976654053,2,1,1,33.1985931396484,0,4232058272,33.1543245315552,,,0.00734897200181238,0.000362075280862405,0.00734906587330886,0.000362075357279116,0.99018007516861,0.991555571556091,28.0468235015869,2.01049374481954E-7,30,1,200,-0.00116050650831312,-0.292050272226334,0.0635235831141472,1,,,,,,,,,,,,,,,,
,3903163300.35313,33.72532081604,500.010986328125,,,6,,,,28.0658197516053,,,100,,,,,,,,,,,,,,,,,,,,,,33.6885528564453,33.7415351867676,500.010986328125,500.010986328125,,,6.55833625793457,,1,0,0,0,0,28.3479976654053,2,1,1,33.7620887756348,0,4232058240,33.7158870697022,,,0.00722820913713038,0.000356124917094552,0.00722828868606839,0.000356124904506796,0.99035906791687,0.991581678390503,28.0480098724365,0.099623903632164,30,1,200,-0.00113749981392175,-0.277185469865799,0.0619682744145393,1,,,,,,,,,,,,,,,,
,3903163333.74681,34.2676658630371,500.010986328125,,,6,,,,28.0658197516053,,,100,,,,,,,,,,,,,,,,,,,,,,34.2367515563965,34.2855224609375,500.010986328125,500.010986328125,,,6.57091522216797,,1,0,0,0,0,28.3479976654053,2,1,1,34.2985801696777,0,4232058272,34.2614717483521,,,0.0071126780031964,0.000350432319340556,0.00711274837444407,0.00035043233850199,0.990474939346313,0.991570830345154,28.0490074157715,0.186303615570068,30,1,200,-0.00110245647374541,-0.273477613925934,0.0602439120411873,1,,,,,,,,,,,,,,,,
,3903163367.32022,34.8204040527344,500.010986328125,,,6,,,,28.0658197516053,,,100,,,,,,,,,,,,,,,,,,,,,,34.786376953125,34.8396034240723,500.010986328125,500.010986328125,,,6.58321619033814,,1,0,0,0,0,28.3479976654053,2,1,1,34.8544311523438,0,4232058272,34.8133955001831,,,0.0070004660516347,0.000344903421558407,0.0070005257871944,0.000344903425799931,0.990609586238861,0.991565585136414,28.0501766204834,4.12256304116454E-5,30,1,200,-0.00108367693610489,-0.269912213087082,0.0585398860275745,1,,,,,,,,,,,,,,,,
,3903163400.56758,35.3692512512207,500.010986328125,,,6,,,,28.0658197516053,,,100,,,,,,,,,,,,,,,,,,,,,,35.3357696533203,35.376407623291,500.010986328125,500.010986328125,,,6.59380674362183,,1,0,0,0,0,28.3479976654053,2,1,1,35.4027328491211,0,4232058368,35.3606996536255,,,0.00689243965057116,0.000339580803336193,0.00689249053672129,0.000339580789466538,0.990718543529511,0.991556107997894,28.0512180328369,,30,1,200,-0.00107978319283575,-0.266433387994766,0.0569360740482807,1,,,,,,,,,,,,,,,,
,3903163433.96244,35.9207515716553,500.010986328125,,,6,,,,28.0658197516053,,,100,,,,,,,,,,,,,,,,,,,,,,35.895751953125,35.9422645568848,500.010986328125,500.010986328125,,,6.6023736000061,,1,0,0,0,0,28.3479976654053,2,1,1,35.9520111083984,0,4232058304,35.9189453125,,,0.00678745002469625,0.000334407773106486,0.00678749582407536,0.000334407893188127,0.99083149433136,0.991556942462921,28.0522708892822,0,30,1,200,-0.00105215283110738,-0.263102144002914,0.0553737618029118,1,,,,,,,,,,,,,,,,
,3903163467.33177,36.4694557189941,500.010986328125,,,6,,,,28.0658197516053,,,100,,,,,,,,,,,,,,,,,,,,,,36.434684753418,36.4911918640137,500.010986328125,500.010986328125,,,6.61481046676636,,1,0,0,0,0,28.3479976654053,2,1,1,36.5042266845703,0,4232058272,36.4623651504517,,,0.00668615592573944,0.000329416751657729,0.00668619010828753,0.00032941672256551,0.99095892906189,0.991553664207459,28.053596496582,2.44295870288624E-6,30,1,200,-0.00105262594297528,-0.259867399930954,0.0538277663290501,1,,,,,,,,,,,,,,,,
,3903163507.41967,37.1275119781494,500.010986328125,,,6,,,,28.0708317794134,,,100,,,,,,,,,,,,,,,,,,,,,,37.0932464599609,37.1512794494629,500.010986328125,500.010986328125,,,6.62616539001465,,1,0,0,0,0,28.3479976654053,2,1,1,37.1617774963379,0,4232058336,37.1234731674194,,,0.00656828282438786,0.000323610454586999,0.00656834122355625,0.000323610480052852,0.990579426288605,0.991566479206085,28.0549201965332,0.186306819319725,30,1,200,-0.0010147892171517,-0.25602999329567,0.0521323122084141,1,,,,,,,,,,,,,,,,
,3903163540.78276,37.677806854248,500.010986328125,,,6,,,,28.0708317794134,,,100,,,,,,,,,,,,,,,,,,,,,,37.6437187194824,37.6975059509277,500.010986328125,500.010986328125,,,6.63483667373657,,1,0,0,0,0,28.3479976654053,2,1,1,37.7118949890137,0,4232058304,37.6708631515503,,,0.0064731183319315,0.000318921395132304,0.00647316656348325,0.000318921455651799,0.990731775760651,0.991551399230957,28.0563888549805,0,30,1,200,-0.00100165535695851,-0.252952009439468,0.0507400222122669,1,,,,,,,,,,,,,,,,
,3903163574.7342,38.2370624542236,500.010986328125,,,6,,,,28.0708317794134,,,100,,,,,,,,,,,,,,,,,,,,,,38.2025756835937,38.2564506530762,500.010986328125,500.010986328125,,,6.64483165740967,,1,0,0,0,0,28.3479976654053,2,1,1,38.2715492248535,0,4232058240,38.2301797866821,,,0.00637973431775873,0.00031432012050908,0.00637977398839036,0.000314320133586881,0.990851581096649,0.991553604602814,28.0575122833252,5.36780500411987,30,1,200,-0.000997004681266844,-0.249928116798401,0.0493812598288059,1,,,,,,,,,,,,,,,,
,3903163608.02345,38.7856178283691,500.010986328125,,,6,,,,28.0708317794134,,,100,,,,,,,,,,,,,,,,,,,,,,38.7569808959961,38.8049812316895,500.010986328125,500.010986328125,,,6.65074443817139,,1,0,0,0,0,28.3479976654053,2,1,1,38.8181495666504,0,4232058400,38.7806024551392,,,0.00629090279677193,0.000309943261448383,0.00629093601668396,0.000309943301445237,0.990950703620911,0.991539061069489,28.058666229248,,30,1,200,-0.000970939930994064,-0.247017696499825,0.0481219626963139,1,,,,,,,,,,,,,,,,
,3903163641.69484,39.346851348877,500.010986328125,,,6,,,,28.0708317794134,,,100,,,,,,,,,,,,,,,,,,,,,,39.310001373291,39.367504119873,500.010986328125,500.010986328125,,,6.66449356079102,,1,0,0,0,0,27.8592376708984,2,1,1,39.3837013244629,0,4232058368,39.3377084732056,,,0.00620297233433128,0.000305610744094547,0.00620299988546162,0.000305610846827301,0.991061508655548,0.991533219814301,28.0599708557129,0,30,1,200,-0.000971312168985605,-0.244119569659233,0.0468722768127918,1,,,,,,,,,,,,,,,,
,3903163675.07272,39.879056930542,500.010986328125,,,6,,,,28.0708317794134,,,100,,,,,,,,,,,,,,,,,,,,,,39.8591842651367,39.8914222717285,500.010986328125,500.010986328125,,,6.67157554626465,,1,0,0,0,0,27.8592376708984,5,1,1,39.8989295959473,0,4232058336,39.8758010864258,,,0.00612104908907537,0.000301574241451339,0.00612107008947884,0.000301574289027773,0.991147756576538,0.991525530815124,28.0611362457275,5.29727602005005,30,1,200,-0.000942992162890732,-0.241354435682297,0.045755285769701,1,,,,,,,,,,,,,,,,
,3903163708.53291,39.9902744293213,500.010986328125,,,6,,,,28.0708317794134,,,100,,,,,,,,,,,,,,,,,,,,,,39.9887962341309,39.9911575317383,500.010986328125,500.010986328125,,,6.66673517227173,,1,0,0,0,0,28.3479976654053,5,1,1,39.9917526245117,0,4232058304,39.9902505874634,,,0.0061053669089832,0.000300801600024706,0.00610538693335188,0.000300801645704186,0.991167187690735,0.991528689861298,28.061351776123,5.29729652404785,30,1,200,-0.000923486659303308,-0.24090114235878,0.0454108454287052,1,,,,,,,,,,,,,,,,
,3903163755.85419,40.0700836181641,500.010986328125,,,6,,,,28.0708317794134,,,100,,,,,,,,,,,,,,,,,,,,,,40.0071334838867,40.0844612121582,500.010986328125,500.010986328125,,,6.68190431594849,,1,0,0,0,0,28.3479976654053,6,1,1,40.1330337524414,0,4232058272,40.0388717651367,,,0.0060982164606442,0.000300449078750693,0.0060982335250562,0.000300449073957809,0.991251409053802,0.991579174995422,28.0618419647217,0,30,1,200,-0.000957493088208139,-0.24106028676033,0.0451359190046787,1,,,,,,,,,,,,,,,,
,3903163795.82911,45.3048782348633,500.010986328125,,,6,,,,28.0764562139532,,,100,,,,,,,,,,,,,,,,,,,,,,44.9848022460937,45.5066604614258,500.010986328125,500.010986328125,,,6.73901891708374,,1,0,0,0,0,28.3479976654053,2,1,1,45.6249542236328,0,4232058336,45.2388782501221,,,0.00538644459867679,0.000265381995176147,0.00538644469581658,0.000265381985818217,0.990949034690857,0.99095493555069,28.0752182006836,,30,1,200,-0.000972752401139587,-0.206727251410484,0.0468362160027027,1,,,,,,,,,,,,,,,,
,3903163835.68837,51.5344772338867,500.010986328125,,,6,,,,28.0818953223838,,,100,,,,,,,,,,,,,,,,,,,,,,51.2085952758789,51.7145767211914,500.010986328125,500.010986328125,,,6.80678987503052,,1,0,0,0,0,28.3479976654053,2,1,1,51.8603591918945,0,4232058272,51.4675531387329,,,0.00474825146572591,0.000233939492919083,0.00474826414889566,0.000233939544667655,0.990841627120972,0.991113126277924,28.0902843475342,,30,1,200,-0.000848461058922112,-0.185171529650688,0.0382050909101963,1,,,,,,,,,,,,,,,,
,3903163881.93427,58.8081645965576,500.010986328125,,,6,,,,28.0927039883253,,,100,,,,,,,,,,,,,,,,,,,,,,58.4880332946777,58.9402084350586,500.010986328125,500.010986328125,,,6.86481285095215,,1,0,0,0,0,27.8592376708984,2,1,1,59.1282958984375,0,4232058400,58.7238512039185,,,0.00418125920437057,0.000206005897961921,0.0041813002409782,0.000206005860556292,0.990129470825195,0.991200149059296,28.1096515655518,,30,1,200,-0.000724037177860737,-0.166053712368011,0.0305512584745884,1,,,,,,,,,,,,,,,,
,3903163921.7146,65.1374778747559,500.010986328125,,,6,,,,28.097913095418,,,100,,,,,,,,,,,,,,,,,,,,,,64.8231964111328,65.3258209228516,500.010986328125,500.010986328125,,,6.90889978408813,,1,0,0,0,0,28.3479976654053,2,1,1,65.4517593383789,0,4232058240,65.0749092102051,,,0.00379523886797853,0.000186990957091122,0.00379536307479564,0.000186991335799962,0.98823618888855,0.991225481033325,28.127613067627,5.36703014373779,30,1,200,-0.00065612536855042,-0.153003051877022,0.0254072267562151,1,,,,,,,,,,,,,,,,
,3903163967.71361,72.4255409240723,500.010986328125,,,6,,,,28.1092977344062,,,100,,,,,,,,,,,,,,,,,,,,,,72.0962371826172,72.5954513549805,500.010986328125,500.010986328125,,,6.94883155822754,,1,0,0,0,0,28.3479976654053,2,1,1,72.7548446655273,0,4232058272,72.3534679412842,,,0.00343239534410507,0.000169117919503416,0.00343260176556871,0.000169118655896884,0.98627769947052,0.991239309310913,28.1493320465088,,30,1,200,-0.000581175496336073,-0.129863709211349,0.0314450301229954,1,,,,,,,,,,,,,,,,
,3903164013.94132,79.7725601196289,500.010986328125,,,6,,,,28.1198720763568,,,100,,,,,,,,,,,,,,,,,,,,,,79.4493255615234,79.9674606323242,500.010986328125,500.010986328125,,,6.98871994018555,,1,0,0,0,0,28.3479976654053,2,1,1,80.0957946777344,0,4232058336,79.7160911560059,,,0.00313545501786658,0.000154493519016363,0.00313577881540505,0.000154494655443078,0.983613193035126,0.991239666938782,28.1723670959473,3.43012260373143E-7,30,1,200,-0.000538275518920273,-0.119870096445084,0.027451591566205,1,,,,,,,,,,,,,,,,
,3903164060.05138,87.2816505432129,500.010986328125,,,6,,,,28.1314994647447,,,100,,,,,,,,,,,,,,,,,,,,,,86.9440231323242,87.4358978271484,500.010986328125,500.010986328125,,,7.02251768112183,,1,0,0,0,0,27.8592376708984,2,1,1,87.6192779541016,0,4232058240,87.1934700012207,,,0.00288920901666148,0.000142367418041942,0.0028896524617026,0.000142368478183979,0.980781972408295,0.991205215454102,28.1962718963623,0,30,1,200,-0.000481095805298537,-0.111642487347126,0.0240901876240969,1,,,,,,,,,,,,,,,,
,3903164112.54765,95.9382934570312,500.010986328125,,,6,,,,28.1482395837507,,,100,,,,,,,,,,,,,,,,,,,,,,95.6183013916016,96.1063461303711,500.010986328125,500.010986328125,,,7.0540885925293,,1,0,0,0,0,28.3479976654053,2,1,1,96.2582855224609,0,4232058560,95.8551235198975,,,0.00265476173441703,0.000130822428538294,0.00265533992907819,0.00013082426932619,0.977985978126526,0.991206228733063,28.2247428894043,0,30,1,200,-0.000443065713625401,-0.103794269263744,0.0208965707570314,1,,,,,,,,,,,,,,,,
,3903164171.38764,105.602993011475,500.010986328125,,,6,,,,28.1651660656063,,,10,,,,,,,,,,,,,,,,,,,,,,104.925582885742,106.087448120117,500.010986328125,500.010986328125,,,7.08511590957642,,1,0,0,0,0,27.8592376708984,2,1,1,106.280403137207,0,4232058336,105.52454662323,,,0.00242748849217906,0.00011963494341625,0.00242827118076407,0.00011963704084258,0.973766207695007,0.991125404834747,28.2587604522705,0,30,1,200,-0.00410092575475574,-0.967689096927643,0.175174340605736,1,,,,,,,,,,,,,,,,
,3903164277.2861,123.077430725098,500.010986328125,,,6,,,,28.2060317647613,,,10,,,,,,,,,,,,,,,,,,,,,,122.411933898926,123.611663818359,500.010986328125,500.010986328125,,,7.15356254577637,,1,0,0,0,0,28.3479976654053,2,1,1,123.74292755127,0,4232058336,123.025239944458,,,0.00211978762706568,0.000104489062198587,0.00212086843389127,0.000104491852710513,0.967670381069183,0.991073191165924,28.3238372802734,0,30,1,200,-0.00353677314706147,-0.866202175617218,0.131298914551735,1,,,,,,,,,,,,,,,,
,3903164393.30795,142.279693603516,500.010986328125,,,6,,,,28.2595911005178,,,10,,,,,,,,,,,,,,,,,,,,,,141.622573852539,142.831405639648,500.010986328125,500.010986328125,,,7.20689868927002,,1,0,0,0,0,28.3479976654053,2,1,1,142.936813354492,0,4232058400,142.233325958252,,,0.00186525499596416,9.19603745480321E-5,0.00186658055124809,9.19635841380587E-5,0.962158024311066,0.990942895412445,28.3989143371582,0,30,1,200,-0.00309965061023831,-0.782579779624939,0.0948219820857048,1,,,,,,,,,,,,,,,,
,3903164509.4279,161.482292175293,500.010986328125,,,6,,,,28.3211792530623,,,10,,,,,,,,,,,,,,,,,,,,,,160.828994750977,162.002655029297,500.010986328125,500.010986328125,,,7.248450756073,,1,0,0,0,0,28.3479976654053,2,1,1,162.135589599609,0,4232058304,161.415235519409,,,0.00166762244244348,8.22325085075864E-5,0.00166914378277906,8.22362441399186E-5,0.957396328449249,0.990843415260315,28.4789505004883,0.211223125457764,30,1,200,-0.00276884878985584,-0.608236014842987,0.176023483276367,1,,,,,,,,,,,,,,,,
,3903164625.57727,180.716583251953,500.010986328125,,,6,,,,28.3904604143933,,,10,,,,,,,,,,,,,,,,,,,,,,180.063034057617,181.235290527344,500.010986328125,500.010986328125,,,7.28596687316895,,1,0,0,0,0,28.3479976654053,2,1,1,181.370132446289,0,4232058272,180.649377822876,,,0.00150911710485918,7.44298793921154E-5,0.00151077317590939,7.44336410729839E-5,0.953360438346863,0.990772843360901,28.5638275146484,0,30,1,200,-0.00247530755586922,-0.557597577571869,0.15204706788063,1,,,,,,,,,,,,,,,,
,3903164741.49611,199.956359863281,500.010986328125,,,6,,,,28.4673357446398,,,10,,,,,,,,,,,,,,,,,,,,,,199.266036987305,200.505157470703,500.010986328125,500.010986328125,,,7.31731462478638,,1,0,0,0,0,28.3479976654053,2,1,1,200.646682739258,0,4232058304,199.889665603638,,,0.0013790592920123,6.80263521775578E-5,0.0013808099608264,6.8030651569206E-5,0.950038909912109,0.990602910518646,28.6534233093262,5.35288906097412,30,1,200,-0.00228937622159719,-0.517443895339966,0.130909770727158,1,,,,,,,,,,,,,,,,
,3903164857.62559,219.210525512695,500.010986328125,,,6,,,,28.5522076947228,,,10,,,,,,,,,,,,,,,,,,,,,,218.56867980957,219.718215942383,500.010986328125,500.010986328125,,,7.34850025177002,,1,0,0,0,0,28.3479976654053,2,1,1,219.85237121582,0,4232058400,219.137323379517,,,0.00126991756068869,6.26517658442917E-5,0.00127172368529803,6.26561320762393E-5,0.947191119194031,0.990534782409668,28.7492656707764,4.42587207771794E-7,30,1,200,-0.00206496589817107,-0.483608156442642,0.113497160375118,1,,,,,,,,,,,,,,,,
,3903164973.78255,238.478553771973,500.010986328125,,,6,,,,28.6446522334218,,,10,,,,,,,,,,,,,,,,,,,,,,237.835601806641,239.009979248047,500.010986328125,500.010986328125,,,7.39412593841553,,1,0,0,0,0,28.3479976654053,2,1,1,239.121505737305,0,4232058304,238.419202804565,,,0.00117707252815929,5.80782805814E-5,0.0011788985304997,5.80828132964363E-5,0.9449462890625,0.990440845489502,28.8503341674805,,30,1,200,-0.00191782927140594,-0.456605970859528,0.0967340990900993,1,,,,,,,,,,,,,,,,
,3903165090.17529,257.769287109375,500.010986328125,,,6,,,,28.7456392044019,,,10,,,,,,,,,,,,,,,,,,,,,,257.1015625,258.338836669922,500.010986328125,500.010986328125,,,7.55297803878784,,1,0,0,0,0,28.8367557525635,2,1,1,258.43701171875,0,4232058304,257.727115631104,,,0.00109715515019241,5.41415862282134E-5,0.0010989962657013,5.4146163934092E-5,0.942804932594299,0.990388572216034,28.9595203399658,0,30,1,200,-0.00179088301956654,-0.43342399597168,0.0823316797614098,1,,,,,,,,,,,,,,,,
,3903165206.49953,277.099609375,500.010986328125,,,6,,,,28.8542251353832,,,10,,,,,,,,,,,,,,,,,,,,,,276.444610595703,277.594512939453,500.010986328125,500.010986328125,,,7.48333549499512,,1,0,0,0,0,28.3479976654053,2,1,1,277.754608154297,0,4232058304,277.00793838501,,,0.00102748389898802,5.07175781020718E-5,0.00102951231741794,5.072280817041E-5,0.938158392906189,0.990329921245575,29.0859527587891,0.165817409753799,30,1,200,-0.0017064994899556,-0.414272665977478,0.0688628181815147,1,,,,,,,,,,,,,,,,
,3903165323.10537,296.377166748047,500.010986328125,,,6,,,,28.9706438845548,,,10,,,,,,,,,,,,,,,,,,,,,,295.725708007812,296.913543701172,500.010986328125,500.010986328125,,,7.47905158996582,,1,0,0,0,0,28.3479976654053,2,1,1,297.028625488281,0,4232058304,296.325969696045,,,0.000965609988387706,4.77006685309784E-5,0.000968298476056667,4.77068631112962E-5,0.926653325557709,0.990344762802124,29.2465324401855,0.186799481511116,30,1,200,-0.00152236013673246,-0.398251742124558,0.0561390109360218,1,,,,,,,,,,,,,,,,
,3903165368.82825,299.54362487793,500.010986328125,,,6,,,,28.9839055133309,,,10,,,,,,,,,,,,,,,,,,,,,,299.506225585937,299.563781738281,500.010986328125,500.010986328125,,,7.48453044891357,,1,0,0,0,0,28.3479976654053,6,1,1,299.581024169922,0,4232058336,299.536331176758,,,0.000956315922391462,4.72395418838751E-5,0.000958941052037603,4.72458622635474E-5,0.927232086658478,0.990292370319366,29.257568359375,0.116322591900826,30,1,200,-0.00153332506306469,-0.395510971546173,0.0538588352501392,1,,,,,,,,,,,,,,,,
,3903165402.23516,299.855117797852,500.010986328125,,,6,,,,28.9839055133309,,,10,,,,,,,,,,,,,,,,,,,,,,299.846160888672,299.860931396484,500.010986328125,500.010986328125,,,7.49298477172852,,1,0,0,0,0,28.3479976654053,5,1,1,299.864074707031,0,4232058272,299.853797912598,,,0.000955167347927516,4.71872383690293E-5,0.000957880213997686,4.71935970731525E-5,0.925961673259735,0.99031013250351,29.2624588012695,3.76339268684387,30,1,200,-0.00152819498907775,-0.396266907453537,0.0526101179420948,1,,,,,,,,,,,,,,,,
,3903165431.45358,299.941665649414,500.010986328125,,,6,,,,28.9839055133309,,,10,,,,,,,,,,,,,,,,,,,,,,299.938232421875,299.943939208984,500.010986328125,500.010986328125,,,7.50296688079834,,1,0,0,0,0,28.8367557525635,1,1,1,299.945098876953,0,4232058272,299.941291809082,,,0.00095482588997388,4.71734152264659E-5,0.000957604591502521,4.71799824197409E-5,0.925099313259125,0.990385711193085,29.265754699707,,30,1,200,-0.00152205547783524,-0.397245854139328,0.0515520609915257,1,,,,,,,,,,,,,,,,