File: Data/HeatCapacity/0p19mg_drhc_EuPd2S4_09152020_0T_fieldscan.dat
[Header]
TITLE,eupd3s4_longpuse_fieldscan
BYAPP,HeatCapacity,3.8.14,1.7
INFO,0,MASS:Sample Mass (mg)
INFO,0,MASSERR:Sample Mass Error (mg)
INFO,0,MOLWGHT:Formula Weight (g/mole)
INFO,0,ATOMS:Atoms per Formula Unit
INFO,PPMS Heat Capacity Option 3.8.14 Build 19,APPNAME
DATATYPE,TIME,1
DATATYPE,COMMENT,2
STARTUPAXIS, X, 8, LINEAR, AUTO
STARTUPAXIS, Y1, 10, LINEAR, AUTO
[Data]
Time Stamp (Seconds),Comment (),System Status (Code),Puck Temp (Kelvin),System Temp (Kelvin),Field (Oersted),Pressure (Torr),Sample Temp (Kelvin),Temp Rise (Kelvin),Samp HC (µJ/K),Samp HC Err (µJ/K),Addenda HC (µJ/K),Addenda HC Err (µJ/K),Total HC (µJ/K),Total HC Err (µJ/K),Fit Deviation (ChiSquare),Time Const tau1 (seconds),Time Const tau2 (seconds),Sample Coupling (Percent),Debye Temp (Kelvin),Debye Temp Err (Kelvin),Cal Correction (Factor),Therm Resist (Ohms),Htr Resist (Ohms),Puck Resist (Ohms),Wire Cond (W/K),Meas Time (seconds),Temp Squared (K^2),Samp HC/Temp (µJ/K/K),Addenda Offset HC (µJ/K)
22405763.78,Error: Warning: Current field is 1000.007 Oe;
22405763.91,Error: but addenda was obtained at -0.025 Oe.
22405939.88,,4881,0,1.1006,1000.007,9.3E-6,1.10756,0.021778068,1.1560279,0.007123,0.10477894,0.001339,1.2608069,0.007123,0.84358006,8.0600269,0.0041109456,99.327547,0,0,1,,,,1.5732E-7,14,1.2266892,1.043761,0
22405989.89,,4881,0,1.1007,1000.007,9.3E-6,1.1089112,0.023749543,1.1648026,0.007409,0.10502005,0.001343,1.2698226,0.007409,0.13248418,7.9723726,0.0045287583,99.247338,0,0,1,,,,1.6029E-7,16.12005,1.2296841,1.050402,0
22406041.55,,4881,0,1.1004,1000.007,9.2E-6,1.1091061,0.023622258,1.1635195,0.007745,0.1050571,0.001343,1.2685766,0.007745,0.11411726,7.99387,0.0047911236,99.206617,0,0,1,,,,1.5976E-7,15.94475,1.2301164,1.0490606,0
22406285.88,,4881,0,1.1671,1000.007,9.3E-6,1.1756871,0.024676433,1.2807931,0.00732,0.11786087,0.001573,1.398654,0.00732,0.86815739,8.0687799,0.0043427456,99.299187,0,0,1,,,,1.7437E-7,15.98774,1.3822402,1.0893996,0
22406336.55,,4881,0,1.1672,1000.007,9.3E-6,1.1763693,0.024818298,1.2769634,0.007234,0.11797661,0.001576,1.3949401,0.007234,0.83351189,7.8365452,0.0035790634,99.407717,0,0,1,,,,1.7889E-7,16.13756,1.3838446,1.0855124,0
22406388.91,,4881,0,1.1664,1000.007,9.3E-6,1.1758349,0.02475443,1.2733083,0.008497,0.11788858,0.001574,1.3911969,0.008497,0.15398569,8.0430276,0.0043609887,99.297558,0,0,1,,,,1.7399E-7,15.67309,1.3825877,1.0828972,0
22406610.45,,4881,0,1.2311,1000.007,9.2E-6,1.2403702,0.026121202,1.3880928,0.008437,0.12899266,0.001926,1.5170854,0.008437,1.3628004,8.0343635,0.00355103,99.42968,0,0,1,,,,1.8973E-7,16.08606,1.5385182,1.1190956,0
22406661.73,,4881,0,1.2311,1000.007,9.3E-6,1.2406102,0.026473342,1.3817635,0.00847,0.12904292,0.001928,1.5108065,0.00847,0.34913002,8.0727908,0.0049888179,99.204638,0,0,1,,,,1.884E-7,16.06873,1.5391136,1.1137773,0
22406712.81,,4881,0,1.2311,1000.007,9.3E-6,1.2408363,0.026493151,1.375564,0.00862,0.12906974,0.001929,1.5046338,0.00862,0.35767355,7.9226378,0.0033359194,99.461133,0,0,1,,,,1.9078E-7,16.14558,1.5396746,1.1085782,0
22406930.59,,4881,0,1.2973,1000.007,9.3E-6,1.3071329,0.027562095,1.4835938,0.009124,0.14112031,0.002201,1.6247141,0.009124,0.97775144,8.019017,0.0047565354,99.248354,0,0,1,,,,2.0389E-7,15.84528,1.7085964,1.1349985,0
22406982.42,,4881,0,1.2969,1000.007,9.4E-6,1.3077201,0.027737169,1.4923637,0.008581,0.14123698,0.002201,1.6336007,0.008581,0.5963189,7.9081882,0.0037413515,99.398581,0,0,1,,,,2.0761E-7,16.03803,1.710132,1.141195,0
22407032.39,,4881,0,1.2965,1000.007,9.3E-6,1.3073809,0.027669972,1.4813226,0.009105,0.14116562,0.002201,1.6224882,0.009105,0.22581413,7.89208,0.004714167,99.244207,0,0,1,,,,2.0689E-7,15.81638,1.7092448,1.1330459,0
22407250.44,,4881,0,1.3615,1000.007,9.3E-6,1.3738914,0.029005273,1.5829477,0.005572,0.1569849,0.001922,1.7399327,0.005572,0.96404496,7.9422773,0.0042711884,99.341996,0,0,1,,,,2.2027E-7,15.78416,1.8875775,1.1521637,0
22407302.02,,4881,0,1.3619,1000.007,9.3E-6,1.3745249,0.029209668,1.5910382,0.00601,0.15714971,0.001917,1.7481879,0.00601,0.28264274,7.8796374,0.0044946489,99.299542,0,0,1,,,,2.2316E-7,15.88455,1.8893188,1.1575186,0
22407353.83,,4881,0,1.3618,1000.007,9.3E-6,1.3738826,0.029181356,1.5844969,0.006154,0.15698381,0.001922,1.7414807,0.006154,0.17213572,7.8867209,0.0047715668,99.258722,0,0,1,,,,2.2218E-7,15.75927,1.8875535,1.1532986,0
22407570.7,,4881,0,1.4277,1000.007,9.4E-6,1.4409029,0.030567612,1.6822106,0.005598,0.17537241,0.001413,1.857583,0.005598,0.98866002,7.9021369,0.0052670286,99.216443,0,0,1,,,,2.366E-7,15.77344,2.0762011,1.1674698,0
22407621.64,,4881,0,1.428,1000.007,9.3E-6,1.4411168,0.030701626,1.6877385,0.006391,0.17542009,0.001412,1.8631586,0.006391,0.2300504,7.7876553,0.003814788,99.423509,0,0,1,,,,2.4038E-7,15.80427,2.0768175,1.1711324,0
22407672.94,,4881,0,1.4283,1000.007,9.4E-6,1.4410375,0.030568102,1.6829307,0.006272,0.17540865,0.001412,1.8583393,0.006272,0.2661271,7.868085,0.0057121316,99.146004,0,0,1,,,,2.3786E-7,15.57531,2.076589,1.1678604,0
22407889.41,,4881,0,1.4927,1000.007,9.4E-6,1.506592,0.032087281,1.7729355,0.006137,0.1945714,0.001249,1.9675069,0.006137,1.0610716,7.8089085,0.0057055969,99.175818,0,0,1,,,,2.5366E-7,15.73617,2.2698194,1.1767855,0
22407940.61,,4881,0,1.4932,1000.007,9.4E-6,1.5072286,0.032069169,1.7868792,0.006905,0.19474566,0.001248,1.9816248,0.006905,0.21727525,7.7514252,0.0028741382,99.580481,0,0,1,,,,2.5652E-7,15.61782,2.2717381,1.1855396,0
22407990.61,,4881,0,1.4934,1000.007,9.4E-6,1.5070063,0.032046143,1.7736361,0.006791,0.1946801,0.001248,1.9683162,0.006791,0.30038159,7.7221225,0.0044488106,99.350946,0,0,1,,,,2.5625E-7,15.50285,2.2710679,1.1769269,0
22408206.78,,4881,0,1.5593,1000.007,9.2E-6,1.573967,0.033487018,1.8574474,0.00679,0.21570545,0.00131,2.0731529,0.00679,1.0354052,7.7082262,0.00402244,99.438299,0,0,1,,,,2.7017E-7,15.44425,2.4773722,1.1801057,0
22408257.78,,4881,0,1.559,1000.007,9.3E-6,1.5740881,0.033673248,1.8509096,0.007197,0.21574826,0.00131,2.0666578,0.007197,0.18012422,7.6470249,0.0054537354,99.23364,0,0,1,,,,2.7193E-7,15.41645,2.4777534,1.1758615,0
22408308.66,,4881,0,1.5595,1000.007,9.2E-6,1.5741656,0.033507343,1.8575337,0.007151,0.21577558,0.00131,2.0733092,0.007151,0.31513686,7.7008194,0.0054625516,99.235684,0,0,1,,,,2.709E-7,15.29405,2.4779973,1.1800116,0
22408524.88,,4881,0,1.624,1000.007,9.3E-6,1.6400683,0.035099476,1.9265912,0.006375,0.23824098,0.001418,2.1648321,0.006375,0.75472031,7.6136187,0.0060290377,99.187586,0,0,1,,,,2.8618E-7,15.40164,2.6898241,1.1747018,0
22408575.7,,4881,0,1.6242,1000.007,9.3E-6,1.6402443,0.035139456,1.9242972,0.007195,0.23828645,0.001418,2.1625837,0.007195,0.29406018,7.5391791,0.0045506629,99.382124,0,0,1,,,,2.8826E-7,15.22724,2.6904015,1.1731772,0
22408626.67,,4881,0,1.6241,1000.007,9.3E-6,1.6404094,0.03450974,1.9370506,0.0109,0.2384081,0.001418,2.1754587,0.0109,0.05167708,7.4963003,0.0066777995,99.082126,0,0,1,,,,2.9234E-7,15.07836,2.6909429,1.1808336,0
22408840.7,,4881,0,1.6901,1000.007,9.3E-6,1.7063113,0.03628507,1.996735,0.007748,0.26247541,0.001536,2.2592105,0.007748,1.0028196,7.4888116,0.0034683714,99.547804,0,0,1,,,,3.0275E-7,14.9926,2.9114984,1.1702056,0
22408890.72,,4881,0,1.6902,1000.007,9.4E-6,1.7067364,0.036578931,1.9981311,0.007836,0.26266009,0.001537,2.2607911,0.007836,0.36720262,7.514803,0.0050799214,99.339204,0,0,1,,,,3.0241E-7,14.97762,2.912949,1.1707321,0
22408940.83,,4881,0,1.6903,1000.007,9.2E-6,1.7068347,0.036678638,1.9889481,0.008327,0.26269718,0.001537,2.2516453,0.008327,0.20496554,7.4781949,0.005571595,99.274086,0,0,1,,,,3.0281E-7,15.02961,2.9132846,1.1652846,0
22409155.47,,4881,0,1.7548,1000.007,9.4E-6,1.7723693,0.037937914,2.0453481,0.007709,0.28852126,0.001701,2.3338694,0.007709,1.059507,7.2880298,0.0033743049,99.571664,0,0,1,,,,3.2129E-7,14.95639,3.1412928,1.1540192,0
22409205.45,,4881,0,1.7552,1000.007,9.4E-6,1.7726846,0.03780604,2.0532745,0.008467,0.28869434,0.001702,2.3419689,0.008467,0.46068597,7.4559896,0.006034916,99.248009,0,0,1,,,,3.1594E-7,14.57606,3.1424107,1.1582853,0
22409254.84,,4881,0,1.7554,1000.007,9.4E-6,1.7725048,0.038373675,2.0446933,0.008919,0.28863899,0.001701,2.3333323,0.008919,0.21652508,7.4151768,0.0065413113,99.182603,0,0,1,,,,3.1666E-7,14.91198,3.1417734,1.1535615,0
22409468.2,,4881,0,1.8208,1000.007,9.3E-6,1.8396586,0.039620769,2.1075282,0.008478,0.31773868,0.001943,2.4252669,0.008478,1.0214462,7.3104027,0.0060456792,99.270862,0,0,1,,,,3.336E-7,14.83035,3.3843436,1.1456083,0
22409518.2,,4881,0,1.8209,1000.007,9.2E-6,1.8397564,0.039446665,2.1143037,0.008803,0.31776602,0.001944,2.4320697,0.008803,0.58280002,7.2793769,0.0057804893,99.298352,0,0,1,,,,3.3589E-7,14.62081,3.3847036,1.1492302,0
22409567.53,,4881,0,1.8206,1000.007,9.3E-6,1.8398925,0.039524551,2.1113324,0.008859,0.31784015,0.001944,2.4291726,0.008859,0.42028813,7.3204661,0.0057375141,99.308354,0,0,1,,,,3.3358E-7,14.55875,3.3852044,1.1475303,0
22409778.7,,4881,0,1.886,1000.007,9.2E-6,1.9061076,0.040913972,2.165605,0.008453,0.34883734,0.002322,2.5144424,0.008453,0.9646048,7.1951411,0.0055147875,99.356523,0,0,1,,,,3.5114E-7,14.64093,3.6332463,1.1361399,0
22409830.17,,4881,0,1.8862,1000.007,9.3E-6,1.9057146,0.040879474,2.1613717,0.008866,0.34862042,0.002319,2.5099921,0.008866,0.44893312,7.1481754,0.0037144784,99.564605,0,0,1,,,,3.5228E-7,14.39028,3.6317482,1.1341529,0
22409880.2,,4881,0,1.8859,1000.007,9.4E-6,1.9053632,0.040764102,2.1595832,0.009097,0.34847817,0.002317,2.5080613,0.009097,0.36902226,7.2156948,0.0062177495,99.277204,0,0,1,,,,3.4946E-7,14.29635,3.6304088,1.1334234,0
22410093.61,,4881,0,1.9519,1000.007,9.3E-6,1.9721331,0.042094833,2.2279056,0.00905,0.38243916,0.002675,2.6103447,0.00905,0.95851919,7.1792677,0.0064662815,99.277298,0,0,1,,,,3.6552E-7,14.43139,3.8893092,1.1296933,0
22410144.28,,4881,0,1.9523,1000.007,9.3E-6,1.9724028,0.042123105,2.2304523,0.0109,0.3825771,0.002676,2.6130294,0.0109,0.55955367,7.1369365,0.0072812404,99.180564,0,0,1,,,,3.6833E-7,14.35854,3.8903728,1.13083,0
22410195,,4881,0,1.952,1000.007,9.2E-6,1.9726223,0.042368193,2.2067376,0.01035,0.38271402,0.002677,2.5894516,0.01035,0.4536471,7.1469961,0.0079039218,99.118418,0,0,1,,,,3.6466E-7,14.27387,3.8912389,1.1186822,0
22410409.48,,4881,0,2.017,1000.007,9.3E-6,2.0381859,0.043310649,2.2684781,0.009877,0.4192818,0.002806,2.6877599,0.009877,1.6420253,7.0680834,0.0069613419,99.249535,0,0,1,,,,3.8232E-7,14.29399,4.1542019,1.1129888,0
22410459.48,,4881,0,2.0167,1000.007,9.3E-6,2.0383738,0.043456652,2.2615178,0.01109,0.4194526,0.002806,2.6809704,0.01109,0.42422481,7.1371534,0.010714808,98.85687,0,0,1,,,,3.7873E-7,14.13617,4.1549678,1.1094715,0
22410508.5,,4881,0,2.017,1000.007,9.2E-6,2.038524,0.043614584,2.2710724,0.01001,0.41951586,0.002806,2.6905883,0.01001,0.40104826,7.1032068,0.007893004,99.152605,0,0,1,,,,3.8109E-7,14.27431,4.1555799,1.1140769,0
22410720.05,,4881,0,2.0831,1000.007,9.2E-6,2.1050687,0.044491889,2.3347437,0.01048,0.46001813,0.002641,2.7947619,0.01048,1.0297421,7.0914232,0.0085821191,99.116767,0,0,1,,,,3.9656E-7,14.20641,4.4313144,1.1091057,0
22410769.98,,4881,0,2.0833,1000.007,9.2E-6,2.1053762,0.044489742,2.3388506,0.0116,0.46012241,0.00264,2.798973,0.0116,0.83913586,6.9612015,0.0038142003,99.600485,0,0,1,,,,4.0321E-7,14.18285,4.4326091,1.1108943,0
22410819.48,,4881,0,2.0833,1000.007,9.3E-6,2.1050907,0.044237763,2.3261227,0.01027,0.46016778,0.00264,2.7862905,0.01027,0.37791974,7.006799,0.006478251,99.327636,0,0,1,,,,3.9953E-7,13.9224,4.4314068,1.1049988,0
22411028.66,,4881,0,2.1481,1000.007,9.3E-6,2.1708666,0.04544421,2.3849355,0.01096,0.50321786,0.002363,2.8881534,0.01096,0.95521709,6.9533545,0.0064811202,99.350618,0,0,1,,,,4.1721E-7,14.0136,4.7126618,1.0986099,0
22411077.23,,4881,0,2.1484,1000.007,9.3E-6,2.1712237,0.045555851,2.3836981,0.01083,0.50346796,0.002362,2.887166,0.01083,0.45147865,6.9375587,0.0072835232,99.268823,0,0,1,,,,4.1826E-7,13.90671,4.7142123,1.0978593,0
22411127.17,,4881,0,2.1481,1000.007,9.3E-6,2.1713353,0.045367926,2.3831359,0.01183,0.50348066,0.002362,2.8866165,0.01183,0.63835329,6.8679541,0.0052203761,99.471114,0,0,1,,,,4.2183E-7,13.87512,4.7146971,1.0975439,0
22411336.61,,4881,0,2.2132,1000.007,9.3E-6,2.238257,0.046196837,2.4586426,0.006269,0.55014968,0.002177,3.0087923,0.006269,1.1510125,6.9980743,0.0074788809,99.282992,0,0,1,,,,4.3202E-7,13.73591,5.0097946,1.098463,0
22411385.64,,4881,0,2.2138,1000.007,9.3E-6,2.2406873,0.047248133,2.4429384,0.007207,0.55191933,0.002175,2.9948577,0.007207,0.32711919,6.9238323,0.0061889168,99.404204,0,0,1,,,,4.3427E-7,13.99615,5.0206795,1.090263,0
22411434.08,,4881,0,2.214,1000.007,9.3E-6,2.2360083,0.046527465,2.4627316,0.007602,0.54852472,0.00218,3.0112563,0.007602,0.17282942,6.9211653,0.0066062435,99.357889,0,0,1,,,,4.3696E-7,13.84766,4.9997332,1.1013964,0
22411641.8,,4881,0,2.2788,1000.007,9.4E-6,2.3037436,0.048054212,2.5014708,0.00699,0.59795353,0.002188,3.0994244,0.00699,1.2955638,6.9612614,0.0075941655,99.297855,0,0,1,,,,4.4729E-7,13.84233,5.3072344,1.0858287,0
22411689.8,,4881,0,2.2791,1000.007,9.3E-6,2.3045893,0.048537196,2.5031328,0.008028,0.59860555,0.002189,3.1017383,0.008028,0.15190968,6.9313974,0.0076683388,99.288108,0,0,1,,,,4.4958E-7,13.92252,5.3111321,1.0861513,0
22411740.19,,4881,0,2.2788,1000.007,9.4E-6,2.3027557,0.048283145,2.5040047,0.007165,0.59725146,0.002188,3.1012561,0.007165,0.31314236,6.9624005,0.0087946446,99.185608,0,0,1,,,,4.4782E-7,13.86279,5.302684,1.0873948,0
22411952.19,,4881,0,2.3457,1000.007,9.3E-6,2.369275,0.049638211,2.5734119,0.007248,0.64805339,0.002297,3.2214653,0.007248,1.9365994,6.9429067,0.0057965518,99.479709,0,0,1,,,,4.6554E-7,13.9248,5.6134638,1.0861601,0
22412001.56,,4881,0,2.3449,1000.007,9.3E-6,2.3674139,0.049689569,2.5802503,0.007681,0.6466789,0.002293,3.2269293,0.007681,0.42750497,6.9970426,0.010434489,99.066882,0,0,1,,,,4.6397E-7,13.88581,5.6046488,1.0899025,0
22412050.52,,4881,0,2.345,1000.007,9.4E-6,2.370573,0.050132134,2.5647812,0.008251,0.64909631,0.0023,3.2138775,0.008251,0.22139085,6.9022621,0.0061159352,99.449404,0,0,1,,,,4.6727E-7,13.99409,5.6196163,1.0819246,0
22412258.53,,4881,0,2.4096,1000.007,9.3E-6,2.4389487,0.050797843,2.6293828,0.008185,0.70511803,0.002476,3.3345008,0.008185,2.1909789,7.0006335,0.0090290552,99.225029,0,0,1,,,,4.7863E-7,13.80452,5.9484706,1.0780804,0
22412306.52,,4881,0,2.4099,1000.007,9.3E-6,2.4384912,0.051324525,2.6297785,0.009629,0.70474211,0.002475,3.3345206,0.009629,0.12107895,6.9449336,0.0089401505,99.2262,0,0,1,,,,4.8247E-7,14.00127,5.9462395,1.0784449,0
22412355.17,,4881,0,2.4097,1000.007,9.3E-6,2.4389572,0.05130179,2.6334778,0.009319,0.70514259,0.002476,3.3386204,0.009319,0.15287161,6.963847,0.0085574203,99.261043,0,0,1,,,,4.8165E-7,13.88987,5.948512,1.0797557,0
22412565.66,,4881,0,2.4757,1000.007,9.2E-6,2.5006178,0.052182439,2.6931266,0.007236,0.75982632,0.002654,3.4529529,0.007236,1.2970674,6.9759412,0.0092095969,99.229474,0,0,1,,,,4.9732E-7,13.92769,6.2530894,1.0769845,0
22412615.47,,4881,0,2.4756,1000.007,9.4E-6,2.5057192,0.053040939,2.6896542,0.007962,0.76462148,0.00267,3.4542756,0.007962,0.20443001,7.00324,0.007871216,99.346979,0,0,1,,,,4.9521E-7,13.95188,6.2786287,1.0734061,0
22412666.48,,4881,0,2.4762,1000.007,9.4E-6,2.5016599,0.05282521,2.6975312,0.007883,0.76089409,0.002657,3.4584253,0.007883,0.50844554,7.0081354,0.010892851,99.092431,0,0,1,,,,4.9624E-7,14.00648,6.2583022,1.0782965,0
22412873.81,,4881,0,2.5405,1000.007,9.2E-6,2.5724557,0.054553027,2.6987359,0.007901,0.82848693,0.002929,3.5272229,0.007901,0.80527072,6.9620418,0.008930131,99.285367,0,0,1,,,,5.0877E-7,14.01627,6.6175283,1.0490894,0
22412922.42,,4881,0,2.5418,1000.007,9.4E-6,2.5662623,0.054406709,2.7126745,0.008178,0.82238158,0.002901,3.5350561,0.008178,0.35686358,6.912836,0.010773222,99.125613,0,0,1,,,,5.1404E-7,13.92408,6.585702,1.0570527,0
22412971.58,,4881,0,2.5405,1000.007,9.2E-6,2.5706667,0.054119149,2.7116416,0.009274,0.82673591,0.002921,3.5383775,0.009274,0.24403394,6.982381,0.011583054,99.07199,0,0,1,,,,5.0955E-7,13.82567,6.6083274,1.0548398,0
22413179.98,,4881,0,2.6069,1000.007,9.4E-6,2.6349321,0.055771665,2.7529215,0.008431,0.89193624,0.003225,3.6448577,0.008431,1.3264968,6.8815562,0.0079714546,99.372697,0,0,1,,,,5.3157E-7,13.96476,6.942867,1.0447789,0
22413229.45,,4881,0,2.6071,1000.007,9.3E-6,2.6335456,0.055505219,2.7588014,0.008858,0.89045766,0.003218,3.6492591,0.008858,0.23713796,6.8892989,0.0074939768,99.409816,0,0,1,,,,5.315E-7,13.76311,6.9355622,1.0475617,0
22413277.64,,4881,0,2.6071,1000.007,9.2E-6,2.6364306,0.055684495,2.7584381,0.009793,0.89349778,0.003232,3.6519359,0.009793,0.23690183,6.8817181,0.0081533592,99.3583,0,0,1,,,,5.3263E-7,13.7786,6.9507664,1.0462775,0
22413486.97,,4881,0,2.6716,1000.007,9.2E-6,2.7026447,0.056463625,2.8146186,0.009288,0.96534705,0.003533,3.7799657,0.009288,1.6677622,6.974069,0.01196118,99.09717,0,0,1,,,,5.4475E-7,13.76344,7.3042885,1.0414312,0
22413537.27,,4881,0,2.672,1000.007,9.3E-6,2.7015699,0.057413119,2.8301586,0.008893,0.96421548,0.003529,3.7943741,0.008893,0.3990367,6.9604473,0.010116805,99.232479,0,0,1,,,,5.4748E-7,13.94814,7.2984798,1.0475978,0
22413586.89,,4881,0,2.672,1000.007,9.4E-6,2.7002595,0.057152088,2.8391446,0.009141,0.96272655,0.003524,3.8018711,0.009141,0.52662014,6.9570078,0.010474394,99.203062,0,0,1,,,,5.4893E-7,13.92089,7.2914015,1.051434,0
22413797.47,,4881,0,2.738,1000.007,9.4E-6,2.7676613,0.057157907,2.9897275,0.01065,1.0405516,0.003748,4.0302792,0.01065,1.0210575,7.1259029,0.0081096627,99.405427,0,0,1,,,,5.6745E-7,13.91402,7.6599489,1.0802361,0
22413848.13,,4881,0,2.7379,1000.007,9.2E-6,2.7690463,0.058272824,3.0076145,0.01046,1.041852,0.00375,4.0494665,0.01046,0.44235793,7.1479021,0.007228015,99.470518,0,0,1,,,,5.6819E-7,14.25181,7.6676171,1.0861554,0
22413900.09,,4881,0,2.7377,1000.007,9.3E-6,2.7676766,0.058408638,2.9796942,0.0107,1.0402128,0.003747,4.019907,0.0107,0.40270177,7.0982595,0.008693984,99.361018,0,0,1,,,,5.6833E-7,14.2958,7.660034,1.0766049,0
22414144.02,,4881,0,2.8028,1000.007,9.3E-6,2.8360971,0.057202015,3.2592533,0.01271,1.1247774,0.003798,4.3840307,0.01271,1.1528899,7.4419219,0.0047369978,99.666162,0,0,1,,,,5.9019E-7,14.19652,8.0434465,1.1492037,0
22414195.22,,4881,0,2.8035,1000.007,9.3E-6,2.827245,0.058812144,3.2727235,0.01452,1.1138458,0.003804,4.3865693,0.01452,1.3180704,7.4688251,0.0094908486,99.328712,0,0,1,,,,5.8953E-7,14.88384,7.9933144,1.1575663,0
22414245.39,,4881,0,2.8032,1000.007,9.2E-6,2.8315356,0.0594365,3.2681251,0.01525,1.1193898,0.003801,4.3875149,0.01525,0.26045469,7.5014065,0.0087362927,99.386744,0,0,1,,,,5.869E-7,14.93765,8.0175941,1.1541882,0
22414455.61,,4881,0,2.8698,1000.007,9.3E-6,2.9028932,0.067870638,2.6192166,0.03263,1.2143007,0.003676,3.8335173,0.03263,27.528498,7.0544977,0.043430225,97.159754,0,0,1,,,,5.5088E-7,15.00281,8.4267887,0.902278,0
22414505.05,,4881,0,2.8689,1000.007,9.2E-6,2.8960266,0.065351983,2.6643082,0.0335,1.2045101,0.003693,3.8688183,0.0335,7.8835915,6.9776025,0.037590794,97.489871,0,0,1,,,,5.6127E-7,14.109,8.3869703,0.91998747,0
22414554.44,,4881,0,2.8685,1000.007,9.3E-6,2.8992156,0.064985331,2.6620412,0.03359,1.2092125,0.003685,3.8712537,0.03359,17.247968,6.9371641,0.027441748,98.159882,0,0,1,,,,5.6301E-7,13.9552,8.4054513,0.91819358,0
22414810.28,,4881,0,2.9342,1000.007,9.4E-6,2.9664128,0.063923912,1.6907958,0.00881,1.3014678,0.003526,2.9922637,0.00881,1.2137384,5.0550298,0.021786488,98.257272,0,0,1,,,,5.953E-7,10.06949,8.7996049,0.56997995,0
22414855.63,,4881,0,2.9342,1000.007,9.3E-6,2.9640264,0.063791689,1.6848473,0.008339,1.2978677,0.003531,2.982715,0.008339,1.6971354,4.9589708,0.019723751,98.391116,0,0,1,,,,6.0463E-7,10.11006,8.7854524,0.56843196,0
22414899.61,,4881,0,2.9338,1000.007,9.4E-6,2.9623663,0.063262583,1.6930411,0.008468,1.296485,0.003533,2.9895261,0.008468,1.9207608,4.9933489,0.021380587,98.267291,0,0,1,,,,6.021E-7,9.917942,8.7756141,0.57151645,0
22415104.58,,4881,0,2.9999,1000.007,9.3E-6,3.0310405,0.068649373,1.3445675,0.005895,1.3942942,0.003452,2.7388617,0.005895,0.60402705,4.4564596,0.027062363,97.600102,0,0,1,,,,6.1825E-7,9.986698,9.1872062,0.44359932,0
22415148.58,,4881,0,2.9997,1000.007,9.4E-6,3.0300995,0.065267404,1.3331164,0.006298,1.3933577,0.003452,2.7264741,0.006298,0.61814961,4.4497064,0.020939898,98.13493,0,0,1,,,,6.1553E-7,8.912919,9.1815031,0.43995795,0
22415192.45,,4881,0,3.0002,1000.007,9.3E-6,3.0315791,0.064659019,1.3426135,0.00634,1.3955502,0.003452,2.7381637,0.00634,0.71845756,4.45599,0.025765465,97.713495,0,0,1,,,,6.1797E-7,8.899413,9.1904716,0.44287597,0
22415426.75,Error: Warning: Current field is 2333.347 Oe;
22415427.08,Error: but addenda was obtained at -0.025 Oe.
22415737.05,,4881,0,1.0996,2333.347,9.3E-6,1.1066982,0.021391589,1.1836755,0.007918,0.10461611,0.001336,1.2882916,0.007918,0.93302122,8.2497645,0.0061346723,98.99637,0,0,1,,,,1.575E-7,14,1.224781,1.0695558,0
22415790.34,,4881,0,1.1003,2333.347,9.2E-6,1.1084019,0.023880527,1.185821,0.006063,0.10490716,0.001341,1.2907282,0.006063,0.74415145,8.1863203,0.0050246671,99.173292,0,0,1,,,,1.5878E-7,16.49953,1.2285549,1.0698475,0
22415842.42,,4881,0,1.1002,2333.347,9.3E-6,1.1086673,0.02346643,1.1892925,0.007894,0.10493511,0.001341,1.2942276,0.007894,0.13874025,7.9541607,0.0033292105,99.436032,0,0,1,,,,1.6349E-7,16.37264,1.2291432,1.0727226,0
22416086.48,,4881,0,1.1664,2333.347,9.3E-6,1.174766,0.024335521,1.2937364,0.007584,0.11768302,0.00157,1.4114194,0.007584,1.4339596,8.0735971,0.0046549907,99.241666,0,0,1,,,,1.7594E-7,15.90832,1.3800752,1.1012716,0
22416137.47,,4881,0,1.1665,2333.347,9.3E-6,1.1749825,0.025010532,1.2791856,0.007771,0.11773989,0.001571,1.3969255,0.007771,0.63495393,8.0867925,0.0059335807,99.043097,0,0,1,,,,1.7414E-7,16.14719,1.3805839,1.0886848,0
22416188.77,,4881,0,1.1662,2333.347,9.3E-6,1.1750704,0.02511358,1.2738058,0.007463,0.11775249,0.001571,1.3915583,0.007463,0.3850932,8.0459435,0.0041533737,99.330531,0,0,1,,,,1.7393E-7,16.17359,1.3807904,1.0840251,0
22416407.05,,4881,0,1.2313,2333.347,9.4E-6,1.2398606,0.026208651,1.3961344,0.007964,0.12892669,0.001924,1.5250611,0.007964,1.0636757,8.2946592,0.0054736574,99.142328,0,0,1,,,,1.8519E-7,16.09189,1.5372544,1.1260414,0
22416459.55,,4881,0,1.231,2333.347,9.3E-6,1.239906,0.026793292,1.3861499,0.008013,0.12890334,0.001923,1.5150532,0.008013,0.50466406,8.0494275,0.0051270941,99.177161,0,0,1,,,,1.8953E-7,16.58932,1.5373669,1.1179476,0
22416511.67,,4881,0,1.2316,2333.347,9.4E-6,1.2402597,0.026421105,1.3929494,0.008355,0.12899335,0.001927,1.5219427,0.008355,0.77953627,8.2487474,0.005115175,99.196213,0,0,1,,,,1.8576E-7,16.09886,1.5382441,1.123111,0
22416732.41,,4881,0,1.2974,2333.347,9.2E-6,1.3065065,0.028205231,1.4918656,0.008105,0.14098352,0.0022,1.6328492,0.008105,0.98296273,8.2004219,0.0066888338,98.958727,0,0,1,,,,2.0087E-7,16.49749,1.7069592,1.1418739,0
22416784.77,,4881,0,1.2967,2333.347,9.3E-6,1.3068756,0.028072774,1.4902005,0.009329,0.14102537,0.0022,1.6312259,0.009329,0.50404316,7.8514557,0.0031491082,99.490421,0,0,1,,,,2.0865E-7,16.40084,1.7079238,1.1402773,0
22416836.05,,4881,0,1.2967,2333.347,9.2E-6,1.3063517,0.027508109,1.4964937,0.009415,0.14096799,0.0022,1.6374617,0.009415,0.84946206,8.1315648,0.0064632977,98.982777,0,0,1,,,,2.031E-7,15.70291,1.7065548,1.1455519,0
22417053.89,,4881,0,1.3619,2333.347,9.4E-6,1.3734632,0.029468444,1.5889473,0.005284,0.15684546,0.001926,1.7457928,0.005284,1.3905009,8.0020222,0.0048390092,99.256818,0,0,1,,,,2.1952E-7,16.26313,1.8864012,1.156891,0
22417104.66,,4881,0,1.3622,2333.347,9.4E-6,1.3738536,0.02939593,1.5894348,0.005902,0.15698267,0.001922,1.7464174,0.005902,0.20611481,7.9065282,0.0043992461,99.316789,0,0,1,,,,2.2214E-7,16.00404,1.8874737,1.1569171,0
22417156.45,,4881,0,1.362,2333.347,9.4E-6,1.3737098,0.02930739,1.5877509,0.00617,0.1569511,0.001923,1.744702,0.00617,0.23760033,7.966923,0.0052310074,99.193682,0,0,1,,,,2.2047E-7,15.81306,1.8870785,1.1558124,0
22417374.2,,4881,0,1.4281,2333.347,9.2E-6,1.44048,0.030839422,1.6696792,0.005333,0.17525517,0.001416,1.8449343,0.005333,1.2795332,7.8467543,0.0055877456,99.167219,0,0,1,,,,2.3674E-7,15.93385,2.0749827,1.159113,0
22417425.55,,4881,0,1.4281,2333.347,9.4E-6,1.4406884,0.030747035,1.6799223,0.006218,0.17531342,0.001414,1.8552357,0.006218,0.15165528,7.8639336,0.0055217667,99.175021,0,0,1,,,,2.3753E-7,15.69351,2.075583,1.1660553,0
22417476.42,,4881,0,1.4278,2333.347,9.2E-6,1.4404929,0.030825985,1.6747207,0.005986,0.17525869,0.001416,1.8499794,0.005986,0.13631437,7.8497397,0.0055533176,99.170667,0,0,1,,,,2.3729E-7,15.72787,2.0750199,1.1626025,0
22417693.5,,4881,0,1.493,2333.347,9.4E-6,1.5061708,0.032240633,1.7549746,0.005935,0.1944401,0.001249,1.9494147,0.005935,1.1560758,7.7453622,0.0053176772,99.23172,0,0,1,,,,2.5327E-7,15.69948,2.2685504,1.1651897,0
22417744.14,,4881,0,1.4929,2333.347,9.2E-6,1.506591,0.032200304,1.7588768,0.006424,0.19456051,0.001249,1.9534373,0.006424,0.2755443,7.7094978,0.0051421063,99.252768,0,0,1,,,,2.5493E-7,15.49072,2.2698163,1.1674548,0
22417794.47,,4881,0,1.4929,2333.347,9.3E-6,1.5064587,0.031970159,1.7658396,0.006243,0.194503,0.001249,1.9603426,0.006243,0.34168956,7.6639009,0.0036653748,99.463073,0,0,1,,,,2.5691E-7,15.419,2.2694178,1.1721792,0
22418011.61,,4881,0,1.5591,2333.347,9.3E-6,1.5733752,0.033507251,1.8347477,0.006126,0.21550933,0.001309,2.050257,0.006126,0.87932729,7.644838,0.0052737845,99.263339,0,0,1,,,,2.6978E-7,15.3278,2.4755095,1.1661222,0
22418062.31,,4881,0,1.5591,2333.347,9.4E-6,1.5736244,0.033709211,1.833155,0.006545,0.21559142,0.001309,2.0487464,0.006545,0.20440775,7.601966,0.0053363848,99.251077,0,0,1,,,,2.7113E-7,15.28968,2.4762939,1.1649253,0
22418114.45,,4881,0,1.5589,2333.347,9.4E-6,1.5735163,0.03355219,1.8473784,0.007357,0.2155618,0.001309,2.0629402,0.007357,0.21324054,7.6893394,0.0049841871,99.304354,0,0,1,,,,2.6979E-7,15.20393,2.4759536,1.1740447,0
22418330,,4881,0,1.6242,2333.347,9.2E-6,1.6399692,0.03531341,1.903248,0.006657,0.2382005,0.001417,2.1414485,0.006657,0.62209299,7.5412716,0.0057170444,99.2297,0,0,1,,,,2.8571E-7,15.37868,2.689499,1.1605389,0
22418380.31,,4881,0,1.6238,2333.347,9.2E-6,1.6396499,0.035092249,1.903555,0.008342,0.23813859,0.001417,2.1416936,0.008342,0.23629388,7.4445298,0.0036480536,99.502718,0,0,1,,,,2.8882E-7,15.08254,2.6884517,1.1609521,0
22418430.98,,4881,0,1.6244,2333.347,9.4E-6,1.6396237,0.034788455,1.9077403,0.007797,0.2381176,0.001417,2.1458579,0.007797,0.33012064,7.4342846,0.003828732,99.476357,0,0,1,,,,2.8985E-7,14.88906,2.6883659,1.1635232,0
22418645.58,,4881,0,1.6903,2333.347,9.2E-6,1.7060608,0.036364783,1.9629636,0.007567,0.26238526,0.001535,2.2253489,0.007567,0.93974385,7.4143481,0.0063347991,99.174692,0,0,1,,,,3.0209E-7,14.86857,2.9106434,1.1505825,0
22418696.25,,4881,0,1.6903,2333.347,9.4E-6,1.7059427,0.036658971,1.9516585,0.007979,0.26233439,0.001535,2.2139929,0.007979,0.36385909,7.3302134,0.0058087789,99.238078,0,0,1,,,,3.0384E-7,14.8287,2.9102407,1.1440352,0
22418747.02,,4881,0,1.6896,2333.347,9.4E-6,1.7061776,0.036429142,1.9541699,0.007087,0.26241966,0.001535,2.2165895,0.007087,0.63161534,7.370531,0.0054699989,99.286107,0,0,1,,,,3.0242E-7,14.66043,2.9110421,1.1453496,0
22418960.09,,4881,0,1.7548,2333.347,9.2E-6,1.772154,0.038108259,2.0049274,0.007626,0.28843705,0.0017,2.2933644,0.007626,1.2683351,7.231491,0.0050656733,99.36073,0,0,1,,,,3.187E-7,14.74106,3.1405299,1.1313505,0
22419009.84,,4881,0,1.755,2333.347,9.2E-6,1.7722396,0.038024425,2.0018504,0.009037,0.28847375,0.0017,2.2903242,0.009037,0.38687294,7.2343512,0.0058582264,99.261534,0,0,1,,,,3.1839E-7,14.46298,3.1408333,1.1295597,0
22419061.28,,4881,0,1.7552,2333.347,9.3E-6,1.7721805,0.038006347,1.9993422,0.00838,0.28843854,0.0017,2.2877808,0.00838,0.44874254,7.2077696,0.0050181167,99.365997,0,0,1,,,,3.1895E-7,14.4687,3.1406238,1.128182,0
22419272.92,,4881,0,1.8211,2333.347,9.4E-6,1.8392798,0.039456547,2.0520172,0.008587,0.31752642,0.001941,2.3695436,0.008587,1.0150914,7.1434907,0.0069677153,99.155888,0,0,1,,,,3.3383E-7,14.41554,3.3829504,1.1156634,0
22419323.63,,4881,0,1.8212,2333.347,9.4E-6,1.8396704,0.039481404,2.0534145,0.007854,0.31770637,0.001943,2.3711209,0.007854,0.64022689,7.1294525,0.0080301166,99.02453,0,0,1,,,,3.3504E-7,14.28698,3.3843871,1.1161861,0
22419374.5,,4881,0,1.8213,2333.347,9.3E-6,1.8393191,0.039651811,2.0432723,0.009032,0.31756463,0.001942,2.3608369,0.009032,0.3308923,7.1690475,0.0079300404,99.045277,0,0,1,,,,3.3169E-7,14.25891,3.3830946,1.1108852,0
22419588.42,,4881,0,1.8862,2333.347,9.4E-6,1.9057151,0.040938144,2.1107668,0.0089,0.34860061,0.002319,2.4593674,0.0089,1.2873151,7.0271139,0.0052529705,99.383713,0,0,1,,,,3.5158E-7,14.3381,3.6317501,1.1075983,0
22419638.33,,4881,0,1.886,2333.347,9.2E-6,1.9057165,0.040766325,2.1026399,0.01021,0.34872628,0.00232,2.4513661,0.01021,0.55914682,6.9762034,0.0058758337,99.307455,0,0,1,,,,3.5319E-7,14.05423,3.6317553,1.103333,0
22419686.66,,4881,0,1.8858,2333.347,9.4E-6,1.9057144,0.040483834,2.1144451,0.0094,0.3487221,0.00232,2.4631672,0.0094,0.76567353,7.0189084,0.0058261595,99.314753,0,0,1,,,,3.5272E-7,13.95241,3.6317475,1.1095289,0
22419897.56,,4881,0,1.9521,2333.347,9.4E-6,1.9722708,0.041766812,2.1635811,0.009931,0.38254923,0.002676,2.5461303,0.009931,1.1100392,6.8684768,0.0049281175,99.4366,0,0,1,,,,3.7222E-7,14.03782,3.8898522,1.097,0
22419946.44,,4881,0,1.9521,2333.347,9.4E-6,1.9726523,0.041751262,2.1560003,0.009815,0.38279151,0.002678,2.5387918,0.009815,0.46450979,6.9389474,0.0073977276,99.164259,0,0,1,,,,3.681E-7,13.73695,3.8913572,1.0929449,0
22419995.58,,4881,0,1.9519,2333.347,9.3E-6,1.972083,0.041930854,2.1585237,0.01043,0.38250665,0.002675,2.5410304,0.01043,0.4726656,6.9476068,0.0080642995,99.088552,0,0,1,,,,3.6817E-7,13.87789,3.8891112,1.09454,0
22420206.89,,4881,0,2.0168,2333.347,9.3E-6,2.0380439,0.042826579,2.2121137,0.009753,0.41926251,0.002806,2.6313762,0.009753,1.1235885,6.8140235,0.0067560781,99.257475,0,0,1,,,,3.8821E-7,13.89521,4.153623,1.0854102,0
22420255.61,,4881,0,2.0167,2333.347,9.4E-6,2.0378269,0.042844749,2.2038736,0.01051,0.41916744,0.002806,2.623041,0.01051,0.37887143,6.8586335,0.0085545182,99.067422,0,0,1,,,,3.8499E-7,13.62805,4.1527384,1.0814822,0
22420304.5,,4881,0,2.017,2333.347,9.3E-6,2.0382165,0.042964773,2.2086533,0.01076,0.41937652,0.002806,2.6280298,0.01076,0.32527791,6.8373501,0.0063985683,99.300173,0,0,1,,,,3.8628E-7,13.71727,4.1543264,1.0836206,0
22420516.44,,4881,0,2.083,2333.347,9.3E-6,2.1045465,0.044143489,2.243231,0.0105,0.45975222,0.002642,2.7029832,0.0105,0.93191906,6.7902196,0.0085167032,99.108423,0,0,1,,,,4.0054E-7,13.6747,4.429116,1.0658976,0
22420565.28,,4881,0,2.0829,2333.347,9.3E-6,2.1050613,0.044467042,2.2246853,0.01166,0.46011154,0.00264,2.6847968,0.01166,0.46762719,6.7679456,0.011037966,98.846473,0,0,1,,,,3.9988E-7,13.58044,4.4312829,1.0568269,0
22420615.39,,4881,0,2.083,2333.347,9.3E-6,2.1052477,0.044005425,2.2433206,0.01036,0.46009971,0.00264,2.7034203,0.01036,0.63393875,6.6571226,0.0047080699,99.498272,0,0,1,,,,4.0751E-7,13.53589,4.432068,1.0655851,0
22420827.69,,4881,0,2.1481,2333.347,9.3E-6,2.1705953,0.045123256,2.2696289,0.01105,0.50289359,0.002365,2.7725225,0.01105,0.85125158,6.6621955,0.007158574,99.274539,0,0,1,,,,4.182E-7,13.31425,4.7114841,1.0456251,0
22420876.38,,4881,0,2.1479,2333.347,9.3E-6,2.170824,0.04539789,2.2678909,0.01132,0.50305524,0.002364,2.7709461,0.01132,0.37717828,6.6341167,0.0072936627,99.258195,0,0,1,,,,4.1977E-7,13.32439,4.7124767,1.0447143,0
22420925.58,,4881,0,2.1479,2333.347,9.3E-6,2.1709329,0.045267751,2.2687832,0.0115,0.50311759,0.002364,2.7719008,0.0115,0.5342615,6.6275654,0.007343776,99.252216,0,0,1,,,,4.2035E-7,13.26823,4.7129497,1.0450729,0
22421138.75,,4881,0,2.214,2333.347,9.2E-6,2.2356621,0.046484859,2.3012081,0.005897,0.54812508,0.00218,2.8493332,0.005897,0.98667826,6.5851381,0.0075566816,99.259696,0,0,1,,,,4.348E-7,13.25513,4.998185,1.0293184,0
22421188,,4881,0,2.2142,2333.347,9.4E-6,2.23738,0.046800565,2.2862443,0.006177,0.54937313,0.002178,2.8356174,0.006177,0.8910781,6.5525443,0.0091486083,99.10373,0,0,1,,,,4.353E-7,13.17028,5.0058692,1.02184,0
22421237.86,,4881,0,2.2139,2333.347,9.3E-6,2.2355818,0.046591012,2.3025484,0.006523,0.54806851,0.00218,2.8506169,0.006523,0.26013327,6.5777406,0.0072302597,99.290646,0,0,1,,,,4.354E-7,13.10509,4.997826,1.0299549,0
22421448.78,,4881,0,2.279,2333.347,9.2E-6,2.3035089,0.048326859,2.3168905,0.006384,0.59753721,0.002188,2.9144277,0.006384,0.84970091,6.4859703,0.0057799051,99.452459,0,0,1,,,,4.5091E-7,13.15548,5.3061532,1.0058092,0
22421496.5,,4881,0,2.2791,2333.347,9.2E-6,2.3036431,0.048190497,2.322245,0.007548,0.59792654,0.002188,2.9201716,0.007548,0.27075548,6.5186643,0.0062105556,99.413976,0,0,1,,,,4.4964E-7,12.97194,5.3067716,1.008075,0
22421543.95,,4881,0,2.2795,2333.347,9.3E-6,2.3020493,0.048510567,2.3130334,0.006664,0.59676948,0.002187,2.9098029,0.006664,0.18898652,6.4950078,0.0073818345,99.30155,0,0,1,,,,4.5E-7,13.03733,5.2994309,1.0047715,0
22421753.48,,4881,0,2.345,2333.347,9.3E-6,2.3697625,0.049570571,2.3401095,0.006545,0.64846827,0.002298,2.9885778,0.006545,1.4378767,6.4450022,0.0068719532,99.371524,0,0,1,,,,4.655E-7,12.99002,5.6157744,0.98748693,0
22421801.5,,4881,0,2.3452,2333.347,9.3E-6,2.3692883,0.049663807,2.3536691,0.006628,0.64809319,0.002297,3.0017623,0.006628,0.56646432,6.4493615,0.0058495707,99.463563,0,0,1,,,,4.6698E-7,12.89,5.613527,0.99340766,0
22421849.14,,4881,0,2.3448,2333.347,9.4E-6,2.3688797,0.049614531,2.3471618,0.008169,0.6478652,0.002296,2.995027,0.008169,0.1652126,6.5107179,0.010967308,99.004006,0,0,1,,,,4.6286E-7,12.89872,5.6115909,0.99083201,0
22422056.56,,4881,0,2.4098,2333.347,9.3E-6,2.4334826,0.050967176,2.4149331,0.006958,0.70054031,0.002461,3.1154734,0.006958,0.61963474,6.516735,0.0089513579,99.21064,0,0,1,,,,4.8036E-7,13.02144,5.9218377,0.99237738,0
22422103.41,,4881,0,2.4099,2333.347,9.2E-6,2.4375573,0.051566385,2.4043912,0.009502,0.7040671,0.002473,3.1084583,0.009502,0.092926912,6.5442007,0.00936274,99.182041,0,0,1,,,,4.7734E-7,13.03347,5.9416855,0.98639374,0
22422152.69,,4881,0,2.4103,2333.347,9.2E-6,2.4366792,0.051192603,2.4195283,0.007076,0.70286685,0.002469,3.1223951,0.007076,0.58500729,6.4522228,0.0074822494,99.334288,0,0,1,,,,4.8588E-7,13.0884,5.9374057,0.99296135,0
22422361.25,,4881,0,2.4763,2333.347,9.2E-6,2.5004668,0.051601853,2.4927783,0.008041,0.75966642,0.002654,3.2524447,0.008041,0.38248968,6.5350753,0.0065816683,99.436837,0,0,1,,,,4.9935E-7,12.90445,6.2523341,0.99692519,0
22422410.5,,4881,0,2.4762,2333.347,9.4E-6,2.5032447,0.05255003,2.4885611,0.008066,0.76194953,0.002661,3.2505106,0.008066,0.2440456,6.5288273,0.0072018382,99.384673,0,0,1,,,,4.9968E-7,13.07015,6.266234,0.99413416,0
22422458.56,,4881,0,2.4759,2333.347,9.2E-6,2.5027921,0.052561107,2.478044,0.0081,0.76191403,0.002661,3.2399581,0.0081,0.291776,6.5271221,0.0075831592,99.353335,0,0,1,,,,4.9828E-7,13.05765,6.2639683,0.99011181,0
22422668.14,,4881,0,2.5408,2333.347,9.2E-6,2.5688568,0.053289644,2.5769073,0.007697,0.82499529,0.002913,3.4019026,0.007697,1.3202932,6.6538299,0.0086813752,99.288987,0,0,1,,,,5.1337E-7,13.05424,6.599025,1.0031339,0
22422717.09,,4881,0,2.541,2333.347,9.3E-6,2.5682447,0.054246329,2.5636631,0.008707,0.82398039,0.002908,3.3876434,0.008707,0.29498173,6.5756429,0.0058161955,99.51913,0,0,1,,,,5.1661E-7,13.30766,6.5958809,0.99821603,0
22422766.69,,4881,0,2.5409,2333.347,9.3E-6,2.5684351,0.053894938,2.5576776,0.008436,0.82413962,0.002909,3.3818172,0.008436,0.34457992,6.5663636,0.0067618835,99.440818,0,0,1,,,,5.1668E-7,13.15129,6.5968591,0.99581163,0
22422976.55,,4881,0,2.6068,2333.347,9.3E-6,2.6348678,0.054187877,2.6882543,0.008304,0.8916024,0.003223,3.5798567,0.008304,1.6853248,6.7464082,0.0087353007,99.307068,0,0,1,,,,5.3272E-7,13.13273,6.9425282,1.0202616,0
22423025,,4881,0,2.607,2333.347,9.3E-6,2.6383028,0.055720401,2.6723739,0.009625,0.89543921,0.003241,3.5678132,0.009625,0.28834065,6.8030411,0.010756558,99.158017,0,0,1,,,,5.2695E-7,13.49282,6.9606415,1.0129141,0
22423073.44,,4881,0,2.6067,2333.347,9.3E-6,2.6374758,0.05604228,2.6633674,0.008927,0.89452008,0.003237,3.5578874,0.008927,0.43906946,6.7178592,0.0097273538,99.229905,0,0,1,,,,5.3192E-7,13.60608,6.9562786,1.0098168,0
22423285.52,,4881,0,2.6719,2333.347,9.3E-6,2.698588,0.055202891,2.8561035,0.009274,0.96054699,0.003516,3.8166505,0.009274,1.6852883,6.9094472,0.0073980712,99.43108,0,0,1,,,,5.5415E-7,13.43572,7.2823771,1.0583696,0
22423335.2,,4881,0,2.6716,2333.347,9.2E-6,2.699263,0.056612718,2.8404895,0.01094,0.96154564,0.003519,3.8020352,0.01094,0.48608748,6.9592059,0.0099104654,99.245607,0,0,1,,,,5.4865E-7,13.81889,7.2860206,1.0523204,0
22423383.03,,4881,0,2.6722,2333.347,9.3E-6,2.698392,0.056969627,2.8468833,0.01164,0.96063648,0.003516,3.8075198,0.01164,0.19279447,6.9767457,0.010121107,99.230269,0,0,1,,,,5.4811E-7,13.91841,7.2813193,1.0550296,0
22423591.58,,4881,0,2.7383,2333.347,9.3E-6,2.7668617,0.056443972,3.0595745,0.01069,1.0396777,0.003746,4.0992522,0.01069,0.82815357,7.2655646,0.010616538,99.227391,0,0,1,,,,5.6665E-7,13.95349,7.6555239,1.1057923,0
22423642.25,,4881,0,2.7379,2333.347,9.3E-6,2.7683645,0.058555494,3.0281172,0.01202,1.0410968,0.003749,4.069214,0.01202,0.23521146,7.1509798,0.0084875071,99.376162,0,0,1,,,,5.7102E-7,14.53113,7.6638423,1.0938289,0
22423691.97,,4881,0,2.7383,2333.347,9.3E-6,2.7649595,0.057515442,3.0645084,0.01198,1.0369943,0.003741,4.1015026,0.01198,0.70753692,7.1928606,0.010665637,99.21432,0,0,1,,,,5.7274E-7,14.30196,7.6450011,1.1083375,0
22423901.05,,4881,0,2.8032,2333.347,9.4E-6,2.8321058,0.056695385,3.3553091,0.01338,1.1198319,0.003801,4.475141,0.01338,1.4852738,7.6285032,0.006809979,99.523902,0,0,1,,,,5.8821E-7,14.38572,8.0208232,1.18474,0
22423951.73,,4881,0,2.8024,2333.347,9.2E-6,2.8343676,0.058991249,3.3849035,0.01489,1.1224156,0.003799,4.5073191,0.01489,0.80097981,7.5861865,0.0030484898,99.785059,0,0,1,,,,5.9487E-7,15.25701,8.0336399,1.1942359,0
22424003.06,,4881,0,2.8031,2333.347,9.3E-6,2.8350916,0.058666428,3.3551747,0.01509,1.1233431,0.003799,4.4785178,0.01509,0.58393715,7.5637987,0.006873317,99.516128,0,0,1,,,,5.9372E-7,15.17237,8.0377445,1.1834449,0
22424215.2,,4881,0,2.8691,2333.347,9.3E-6,2.9006167,0.073551986,2.1947335,0.02957,1.2112779,0.003681,3.4060114,0.02957,50.885419,6.4457007,0.056332556,96.20866,0,0,1,,,,5.3714E-7,15.1276,8.4135774,0.75664375,0
22424264.84,,4881,0,2.8692,2333.347,9.4E-6,2.8962916,0.066713655,2.2580499,0.03137,1.2056248,0.003691,3.4636747,0.03137,5.1500081,6.3658268,0.035689975,97.53785,0,0,1,,,,5.4998E-7,12.8914,8.3885051,0.77963485,0
22424314.69,,4881,0,2.8695,2333.347,9.3E-6,2.9001725,0.066154731,2.2461455,0.03062,1.2107296,0.003682,3.4568752,0.03062,9.7572116,6.3413437,0.035028348,97.581311,0,0,1,,,,5.5087E-7,12.73165,8.4110004,0.77448688,0
22424568.91,,4881,0,2.9341,2333.347,9.3E-6,2.9646819,0.063554817,1.4934697,0.007122,1.2991502,0.003529,2.7926199,0.007122,1.823638,4.6606969,0.018934677,98.378279,0,0,1,,,,6.0202E-7,9.342882,8.789339,0.50375378,0
22424615.02,,4881,0,2.9343,2333.347,9.2E-6,2.9653049,0.063517092,1.4853961,0.007397,1.2999936,0.003528,2.7853897,0.007397,0.80830726,4.6487314,0.018502484,98.41173,0,0,1,,,,6.0193E-7,9.321394,8.7930333,0.50092524,0
22424659.97,,4881,0,2.9339,2333.347,9.4E-6,2.9647161,0.063453225,1.4819439,0.007313,1.2991915,0.003529,2.7811355,0.007313,1.8067948,4.6416792,0.021048191,98.192386,0,0,1,,,,6.0231E-7,9.297463,8.7895413,0.49986033,0
22424865.14,,4881,0,3,2333.347,9.2E-6,3.0338951,0.06764089,1.2140321,0.005319,1.3987979,0.003453,2.61283,0.005319,1.4333704,4.2239324,0.021670898,97.961243,0,0,1,,,,6.2137E-7,9.283358,9.2045195,0.40015624,0
22424908.17,,4881,0,2.9999,2333.347,9.2E-6,3.0288164,0.063948951,1.2276032,0.006545,1.3919084,0.003452,2.6195117,0.006545,0.53665152,4.2187849,0.021088769,98.01481,0,0,1,,,,6.2369E-7,8.447865,9.173729,0.40530791,0
22424952.22,,4881,0,2.9998,2333.347,9.4E-6,3.0310178,0.06435981,1.2197305,0.005973,1.3949983,0.003452,2.6147288,0.005973,0.71857673,4.1882388,0.01498465,98.573956,0,0,1,,,,6.2628E-7,8.43757,9.187069,0.40241615,0
22425188.55,Error: Warning: Current field is 3666.695 Oe;
22425188.72,Error: but addenda was obtained at -0.025 Oe.
[...]
22548091.33,,4881,0,1.5589,21000.096,9.4E-6,1.5755392,0.034151106,1.1819999,0.005313,0.2256175,0.001246,1.4076174,0.005313,0.47081722,5.2710368,0.0061095558,99.135725,0,0,1,,,,2.6869E-7,10.61529,2.4823237,0.7502193,0
22548300.91,,4881,0,1.6243,21000.096,9.2E-6,1.6422106,0.037824264,1.0646056,0.00441,0.24811822,0.00137,1.3127238,0.00441,0.7233139,4.6452735,0.0078887313,98.888141,0,0,1,,,,2.8469E-7,10.54207,2.6968558,0.64827589,0
22548345.78,,4881,0,1.6241,21000.096,9.2E-6,1.6408793,0.035467956,1.0674172,0.004697,0.24771453,0.001366,1.3151317,0.004697,0.57336358,4.6747665,0.0064859294,99.08979,0,0,1,,,,2.8303E-7,9.290547,2.692485,0.65051533,0
22548552.58,,4881,0,1.6899,21000.096,9.4E-6,1.7086363,0.038692265,1.0005222,0.004472,0.27180047,0.001609,1.2723227,0.004472,1.1333472,4.2156988,0.0023458143,99.668499,0,0,1,,,,3.0243E-7,9.349533,2.9194382,0.58556766,0
22548595.64,,4881,0,1.6898,21000.096,9.3E-6,1.7073698,0.036667217,0.99800534,0.005126,0.27147035,0.001605,1.2694757,0.005126,0.58109755,4.2763253,0.0079337124,98.893468,0,0,1,,,,2.9892E-7,8.431398,2.9151118,0.58452792,0
22548802.47,,4881,0,1.755,21000.096,9.2E-6,1.7736945,0.039270023,0.98212208,0.005529,0.29769532,0.001882,1.2798174,0.005529,0.18442043,4.0382443,0.0028002587,99.611252,0,0,1,,,,3.1765E-7,8.552651,3.1459922,0.55371547,0
22548845.19,,4881,0,1.755,21000.096,9.3E-6,1.7729501,0.038106535,0.98485718,0.004905,0.29734355,0.001879,1.2822007,0.004905,0.78576618,4.0526703,0.0035514689,99.507578,0,0,1,,,,3.1731E-7,8.076489,3.1433521,0.55549063,0
22549051.67,,4881,0,1.8208,21000.096,9.2E-6,1.8403938,0.040366236,0.96419735,0.005488,0.3277728,0.002194,1.2919702,0.005488,0.93626967,3.8928705,0.0059777544,99.188197,0,0,1,,,,3.334E-7,8.105341,3.3870492,0.52390818,0
22549094.06,,4881,0,1.8207,21000.096,9.4E-6,1.8398098,0.039629462,0.96349812,0.005427,0.32767672,0.002193,1.2911748,0.005427,1.2277235,3.8722095,0.0036552667,99.501247,0,0,1,,,,3.3438E-7,7.785741,3.3849001,0.52369442,0
22549300.13,,4881,0,1.8859,21000.096,9.3E-6,1.9059934,0.041420352,0.95843664,0.00588,0.36070558,0.002552,1.3191422,0.00588,1.1836425,3.8207971,0.0063072585,99.168677,0,0,1,,,,3.4678E-7,7.744419,3.6328107,0.50285413,0
22549342.86,,4881,0,1.8861,21000.096,9.4E-6,1.9061438,0.041274048,0.94585295,0.005771,0.36076367,0.002553,1.3066166,0.005771,0.68213252,3.7699882,0.0078592355,98.956407,0,0,1,,,,3.485E-7,7.641594,3.6333843,0.49621279,0
22549547.75,,4881,0,1.9518,21000.096,9.2E-6,1.9729124,0.042569328,0.95450188,0.006425,0.39657316,0.0028,1.351075,0.006425,0.91630007,3.6999801,0.0032183389,99.580539,0,0,1,,,,3.6593E-7,7.539976,3.8923834,0.48380348,0
22549591.02,,4881,0,1.9522,21000.096,9.3E-6,1.9730455,0.042093467,0.95599479,0.006306,0.39660069,0.0028,1.3525955,0.006306,0.91973499,3.6762517,0.0027590329,99.637857,0,0,1,,,,3.686E-7,7.39996,3.8929087,0.48452748,0
22549796.06,,4881,0,2.0172,21000.096,9.2E-6,2.0381257,0.043335917,0.95940096,0.006575,0.43374949,0.002779,1.3931505,0.006575,1.9520741,3.7066087,0.0083303482,98.952318,0,0,1,,,,3.7775E-7,7.352503,4.1539564,0.47072708,0
22549839.48,,4881,0,2.0168,21000.096,9.2E-6,2.0383583,0.043895945,0.94994462,0.006622,0.43388101,0.002778,1.3838256,0.006622,1.0404979,3.6746084,0.0067935499,99.141424,0,0,1,,,,3.7813E-7,7.413217,4.1549044,0.46603418,0
22550042.08,,4881,0,2.0832,21000.096,9.3E-6,2.1046152,0.04453506,0.96752758,0.006585,0.47373904,0.002528,1.4412666,0.006585,0.58877294,3.5903595,0.0033773099,99.573872,0,0,1,,,,4.022E-7,7.349217,4.4294052,0.45971709,0
22550085.7,,4881,0,2.0831,21000.096,9.3E-6,2.1043956,0.04393304,0.96394136,0.006251,0.47354937,0.002529,1.4374907,0.006251,0.98346312,3.5550716,0.0041771188,99.468388,0,0,1,,,,4.0532E-7,7.180719,4.4284807,0.45806091,0
22550288.89,,4881,0,2.148,21000.096,9.3E-6,2.1696043,0.044989882,0.97397334,0.006466,0.51567155,0.002251,1.4896449,0.006466,1.3269518,3.6159951,0.011153156,98.639845,0,0,1,,,,4.144E-7,7.110143,4.707183,0.44891749,0
22550333.36,,4881,0,2.1482,21000.096,9.4E-6,2.1699972,0.045602715,0.97380233,0.006296,0.51590495,0.00225,1.4897073,0.006296,1.221663,3.5831592,0.007543259,99.071287,0,0,1,,,,4.1742E-7,7.23199,4.708888,0.44875741,0
22550537.5,,4881,0,2.2141,21000.096,9.4E-6,2.2355647,0.04662506,0.97177581,0.003779,0.56115118,0.002134,1.532927,0.003779,1.1282612,3.547836,0.0079378327,99.03766,0,0,1,,,,4.3376E-7,7.166318,4.9977496,0.43468919,0
22550580.53,,4881,0,2.2138,21000.096,9.2E-6,2.234022,0.04643324,0.97985274,0.004072,0.56005072,0.002134,1.5399035,0.004072,0.35207463,3.5690915,0.0069822473,99.155986,0,0,1,,,,4.3295E-7,7.095672,4.9908544,0.43860478,0
22550784.75,,4881,0,2.279,21000.096,9.3E-6,2.3001898,0.04801665,0.97741437,0.0042,0.60817105,0.002178,1.5855854,0.0042,0.48568573,3.5938358,0.012926659,98.484161,0,0,1,,,,4.4379E-7,7.138183,5.2908731,0.4249277,0
22550827.03,,4881,0,2.279,21000.096,9.3E-6,2.2975559,0.048246372,0.98470113,0.004046,0.60612915,0.002174,1.5908303,0.004046,0.65527406,3.5466925,0.0083847965,98.999896,0,0,1,,,,4.5028E-7,7.187672,5.2787632,0.42858636,0
22551029.86,,4881,0,2.345,21000.096,9.2E-6,2.3649362,0.049287247,0.98310161,0.004731,0.65789045,0.002308,1.6409921,0.004731,0.20716108,3.5583848,0.011299338,98.682754,0,0,1,,,,4.6338E-7,7.093385,5.5929231,0.415699,0
22551072.86,,4881,0,2.3456,21000.096,9.2E-6,2.3673399,0.049650571,0.97401642,0.004164,0.65973266,0.002313,1.6337491,0.004164,0.57408159,3.517307,0.0075723291,99.108042,0,0,1,,,,4.6598E-7,7.11677,5.6042983,0.41143919,0
22551277.72,,4881,0,2.4097,21000.096,9.3E-6,2.4285814,0.050457899,0.98835486,0.004662,0.71053933,0.002484,1.6988942,0.004662,0.83192827,3.5162673,0.009243086,98.923367,0,0,1,,,,4.8494E-7,7.034614,5.8980077,0.40696797,0
22551321.06,,4881,0,2.41,21000.096,9.4E-6,2.4298335,0.050546797,0.98525164,0.004461,0.71167361,0.002488,1.6969252,0.004461,0.87032535,3.5464649,0.0099007764,98.857732,0,0,1,,,,4.8035E-7,7.032535,5.9040906,0.40548114,0
22551522.84,,4881,0,2.4759,21000.096,9.4E-6,2.4960702,0.051839772,0.99581934,0.004896,0.77192182,0.002692,1.7677412,0.004896,0.46515332,3.5801137,0.014145055,98.403094,0,0,1,,,,4.9632E-7,7.09293,6.2303666,0.39895486,0
22551565.75,,4881,0,2.4761,21000.096,9.4E-6,2.4955947,0.052391829,0.9888725,0.005128,0.77135774,0.00269,1.7602302,0.005128,0.21893268,3.5278004,0.0085118595,99.023422,0,0,1,,,,5.0052E-7,7.160227,6.227993,0.39624723,0
22551771.08,,4881,0,2.5411,21000.096,9.3E-6,2.5626195,0.05278782,1.0071125,0.005507,0.83763263,0.002954,1.8447451,0.005507,0.30835492,3.5655543,0.0078912726,99.110377,0,0,1,,,,5.1877E-7,7.055601,6.5670185,0.3930012,0
22551813.91,,4881,0,2.5407,21000.096,9.4E-6,2.562905,0.053494304,0.9920961,0.004998,0.8378368,0.002954,1.8299329,0.004998,0.353926,3.519534,0.0036162815,99.586766,0,0,1,,,,5.2057E-7,7.131109,6.5684823,0.38709827,0
22552018.05,,4881,0,2.6066,21000.096,9.4E-6,2.6302296,0.05428814,0.99115138,0.005427,0.90948526,0.003264,1.9006366,0.005427,0.68287852,3.6027459,0.012177576,98.653732,0,0,1,,,,5.2952E-7,7.039068,6.9181075,0.37683075,0
22552061.7,,4881,0,2.6073,21000.096,9.4E-6,2.6273529,0.054961722,0.99986647,0.005216,0.90641351,0.00325,1.90628,0.005216,1.0537871,3.5949832,0.011948655,98.675206,0,0,1,,,,5.3223E-7,7.205492,6.9029832,0.3805604,0
22552265.52,,4881,0,2.6722,21000.096,9.4E-6,2.6977761,0.056132349,0.99050438,0.005452,0.98528217,0.003578,1.9757865,0.005452,0.77038903,3.6603775,0.01616166,98.249143,0,0,1,,,,5.422E-7,7.189966,7.2779959,0.36715589,0
22552308.3,,4881,0,2.6718,21000.096,9.4E-6,2.6932818,0.056564851,1.0002369,0.005848,0.98005736,0.003557,1.9802943,0.005848,0.43850528,3.618592,0.011876667,98.69536,0,0,1,,,,5.4911E-7,7.320755,7.2537667,0.3713822,0
22552510.78,,4881,0,2.7377,21000.096,9.3E-6,2.7640541,0.057288056,0.99530766,0.006439,1.0624021,0.00385,2.0577098,0.006439,0.29959367,3.6683035,0.015388198,98.33505,0,0,1,,,,5.6317E-7,7.237184,7.6399949,0.36008979,0
22552553.05,,4881,0,2.7385,21000.096,9.4E-6,2.7595004,0.058054905,0.99737295,0.006048,1.057088,0.003834,2.054461,0.006048,0.40238218,3.6418761,0.01581631,98.277115,0,0,1,,,,5.6646E-7,7.336607,7.6148424,0.36143243,0
22552756.92,,4881,0,2.8028,21000.096,9.3E-6,2.8302731,0.058332742,1.0012361,0.00577,1.1425186,0.004075,2.1437547,0.00577,1.1699909,3.6834644,0.013089078,98.583764,0,0,1,,,,5.8382E-7,7.283752,8.0104457,0.35375955,0
22552799.78,,4881,0,2.8025,21000.096,9.3E-6,2.8221814,0.058988057,1.0092181,0.005826,1.1326389,0.004049,2.141857,0.005826,0.62979454,3.6733912,0.013922238,98.491639,0,0,1,,,,5.8506E-7,7.366929,7.964708,0.35760213,0
22553004.14,,4881,0,2.8691,21000.096,9.4E-6,2.8912031,0.059531934,1.0157101,0.006317,1.2194768,0.004258,2.2351869,0.006317,1.8720737,3.7415636,0.014252837,98.477182,0,0,1,,,,5.9931E-7,7.346782,8.3590555,0.35131052,0
22553046.61,,4881,0,2.8689,21000.096,9.3E-6,2.8917767,0.060407986,1.0089598,0.005987,1.2203769,0.00426,2.2293366,0.005987,1.4108179,3.7421931,0.016230528,98.267218,0,0,1,,,,5.9789E-7,7.483127,8.3623727,0.34890652,0
22553249.98,,4881,0,2.934,21000.096,9.4E-6,2.9584665,0.061015442,1.0083272,0.006545,1.3074459,0.004455,2.3157731,0.006545,0.64257201,3.7235019,0.011959824,98.703893,0,0,1,,,,6.2349E-7,7.484386,8.7525239,0.34082767,0
22553294.16,,4881,0,2.9335,21000.096,9.2E-6,2.9580484,0.0613735,1.0067053,0.006919,1.3072339,0.004454,2.3139391,0.006919,0.36291563,3.7987122,0.017900761,98.105215,0,0,1,,,,6.1138E-7,7.447004,8.7500505,0.34032752,0
22553497.48,,4881,0,2.9998,21000.096,9.3E-6,3.0228306,0.062718575,1.019227,0.0066,1.3949872,0.00466,2.4142142,0.0066,0.58085793,3.8300132,0.011840268,98.74295,0,0,1,,,,6.3178E-7,7.597424,9.137505,0.33717634,0
22553539.8,,4881,0,2.9999,21000.096,9.2E-6,3.024928,0.063173291,1.0071091,0.006599,1.3980902,0.004667,2.4051993,0.006599,0.87325104,3.8340472,0.017507794,98.146369,0,0,1,,,,6.2941E-7,7.660026,9.1501891,0.33293657,0
22553754.13,Error: Warning: Current field is 22000.098 Oe;
22553754.41,Error: but addenda was obtained at 10000.058 Oe.
22554069.94,,4881,0,1.1001,22000.098,9.4E-6,1.1109421,0.023765498,0.98265797,0.005734,0.10950328,0.001534,1.0921613,0.005734,1.3604155,6.8020196,0.0057155093,99.063078,0,0,1,,,,1.6179E-7,14,1.2341923,0.88452675,0
22554118.81,,4881,0,1.1,22000.098,9.4E-6,1.1117198,0.023330301,0.97334917,0.006147,0.10959179,0.001536,1.082941,0.006147,0.7341949,6.4297867,0.0025356066,99.565274,0,0,1,,,,1.6902E-7,13.60404,1.235921,0.8755346,0
22554359.16,,4881,0,1.1663,22000.098,9.2E-6,1.1762646,0.024414055,1.0498505,0.006454,0.12095391,0.001799,1.1708044,0.006454,0.93179383,6.9011728,0.0067480373,98.937541,0,0,1,,,,1.7112E-7,12.85957,1.3835984,0.89252919,0
22554407.64,,4881,0,1.1665,22000.098,9.3E-6,1.1776591,0.025100806,1.0601068,0.006395,0.12117446,0.001804,1.1812812,0.006395,0.89210654,6.6069158,0.0028557037,99.529115,0,0,1,,,,1.7948E-7,13.80235,1.3868811,0.90018131,0
22554644.31,,4881,0,1.2306,22000.098,9.3E-6,1.243121,0.025619084,1.1425053,0.007793,0.13486923,0.002096,1.2773745,0.007793,0.66775296,6.4698441,0.0020448693,99.664638,0,0,1,,,,1.9797E-7,13.21383,1.5453499,0.919062,0
22554692.25,,4881,0,1.2316,22000.098,9.3E-6,1.242736,0.026131262,1.1513109,0.007797,0.1349005,0.002096,1.2862114,0.007797,1.0246743,7.0872508,0.0063533155,99.039541,0,0,1,,,,1.8289E-7,12.93969,1.5443927,0.92643241,0
22554908.44,,4881,0,1.297,22000.098,9.2E-6,1.3098083,0.027961747,1.2725431,0.007538,0.15023605,0.002101,1.4227792,0.007538,0.76810294,6.8611807,0.0041302735,99.360138,0,0,1,,,,2.0844E-7,14.1745,1.7155977,0.97154917,0
22554956.83,,4881,0,1.2968,22000.098,9.3E-6,1.3094765,0.02767285,1.2794204,0.008364,0.15020764,0.002101,1.429628,0.008364,0.65798625,6.9462625,0.0048010876,99.261631,0,0,1,,,,2.0704E-7,13.72236,1.7147287,0.97704723,0
22555174,,4881,0,1.3621,22000.098,9.4E-6,1.3770237,0.030043141,1.2961976,0.004465,0.16704509,0.001677,1.4632427,0.004465,0.82135128,6.6471587,0.0048437798,99.276432,0,0,1,,,,2.2139E-7,13.89252,1.8961943,0.94130379,0
22555224.67,,4881,0,1.3617,22000.098,9.4E-6,1.3767484,0.029705461,1.2903944,0.004791,0.16697267,0.001679,1.4573671,0.004791,0.29225447,6.6828339,0.0061073025,99.094446,0,0,1,,,,2.1964E-7,13.29432,1.8954362,0.93727685,0
22555437.8,,4881,0,1.4281,22000.098,9.2E-6,1.4447955,0.034061971,1.1463118,0.003963,0.18542389,0.001319,1.3317357,0.003963,0.86975355,5.7260113,0.0053048895,99.224054,0,0,1,,,,2.3393E-7,13.36567,2.0874339,0.79340767,0
22555484.03,,4881,0,1.4281,22000.098,9.3E-6,1.4432651,0.031541638,1.1434657,0.004926,0.18510221,0.001322,1.3285679,0.004926,0.96130429,5.7955396,0.0093653339,98.643411,0,0,1,,,,2.3158E-7,11.45202,2.0830142,0.79227693,0
22555695.2,,4881,0,1.4932,22000.098,9.2E-6,1.5105121,0.035636682,1.0200931,0.003708,0.20484129,0.001222,1.2249344,0.003708,0.71094899,4.8962233,0.0066266728,99.02441,0,0,1,,,,2.5189E-7,11.59108,2.2816467,0.67532931,0
22555740.17,,4881,0,1.493,22000.098,9.3E-6,1.5090211,0.032660303,1.018377,0.004192,0.2044907,0.001222,1.2228677,0.004192,1.0516054,4.8677594,0.0047322259,99.299993,0,0,1,,,,2.5245E-7,9.792447,2.2771447,0.67485936,0
22555948.81,,4881,0,1.5588,22000.098,9.3E-6,1.576249,0.035486009,0.97158866,0.004322,0.22584291,0.001247,1.1974316,0.004322,0.95161012,4.4991051,0.0070717278,98.96948,0,0,1,,,,2.6798E-7,9.735519,2.484561,0.61639286,0
22555994.7,,4881,0,1.5592,22000.098,9.3E-6,1.5757144,0.034058075,0.97052943,0.004404,0.22560953,0.001246,1.196139,0.004404,0.59689375,4.4745048,0.0060101824,99.119823,0,0,1,,,,2.6889E-7,8.99821,2.482876,0.61592977,0
22556203.75,,4881,0,1.6241,22000.098,9.2E-6,1.6418334,0.035997637,0.96171827,0.00406,0.24792017,0.001368,1.2096384,0.00406,0.51258095,4.1993519,0.0041367092,99.394481,0,0,1,,,,2.8916E-7,8.94901,2.6956168,0.58575875,0
22556247.16,,4881,0,1.6239,22000.098,9.3E-6,1.6411727,0.035202357,0.9457807,0.004241,0.24782047,0.001367,1.1936012,0.004241,0.51215469,4.1910934,0.0068244163,99.007671,0,0,1,,,,2.8659E-7,8.398704,2.6934477,0.57628348,0
22556453.67,,4881,0,1.69,22000.098,9.2E-6,1.7078691,0.037414523,0.93335474,0.004887,0.27159612,0.001607,1.2049509,0.004887,1.1978458,4.0144436,0.0072956433,98.956869,0,0,1,,,,3.0206E-7,8.382187,2.9168168,0.54650251,0
22556498.19,,4881,0,1.69,22000.098,9.3E-6,1.7077684,0.036753566,0.93351688,0.004434,0.27154466,0.001606,1.2050615,0.004434,0.94220326,4.0452875,0.0073492714,98.957003,0,0,1,,,,2.9978E-7,8.028887,2.9164728,0.54662968,0
22556708.14,,4881,0,1.7547,22000.098,9.2E-6,1.7734251,0.039180131,0.92497001,0.004657,0.2975932,0.001881,1.2225632,0.004657,0.95927033,3.9607268,0.0093663389,98.713426,0,0,1,,,,3.1098E-7,8.090575,3.1450365,0.52157265,0
22556751.64,,4881,0,1.7549,22000.098,9.3E-6,1.7730039,0.038753752,0.92553547,0.004988,0.29738172,0.001879,1.2229172,0.004988,0.61113136,3.9425561,0.0081171187,98.879406,0,0,1,,,,3.122E-7,7.921454,3.143543,0.52201546,0
22556959.84,,4881,0,1.8211,22000.098,9.4E-6,1.8407862,0.040538816,0.92389944,0.004766,0.32794545,0.002196,1.2518449,0.004766,1.2175621,3.8128555,0.0081637862,98.891404,0,0,1,,,,3.3033E-7,7.885112,3.3884939,0.5019048,0
22557002.27,,4881,0,1.8209,22000.098,9.3E-6,1.8404479,0.039889117,0.9228947,0.005352,0.32796417,0.002197,1.2508589,0.005352,0.79351476,3.7744376,0.0054388042,99.254601,0,0,1,,,,3.3276E-7,7.625711,3.3872484,0.50145114,0
22557205.72,,4881,0,1.8863,22000.098,9.4E-6,1.9059455,0.041474741,0.92680097,0.005811,0.36063665,0.002551,1.2874376,0.005811,0.94395505,3.7395027,0.0060311844,99.199936,0,0,1,,,,3.4572E-7,7.548875,3.6326284,0.48626834,0
22557248.55,,4881,0,1.8861,22000.098,9.3E-6,1.9064055,0.041246288,0.9260351,0.005625,0.36088037,0.002554,1.2869155,0.005625,1.0027217,3.7302647,0.0083307374,98.892739,0,0,1,,,,3.47E-7,7.479005,3.6343818,0.48574929,0
22557453.28,,4881,0,1.952,22000.098,9.3E-6,1.9733015,0.042359043,0.93676216,0.006117,0.39674942,0.002801,1.3335116,0.006117,1.5196897,3.6198713,0.0051954692,99.313327,0,0,1,,,,3.6965E-7,7.460529,3.8939186,0.47471822,0
22557496.94,,4881,0,1.9522,22000.098,9.3E-6,1.9725687,0.041962115,0.92985261,0.00634,0.39639092,0.002799,1.3262435,0.00634,1.3589716,3.6625781,0.0093876994,98.777016,0,0,1,,,,3.6432E-7,7.239743,3.8910274,0.47139174,0
22557703,,4881,0,2.0171,22000.098,9.2E-6,2.0378006,0.043515045,0.94142245,0.006256,0.43351314,0.00278,1.3749356,0.006256,1.2958221,3.6336917,0.0075180604,99.04216,0,0,1,,,,3.801E-7,7.325156,4.1526315,0.46197966,0
22557746.25,,4881,0,2.0166,22000.098,9.3E-6,2.0381845,0.043381943,0.94392793,0.006239,0.43363337,0.002779,1.3775613,0.006239,0.8307938,3.5816304,0.0021675513,99.719472,0,0,1,,,,3.8513E-7,7.267383,4.154196,0.46312193,0
22557952.55,,4881,0,2.0829,22000.098,9.2E-6,2.1048031,0.044238884,0.94854175,0.006308,0.47388416,0.002527,1.4224259,0.006308,0.95820408,3.5816914,0.0077723449,99.024242,0,0,1,,,,3.9888E-7,7.163261,4.430196,0.45065582,0
22557994.52,,4881,0,2.0834,22000.098,9.2E-6,2.1044287,0.044310649,0.95194661,0.006213,0.47360171,0.002529,1.4255483,0.006213,0.90869058,3.5618091,0.0044769996,99.433769,0,0,1,,,,4.0125E-7,7.163383,4.4286202,0.45235393,0
22558197.23,,4881,0,2.1483,22000.098,9.2E-6,2.1694526,0.045426408,0.95423472,0.006493,0.51554049,0.002251,1.4697752,0.006493,0.72646687,3.5590922,0.0099821979,98.770704,0,0,1,,,,4.1514E-7,7.123618,4.7065245,0.43985046,0
22558240.7,,4881,0,2.1479,22000.098,9.2E-6,2.1695842,0.045512535,0.96124819,0.006749,0.51570875,0.002251,1.4769569,0.006749,0.48026669,3.619819,0.012219076,98.517829,0,0,1,,,,4.1063E-7,7.118184,4.7070956,0.44305641,0
22558446.08,,4881,0,2.2144,22000.098,9.3E-6,2.2312549,0.046854739,0.97709953,0.004418,0.55807877,0.002135,1.5351783,0.004418,0.38584816,3.5277936,0.0064768955,99.207675,0,0,1,,,,4.3658E-7,7.239638,4.9784983,0.4379148,0
22558487.95,,4881,0,2.2143,22000.098,9.3E-6,2.2325553,0.046526268,0.9683227,0.004161,0.55902431,0.002135,1.527347,0.004161,0.77901078,3.5408231,0.0092704501,98.87415,0,0,1,,,,4.3333E-7,7.055587,4.9843032,0.43372843,0
22558693.42,,4881,0,2.279,22000.098,9.3E-6,2.2983978,0.047913269,0.97157387,0.004154,0.6066014,0.002175,1.5781753,0.004154,0.46425804,3.4901191,0.0034863236,99.578286,0,0,1,,,,4.5291E-7,7.081646,5.2826325,0.42271789,0
22558736.69,,4881,0,2.2793,22000.098,9.3E-6,2.2992339,0.047609773,0.96767226,0.004159,0.60731575,0.002176,1.574988,0.004159,0.57315831,3.5229873,0.0093019839,98.8885,0,0,1,,,,4.4896E-7,6.980238,5.2864766,0.42086725,0
22558941.66,,4881,0,2.345,22000.098,9.3E-6,2.361404,0.049564486,0.97683888,0.00419,0.6549686,0.002298,1.6318075,0.00419,0.48100744,3.522941,0.0044146438,99.479229,0,0,1,,,,4.6406E-7,7.045975,5.576229,0.41366868,0
22558984.98,,4881,0,2.345,22000.098,9.3E-6,2.3679858,0.049581899,0.96661123,0.004229,0.66030171,0.002315,1.6269129,0.004229,1.4046193,3.5202885,0.011403004,98.661905,0,0,1,,,,4.6437E-7,7.045882,5.607357,0.40819975,0
22559188.41,,4881,0,2.41,22000.098,9.3E-6,2.430906,0.050678721,0.97379178,0.004633,0.71255862,0.002491,1.6863504,0.004633,1.3230325,3.5189256,0.0086434612,98.996668,0,0,1,,,,4.8085E-7,7.040577,5.9093039,0.400588,0
22559233.17,,4881,0,2.4101,22000.098,9.3E-6,2.4311274,0.050712717,0.98150482,0.004289,0.71279914,0.002492,1.694304,0.004289,1.0263321,3.5450828,0.0095430656,98.899412,0,0,1,,,,4.7972E-7,7.037851,5.9103804,0.40372415,0
22559436.59,,4881,0,2.4762,22000.098,9.3E-6,2.4972524,0.051920125,0.98412541,0.004758,0.77301577,0.002696,1.7571412,0.004758,0.80978068,3.5546516,0.013997298,98.411193,0,0,1,,,,4.9683E-7,7.090166,6.2362693,0.39408329,0
22559479.02,,4881,0,2.4765,22000.098,9.2E-6,2.5026001,0.052525464,0.97311238,0.00474,0.7780393,0.002715,1.7511517,0.00474,0.84653616,3.5269133,0.0083694716,99.042358,0,0,1,,,,4.98E-7,7.109303,6.2630074,0.38884054,0
22559810.91,,4881,0,2.5413,22000.098,9.3E-6,2.5636833,0.053303313,0.98747357,0.004905,0.83874365,0.002958,1.8262172,0.004905,1.0877046,3.5641118,0.0064545901,99.272958,0,0,1,,,,5.1349E-7,7.053827,6.5724719,0.38517768,0
22559859.77,,4881,0,2.5412,22000.098,9.3E-6,2.5660707,0.053778388,0.97880612,0.004809,0.84115074,0.002969,1.8199569,0.004809,0.46116614,3.513132,0.005628364,99.357216,0,0,1,,,,5.1901E-7,7.128224,6.584719,0.3814416,0