File: Data/HeatCapacity/0p19mg_drhc_EuPd2S4_11132020.dat
[Header]
TITLE,0p19mg_drhc_EuPd2S4_11132020.dat
BYAPP,HeatCapacity,3.8.14,1.7
INFO,0.20,MASS:Sample Mass (mg)
INFO,0,MASSERR:Sample Mass Error (mg)
INFO,0,MOLWGHT:Formula Weight (g/mole)
INFO,0,ATOMS:Atoms per Formula Unit
INFO,PPMS Heat Capacity Option 3.8.14 Build 19,APPNAME
DATATYPE,TIME,1
DATATYPE,COMMENT,2
STARTUPAXIS, X, 8, LINEAR, AUTO
STARTUPAXIS, Y1, 10, LINEAR, AUTO
[Data]
Time Stamp (Seconds),Comment (),System Status (Code),Puck Temp (Kelvin),System Temp (Kelvin),Field (Oersted),Pressure (Torr),Sample Temp (Kelvin),Temp Rise (Kelvin),Samp HC (µJ/K),Samp HC Err (µJ/K),Addenda HC (µJ/K),Addenda HC Err (µJ/K),Total HC (µJ/K),Total HC Err (µJ/K),Fit Deviation (ChiSquare),Time Const tau1 (seconds),Time Const tau2 (seconds),Sample Coupling (Percent),Debye Temp (Kelvin),Debye Temp Err (Kelvin),Cal Correction (Factor),Therm Resist (Ohms),Htr Resist (Ohms),Puck Resist (Ohms),Wire Cond (W/K),Meas Time (seconds),Temp Squared (K^2),Samp HC/Temp (µJ/K/K),Addenda Offset HC (µJ/K)
27444309.36,Error: Error at T = 0.12 K while attempting to measure time window: The requested temperature rise delT = 0.00239917728285858 will produce a resistance change of only delRtrip = -77.5491783286652.  However; I measure the noise to be SigmaThRes = 11.3906188083103
27444309.55,Error: Using default time-constant of 1.0199 seconds
27444366.66,Error: Warning:  Measured time constant less than time constant calculated from addenda table.  Changing time constant to addenda table value
27444366.75,CALFILE: DRPuck93_2.cal - Addenda #13 measured on 11/11/2020 from 0.10028 to 3.7096 K
27444366.89,,4881,0,0.12,-0.011,9.3E-6,0.12019517,0.00029163826,0.0317584,0.0003798,0.0059476113,0.0003798,0.037706011,0,1.0824758,1.1565012,0,100,0,0,1,,,,3.2604E-8,2.03984,0.014446878,0.26422361,0
27444661.34,,4881,0,0.1199,-0.011,9.3E-6,0.12151693,0.0026945199,0.051546055,0.002514,0.0060075623,0.000456,0.057553617,0.002473,2.1230364,15.809569,0,100,0,0,1,,,,3.6404E-9,29.52247,0.014766365,0.42418825,0
27444809.97,,4881,0,0.12,-0.011,9.4E-6,0.12144911,0.002807743,0.052377142,0.002231,0.006005247,0.0004531,0.058382389,0.002184,1.3630569,16.160968,0,100,0,0,1,,,,3.6126E-9,31.61914,0.014749887,0.43126822,0
27445240.14,,4881,0,0.138,-0.011,9.2E-6,0.1396158,0.0033014795,0.040872856,0.001523,0.0061781443,0.0007098,0.047051,0.001348,2.1471393,10.216857,0,100,0,0,1,,,,4.6052E-9,21.09355,0.019492573,0.29275236,0
27445334.94,,4881,0,0.138,-0.011,9.4E-6,0.13977515,0.0033313505,0.040256477,0.001475,0.0061792307,0.000709,0.046435708,0.001293,1.3974744,10.440558,0,100,0,0,1,,,,4.4476E-9,20.43371,0.019537093,0.28800882,0
27445431.28,,4881,0,0.138,-0.011,9.3E-6,0.13967454,0.0033953292,0.040183082,0.001507,0.0061786324,0.0007094,0.046361714,0.00133,1.6635787,10.425545,0,100,0,0,1,,,,4.4469E-9,20.88112,0.019508978,0.28769081,0
27445793.91,,4881,0,0.1591,-0.011,9.3E-6,0.16119699,0.004110174,0.031102607,0.001704,0.0067389075,0.0005131,0.037841515,0.001625,2.7438935,6.7301881,0,100,0,0,1,,,,5.6227E-9,13.71176,0.025984469,0.19294782,0
27445867.39,,4881,0,0.159,-0.011,9.2E-6,0.16133657,0.0040764418,0.030456259,0.001589,0.0067463394,0.0005128,0.037202599,0.001504,1.8651825,6.4731922,0,100,0,0,1,,,,5.7472E-9,13.46038,0.026029489,0.18877468,0
27445939.61,,4881,0,0.159,-0.011,9.3E-6,0.16119964,0.0039512311,0.03135383,0.00168,0.0067398118,0.0005131,0.038093642,0.0016,2.7629463,6.7434013,0,100,0,0,1,,,,5.649E-9,12.94638,0.025985326,0.19450309,0
27446259.66,,4881,0,0.183,-0.011,9.3E-6,0.18538594,0.004557697,0.025143472,0.001884,0.0075842251,0.0007305,0.032727698,0.001736,1.1910192,4.5595616,0,100,0,0,1,,,,7.1778E-9,8.983016,0.034367947,0.13562772,0
27446321.11,,4881,0,0.1831,-0.011,9.2E-6,0.18564158,0.0046988761,0.023994135,0.001853,0.0075904884,0.0007321,0.031584623,0.001702,1.3387953,4.4085989,0,100,0,0,1,,,,7.1643E-9,9.119123,0.034462796,0.12924979,0
27446381.64,,4881,0,0.183,-0.011,9.3E-6,0.18537923,0.0045223607,0.024289299,0.001981,0.0075845673,0.0007306,0.031873866,0.001841,0.96064063,4.3002891,0,100,0,0,1,,,,7.412E-9,8.817198,0.034365461,0.13102492,0
27446668.09,,4881,0,0.2111,-0.011,9.2E-6,0.21377376,0.0050319775,0.019118372,0.001686,0.008968109,-1.391E-6,0.028086481,0.001686,0.77043921,3.0917744,0,100,0,0,1,,,,9.0843E-9,6.015116,0.045699218,0.089432736,0
27446719.55,,4881,0,0.2111,-0.011,9.4E-6,0.21381876,0.0051183771,0.018865372,0.002825,0.0089681046,-1.059E-6,0.027833476,0.002825,0.83120255,3.0212595,0,100,0,0,1,,,,9.2125E-9,6.183549,0.045718464,0.088230664,0
27446771.91,,4881,0,0.2111,-0.011,9.3E-6,0.21373866,0.005016196,0.019282394,0.00182,0.0089681024,-1.687E-6,0.028250496,0.00182,0.90816932,3.072775,0,100,0,0,1,,,,9.1938E-9,6.042519,0.045684215,0.090214814,0
27447032.94,,4881,0,0.242,-0.011,9.3E-6,0.24511459,0.0057309661,0.017657422,0.00115,0.0088496652,0.000442,0.026507087,0.001062,0.65659166,2.2507514,0,100,0,0,1,,,,1.1777E-8,4.578847,0.060081161,0.072037418,0
27447074.19,,4881,0,0.2419,-0.011,9.3E-6,0.24520129,0.0056691639,0.017304022,0.001304,0.0088523452,0.0004412,0.026156367,0.001227,0.60624401,2.1966531,0,100,0,0,1,,,,1.1907E-8,4.501503,0.060123673,0.070570681,0
27447115.09,,4881,0,0.2421,-0.011,9.4E-6,0.24516076,0.0057173414,0.01748429,0.0008512,0.0088520456,0.0004413,0.026336336,0.0008512,0.70100296,2.377684,0.015014278,97.178664,0,0,1,,,,1.1219E-8,4.393306,0.0601038,0.071317651,0
27447334.27,,4881,0,0.2791,-0.011,9.4E-6,0.2832473,0.0072444506,0.017641827,0.0007193,0.010660232,0.0002633,0.028302059,0.0007193,0.56851433,1.9067908,0.0081018856,98.197362,0,0,1,,,,1.4949E-8,4.755368,0.080229036,0.062284183,0
27447374.14,,4881,0,0.2791,-0.011,9.3E-6,0.28261305,0.0065944546,0.017181611,0.0008042,0.010637385,0.0002609,0.027818996,0.0008042,0.59940114,1.9917158,0.022028533,95.364812,0,0,1,,,,1.4229E-8,3.813582,0.079870139,0.060795533,0
27447412.03,,4881,0,0.279,-0.011,9.2E-6,0.28291029,0.0067165611,0.017418628,0.0008533,0.010648143,0.000262,0.028066771,0.0008533,0.71276614,1.8957514,0.0036696902,99.179392,0,0,1,,,,1.4852E-8,3.983432,0.080038232,0.061569441,0
27447627.41,,4881,0,0.3211,-0.011,9.3E-6,0.32488578,0.0075389817,0.022367836,0.001479,0.012313068,0.00104,0.034680903,0.001479,0.95230956,1.8566351,0.0098438761,97.693095,0,0,1,,,,1.8864E-8,3.791503,0.10555077,0.068848305,0
27447666.53,,4881,0,0.3212,-0.011,9.3E-6,0.32482718,0.0074382078,0.022375238,0.0015,0.01231105,0.001039,0.034686288,0.0015,0.89768689,1.8794473,0.015730206,96.364874,0,0,1,,,,1.8748E-8,3.71327,0.1055127,0.068883516,0
27447706.88,,4881,0,0.3212,-0.011,9.2E-6,0.324863,0.0076008908,0.022081103,0.001462,0.01231688,0.00104,0.034397983,0.001462,0.78277152,1.9622497,0.025524558,94.389889,0,0,1,,,,1.7965E-8,3.758895,0.10553597,0.067970509,0
27447927.08,,4881,0,0.3692,-0.011,9.4E-6,0.37379524,0.0080803932,0.035716491,0.001392,0.015194305,0.001001,0.050910796,0.001392,0.65787795,2.0127672,0.0026024325,99.382522,0,0,1,,,,2.5371E-8,3.924499,0.13972288,0.095550952,0
27447963.52,,4881,0,0.369,-0.011,9.4E-6,0.37371051,0.0082995596,0.035067619,0.001361,0.015196878,0.001001,0.050264497,0.001361,0.60245452,2.1333648,0.017783246,96.049374,0,0,1,,,,2.4037E-8,4.025534,0.13965954,0.093836321,0
27448002.27,,4881,0,0.369,-0.011,9.3E-6,0.37395931,0.0084539094,0.035670283,0.001387,0.015205712,0.001001,0.050875995,0.001387,0.6305637,2.0670999,0.0097945409,97.739151,0,0,1,,,,2.4893E-8,4.26673,0.13984557,0.095385465,0
27448224.22,,4881,0,0.4252,-0.011,9.3E-6,0.42915398,0.0084770392,0.062222043,0.002407,0.018172465,0.001169,0.080394508,0.002407,0.6501858,2.6751521,0.01249133,97.315648,0,0,1,,,,3.0551E-8,4.1342,0.18417314,0.14498769,0
27448266.86,,4881,0,0.4249,-0.011,9.3E-6,0.43010312,0.009764835,0.063663929,0.002073,0.018225955,0.001172,0.081889884,0.002073,0.74536051,2.5732259,0.0065014534,98.535161,0,0,1,,,,3.211E-8,5.350304,0.1849887,0.14802015,0
27448309.19,,4881,0,0.4252,-0.011,9.2E-6,0.42995808,0.0095923121,0.063125492,0.002233,0.018215425,0.001171,0.081340917,0.002233,0.955233,2.5740719,0.0065570747,98.529645,0,0,1,,,,3.1885E-8,5.146452,0.18486395,0.14681778,0
27448534.58,,4881,0,0.4891,-0.011,9.4E-6,0.49436079,0.0092901665,0.11247377,0.002082,0.022474738,0.0006157,0.13494851,0.002082,0.87448417,3.2647021,0.006074463,98.652338,0,0,1,,,,4.1729E-8,5.148144,0.2443926,0.22751353,0
27448580.05,,4881,0,0.4891,-0.011,9.3E-6,0.49514851,0.010786853,0.11367107,0.001807,0.022529644,0.0006117,0.13620072,0.001807,0.94958338,3.2987364,0.0057068502,98.740509,0,0,1,,,,4.1656E-8,6.529404,0.24517204,0.22956966,0
27448625.81,,4881,0,0.4891,-0.011,9.2E-6,0.49500397,0.010840976,0.11398028,0.0018,0.022520251,0.0006124,0.13650053,0.0018,0.95082915,3.3104539,0.0056727343,98.749874,0,0,1,,,,4.1598E-8,6.597473,0.24502893,0.23026135,0
27448853.16,,4881,0,0.5631,-0.011,9.4E-6,0.56864679,0.010560647,0.19244338,0.003869,0.027888825,0.0008205,0.22033221,0.003869,0.73463667,4.3060831,0.0082009471,98.261175,0,0,1,,,,5.186E-8,6.620908,0.32335918,0.3384234,0
27448905.53,,4881,0,0.563,-0.011,9.2E-6,0.56976355,0.012475938,0.1950965,0.002865,0.027960073,0.0008304,0.22305657,0.002865,1.0102507,4.2571857,0.0053291461,98.851166,0,0,1,,,,5.2862E-8,8.612166,0.32463051,0.3424166,0
27448957.61,,4881,0,0.5631,-0.011,9.3E-6,0.56987506,0.012372876,0.19434726,0.003118,0.027964421,0.000831,0.22231168,0.003118,1.5549117,4.1642528,0.0034460229,99.244437,0,0,1,,,,5.3697E-8,8.514371,0.32475759,0.34103486,0
27449196.23,,4881,0,0.6481,-0.011,9.2E-6,0.65466977,0.01224402,0.30978578,0.00601,0.035919136,0.001579,0.34570491,0.00601,1.0468873,5.1580938,0.0056321342,98.818718,0,0,1,,,,6.7666E-8,8.328506,0.42859251,0.47319395,0
27449254.23,,4881,0,0.6482,-0.011,9.3E-6,0.65577662,0.013959983,0.31436698,0.005204,0.036030197,0.001586,0.35039718,0.005204,1.468897,5.1255924,0.0031600563,99.328946,0,0,1,,,,6.8734E-8,10.31619,0.43004298,0.47938119,0
27449312.28,,4881,0,0.6479,-0.011,9.4E-6,0.65548544,0.013973443,0.3126575,0.005065,0.036001555,0.001584,0.34865906,0.005065,1.766004,5.1983429,0.0052915515,98.893155,0,0,1,,,,6.7675E-8,10.25118,0.42966116,0.47698619,0
27449556.88,,4881,0,0.7462,-0.011,9.2E-6,0.75381252,0.014483507,0.47826221,0.0087,0.045803622,0.002075,0.52406583,0.0087,2.0494068,6.1603434,0.0044132536,99.096364,0,0,1,,,,8.5717E-8,10.39669,0.56823332,0.63445777,0
27449619.91,,4881,0,0.7462,-0.011,9.3E-6,0.75452161,0.016124803,0.48163083,0.007461,0.045871742,0.002074,0.52750257,0.007461,1.3491999,6.1712558,0.005072192,98.957535,0,0,1,,,,8.6229E-8,12.32069,0.56930285,0.6383261,0
27449682.98,,4881,0,0.746,-0.011,9.3E-6,0.75485314,0.016269136,0.47697941,0.007794,0.045907677,0.002074,0.52288708,0.007794,2.3383844,6.1272017,0.0044452215,99.088591,0,0,1,,,,8.5992E-8,12.34251,0.56980327,0.63188371,0
27449933.44,,4881,0,0.858,-0.011,9.3E-6,0.86752015,0.0170287,0.6883915,0.006245,0.060137257,0.001617,0.74852876,0.006245,1.5492772,6.9574679,0.0047156427,99.076743,0,0,1,,,,1.0843E-7,12.2544,0.75259121,0.79351644,0
27450001.03,,4881,0,0.8582,-0.011,9.3E-6,0.86821771,0.018581653,0.69165552,0.005708,0.060241221,0.001622,0.75189674,0.005708,1.674878,7.0190682,0.0050789562,99.011387,0,0,1,,,,1.0803E-7,13.91494,0.75380198,0.79663835,0
27450068.34,,4881,0,0.8581,-0.011,9.4E-6,0.86844254,0.018654327,0.68958237,0.005906,0.060269981,0.001624,0.74985235,0.005906,1.9137207,6.9410142,0.0044283737,99.131614,0,0,1,,,,1.0883E-7,14.03814,0.75419244,0.79404491,0
27450325.08,,4881,0,0.9882,-0.011,9.3E-6,0.99822839,0.020009704,0.93813108,0.009609,0.079567386,0.002353,1.0176985,0.009609,2.3621479,7.5120568,0.0051637588,99.039742,0,0,1,,,,1.3659E-7,13.88203,0.99645992,0.93979603,0
27450396.78,,4881,0,0.9881,-0.011,9.4E-6,0.99907366,0.021135712,0.94418196,0.008693,0.079695419,0.002355,1.0238774,0.008693,2.7392907,7.5166933,0.0039993963,99.254827,0,0,1,,,,1.3708E-7,15.02411,0.99814817,0.9450574,0
27450468.38,,4881,0,0.9882,-0.011,9.2E-6,0.99888606,0.021240308,0.9396286,0.008621,0.079670824,0.002355,1.0192994,0.008621,2.1215547,7.5468997,0.0053187595,99.015065,0,0,1,,,,1.362E-7,15.03339,0.99777336,0.94067646,0
27470379.02,,4881,0,1.137,-0.011,9.2E-6,1.148063,0.023357781,1.2229572,0.01252,0.10821633,0.003775,1.3311736,0.01252,1.514215,7.9000765,0.0062716573,98.929106,0,0,1,,,,1.7004E-7,15.0938,1.3180487,1.0652353,0
27470452.66,,4881,0,1.137,-0.011,9.2E-6,1.1491414,0.024237788,1.223111,0.01187,0.10838638,0.003783,1.3314974,0.01187,1.9898498,7.8468548,0.0050920517,99.126899,0,0,1,,,,1.7095E-7,15.80015,1.320526,1.0643694,0
27470525.63,,4881,0,1.1371,-0.011,9.3E-6,1.1492569,0.024366376,1.2170921,0.01174,0.10842407,0.003784,1.3255162,0.01174,2.1493811,8.042265,0.0082093228,98.627891,0,0,1,,,,1.6675E-7,15.69371,1.3207915,1.0590252,0
27470802.84,,4881,0,1.3092,-0.011,9.3E-6,1.3228916,0.028078204,1.510411,0.01518,0.13404831,0.003803,1.6444593,0.01518,1.5090214,7.9378185,0.0062008379,98.948995,0,0,1,,,,2.0903E-7,16.08453,1.7500421,1.1417496,0
27470877.36,,4881,0,1.3091,-0.011,9.3E-6,1.3228787,0.028297283,1.498521,0.01475,0.13404679,0.003803,1.6325678,0.01475,1.7896102,7.8695284,0.0067842925,98.84696,0,0,1,,,,2.0949E-7,15.87564,1.750008,1.1327728,0
27470951.8,,4881,0,1.309,-0.011,9.3E-6,1.322932,0.028147159,1.5052385,0.01577,0.1340532,0.003803,1.6392917,0.01577,2.0189903,7.8955504,0.0053176218,99.097439,0,0,1,,,,2.0922E-7,15.73906,1.7501491,1.1378049,0
27471227.77,,4881,0,1.5063,-0.011,9.3E-6,1.5227544,0.03244575,1.7926614,0.01093,0.1832206,0.003481,1.975882,0.01093,2.6991299,7.6000864,0.0054931072,99.13604,0,0,1,,,,2.6185E-7,15.7911,2.3187811,1.1772492,0
27471299.59,,4881,0,1.5059,-0.011,9.2E-6,1.5226003,0.03218834,1.7930469,0.01072,0.18318263,0.003479,1.9762295,0.01072,1.282727,7.6576147,0.006335798,99.009824,0,0,1,,,,2.602E-7,15.20017,2.3183117,1.1776215,0
27471372.8,,4881,0,1.5058,-0.011,9.2E-6,1.5225857,0.032235044,1.8017071,0.0104,0.1831712,0.003479,1.9848783,0.0104,1.2805046,7.6410504,0.0041531192,99.348383,0,0,1,,,,2.6117E-7,15.31523,2.3182672,1.1833206,0
27471642.63,,4881,0,1.7334,-0.011,9.3E-6,1.7519208,0.037750382,2.041239,0.01395,0.25558151,0.005393,2.2968205,0.01395,1.5710321,7.2435494,0.0049712419,99.303195,0,0,1,,,,3.1884E-7,15.2821,3.0692264,1.1651435,0
27471712.83,,4881,0,1.7327,-0.011,9.2E-6,1.7512968,0.037156846,2.0299708,0.01321,0.25544215,0.00539,2.2854129,0.01321,1.7766565,7.2807952,0.0063037029,99.123434,0,0,1,,,,3.1609E-7,14.4871,3.0670403,1.1591244,0
27471783.05,,4881,0,1.7333,-0.011,9.3E-6,1.7514593,0.037306686,2.0309304,0.01321,0.25551002,0.005392,2.2864404,0.01321,1.8513109,7.3057719,0.0063826932,99.115299,0,0,1,,,,3.1517E-7,14.56159,3.0676097,1.1595647,0
27472050.7,,4881,0,1.9951,-0.011,9.4E-6,2.0164534,0.043364841,2.267542,0.01669,0.36216977,0.00644,2.6297117,0.01669,1.70318,6.8841642,0.0050176392,99.384385,0,0,1,,,,3.8375E-7,14.61154,4.0660845,1.1245199,0
27472118.08,,4881,0,1.995,-0.011,9.3E-6,2.0158149,0.04217688,2.2758142,0.01774,0.36196638,0.006445,2.6377806,0.01774,1.6680415,6.9224398,0.0060621426,99.257614,0,0,1,,,,3.8317E-7,13.76833,4.0635096,1.1289798,0
27472186.61,,4881,0,1.9954,-0.011,9.3E-6,2.0160104,0.042589879,2.2603937,0.0173,0.36210334,0.006442,2.622497,0.0173,1.8781085,6.9567007,0.0072208895,99.12407,0,0,1,,,,3.7945E-7,13.84488,4.0642977,1.1212213,0
27472450.72,,4881,0,2.2957,-0.011,9.3E-6,2.3187118,0.048712547,2.5274234,0.01115,0.53637635,0.004953,3.0637998,0.01115,1.2277339,6.7261309,0.0080597858,99.167749,0,0,1,,,,4.5811E-7,13.9134,5.3764245,1.0900119,0
27472518.28,,4881,0,2.2954,-0.011,9.4E-6,2.3188228,0.048242632,2.5303871,0.01219,0.53639975,0.004953,3.0667868,0.01219,1.3194323,6.7060079,0.007179283,99.25614,0,0,1,,,,4.5966E-7,13.45226,5.376939,1.0912378,0
27472585.3,,4881,0,2.2959,-0.011,9.3E-6,2.3220263,0.048352704,2.5052825,0.0112,0.53849219,0.004989,3.0437747,0.0112,1.8479442,6.7032679,0.0084285818,99.133813,0,0,1,,,,4.5676E-7,13.41202,5.391806,1.0789208,0
27472848.33,,4881,0,2.6419,-0.011,9.3E-6,2.6688539,0.05549346,2.8153703,0.01505,0.81262549,0.008036,3.6279958,0.01505,1.3848814,6.7036771,0.01032852,99.111945,0,0,1,,,,5.4412E-7,13.40654,7.1227811,1.0548986,0
27472915.89,,4881,0,2.642,-0.011,9.3E-6,2.6685177,0.055864407,2.8307774,0.01483,0.81238913,0.008034,3.6431665,0.01483,2.5406464,6.7430812,0.011343744,99.02706,0,0,1,,,,5.4349E-7,13.40735,7.1209867,1.0608052,0
27472982.3,,4881,0,2.6418,-0.011,9.4E-6,2.669292,0.056112812,2.8345404,0.01472,0.81314352,0.008042,3.6476839,0.01472,1.0833153,6.7522136,0.011001514,99.057541,0,0,1,,,,5.4333E-7,13.48616,7.1251198,1.0619072,0
27473298.14,,4881,0,3.0408,-0.011,9.4E-6,3.0694305,0.064049673,1.2739069,0.01564,1.2660006,0.01337,2.5399076,0.01564,0.86417799,3.9413406,0.015030695,98.485954,0,0,1,,,,6.4693E-7,7.96648,9.4214039,0.41503038,0
27473348.42,,4881,0,3.0408,-0.011,9.3E-6,3.0705831,0.063737299,1.2832256,0.01555,1.2677544,0.01338,2.5509799,0.01555,0.75090727,3.9983717,0.024264396,97.600973,0,0,1,,,,6.42E-7,7.882681,9.4284804,0.41790941,0
27473399.36,,4881,0,3.0415,-0.011,9.3E-6,3.073963,0.064220991,1.2783177,0.01563,1.2720443,0.01342,2.5503621,0.01563,1.0398339,3.9689416,0.018719745,98.130784,0,0,1,,,,6.4567E-7,7.996743,9.4492484,0.41585332,0
27473749.05,,4881,0,3.5005,-0.011,9.4E-6,3.5329839,0.079100941,0.55452433,0.0257,1.9514314,0.01987,2.5059557,0.01631,1.1854317,3.2896764,0,100,0,0,1,,,,7.6176E-7,7.937883,12.481975,0.15695637,0
27473896.41,,4881,0,3.4995,-0.011,9.4E-6,3.5251,0.072081427,0.55641983,0.02071,1.9408756,0.01976,2.4972955,0.02071,0.89038032,3.3522131,0.063507585,90.038777,0,0,1,,,,7.4914E-7,6.579353,12.42633,0.15784512,0
27473999.63,,4881,0,3.5,-0.011,9.3E-6,3.524586,0.073306014,0.55585314,0.02071,1.9404747,0.01975,2.4963278,0.02071,0.6807309,3.3679515,0.072478059,88.816107,0,0,1,,,,7.4593E-7,6.704426,12.422706,0.15770736,0
27495012.13,,4881,0,0.9999,-0.004,9.3E-6,1.0103574,0.021016301,0.96222308,0.007542,0.081517641,0.002388,1.0437407,0.007542,1.256468,7.6864686,0.0067635675,98.767198,0,0,1,,,,1.3723E-7,14.18256,1.0208221,0.95235908,0
27495085.11,,4881,0,1.0014,-0.004,9.4E-6,1.0112661,0.021933226,0.97296154,0.007239,0.081671458,0.002391,1.054633,0.007239,0.82380291,8.0084928,0.0066601729,98.826218,0,0,1,,,,1.3302E-7,15.37294,1.022659,0.96212221,0
27495158.88,,4881,0,1.0008,-0.004,9.3E-6,1.0120034,0.022104719,0.97078878,0.006577,0.081767209,0.002393,1.052556,0.006577,1.0372139,7.5146585,0.0031473306,99.413029,0,0,1,,,,1.4077E-7,16.01699,1.024151,0.95927419,0
27495322.31,Error: Warning: Current field is 555.566 Oe;
27495322.52,Error: but addenda was obtained at 0.007 Oe.
27495560.98,,4881,0,1,555.566,9.3E-6,1.0086672,0.02100984,0.9669565,0.006592,0.081242087,0.002382,1.0481986,0.006592,1.8466686,7.7773749,0.0040282584,99.271856,0,0,1,,,,1.3562E-7,14.18256,1.0174096,0.95864767,0
27495640.89,,4881,0,1.0001,555.566,9.2E-6,1.0093953,0.021507208,0.9683545,0.005863,0.081331624,0.002384,1.0496861,0.005863,1.1682282,7.4909684,0.0030980675,99.419024,0,0,1,,,,1.4082E-7,15.55475,1.0188789,0.95934118,0
27495717.22,,4881,0,1.0008,555.566,9.3E-6,1.0096296,0.021436423,0.96539838,0.007074,0.081413009,0.002385,1.0468114,0.007074,0.96009002,7.8561479,0.0062909059,98.874619,0,0,1,,,,1.3454E-7,14.98194,1.0193519,0.95619065,0
27495885.53,Error: Warning: Current field is 1111.119 Oe;
27495885.69,Error: but addenda was obtained at 0.007 Oe.
27496025.13,,4881,0,1,1111.119,9.3E-6,1.0072772,0.020893534,0.96405383,0.006185,0.081016063,0.002378,1.0450699,0.006185,1.0875132,7.7476347,0.005372431,99.023614,0,0,1,,,,1.3602E-7,14.18256,1.0146074,0.95708886,0
27496103.7,,4881,0,1,1111.119,9.3E-6,1.0075361,0.021632822,0.97341503,0.006705,0.081053159,0.002378,1.0544682,0.006705,1.1010769,7.8386784,0.0066719305,98.790107,0,0,1,,,,1.3593E-7,15.49527,1.0151291,0.96613411,0
27496177.72,,4881,0,0.9998,1111.119,9.3E-6,1.0081009,0.021672555,0.9660058,0.006367,0.081126473,0.00238,1.0471323,0.006367,0.81938949,7.5027002,0.0041563483,99.220623,0,0,1,,,,1.405E-7,15.67736,1.0162674,0.95824317,0
27496343.98,Error: Warning: Current field is 1666.682 Oe;
27496344.16,Error: but addenda was obtained at 0.007 Oe.
27496447.91,,4881,0,1,1666.682,9.3E-6,1.0078179,0.020796288,0.97309054,0.006964,0.081097084,0.002379,1.0541876,0.006964,1.4102556,7.6700758,0.0044423755,99.179612,0,0,1,,,,1.3841E-7,14.18256,1.0156969,0.96554206,0
27496519.97,,4881,0,0.9998,1666.682,9.4E-6,1.0076155,0.021399789,0.97442267,0.006585,0.08105485,0.002378,1.0554775,0.006585,1.2408756,7.7011154,0.0057772881,98.93381,0,0,1,,,,1.3831E-7,15.34015,1.015289,0.96705803,0
27496593.56,,4881,0,1,1666.682,9.3E-6,1.0073547,0.021459533,0.98793463,0.006496,0.081022809,0.002378,1.0689574,0.006496,0.92364731,7.9233266,0.0055207038,98.998202,0,0,1,,,,1.3608E-7,15.40223,1.0147634,0.98072173,0
27496760.47,Error: Warning: Current field is 2222.242 Oe;
27496760.61,Error: but addenda was obtained at 0.007 Oe.
27496864.34,,4881,0,1.0001,2222.242,9.3E-6,1.0073746,0.02047093,0.99471249,0.007081,0.081026139,0.002378,1.0757386,0.007081,1.2520366,7.8015676,0.0049840272,99.076666,0,0,1,,,,1.3899E-7,14.18256,1.0148035,0.98743062,0
27496943,,4881,0,1.0008,2222.242,9.3E-6,1.0077886,0.0215495,0.99962535,0.006893,0.081102213,0.002379,1.0807276,0.006893,1.1158361,8.0852301,0.0060985266,98.904761,0,0,1,,,,1.3493E-7,15.60314,1.0156378,0.99189988,0
27497019.56,,4881,0,0.9997,2222.242,9.3E-6,1.0081362,0.021902586,0.99129587,0.006929,0.08114992,0.00238,1.0724458,0.006929,1.5649633,7.7967494,0.0047307747,99.127059,0,0,1,,,,1.3859E-7,16.17046,1.0163386,0.98329556,0
27501603.75,,4881,0,1,-0.005,9.3E-6,1.0102955,0.02121066,0.95825213,0.008639,0.081507745,0.002387,1.0397599,0.008639,1.6109132,7.6872661,0.0048580089,99.119833,0,0,1,,,,1.3628E-7,14.18256,1.020697,0.94848698,0
27501676.67,,4881,0,1.0001,-0.005,9.3E-6,1.0108421,0.021749633,0.9607253,0.008408,0.081579548,0.002389,1.0423049,0.008408,1.9553112,7.6003589,0.0055854312,98.973935,0,0,1,,,,1.3835E-7,15.37453,1.0218018,0.95042073,0
27501748.7,,4881,0,1.0001,-0.005,9.3E-6,1.0111418,0.021557301,0.95843577,0.008115,0.081615562,0.00239,1.0400513,0.008115,1.925589,7.4643071,0.0031914447,99.40628,0,0,1,,,,1.4004E-7,15.20072,1.0224077,0.94787477,0
27501912.14,Error: Warning: Current field is 555.566 Oe;
27501912.3,Error: but addenda was obtained at 0.007 Oe.
27502142.61,,4881,0,1.0003,555.566,9.3E-6,1.0088939,0.020899455,0.96085721,0.008733,0.081271214,0.002383,1.0421284,0.008733,1.8676813,7.5920787,0.0052728168,99.027452,0,0,1,,,,1.3841E-7,14.18256,1.0178668,0.95238682,0
27502214.73,,4881,0,1.0001,555.566,9.3E-6,1.0092022,0.021495215,0.95791199,0.007949,0.081304623,0.002383,1.0392166,0.007949,1.9626525,7.531281,0.0049529391,99.082143,0,0,1,,,,1.3907E-7,15.18416,1.018489,0.94917751,0
27502285.69,,4881,0,1.0002,555.566,9.4E-6,1.0091455,0.021343123,0.9650242,0.009002,0.081322055,0.002384,1.0463463,0.009002,1.9034991,7.6284003,0.0057346126,98.943373,0,0,1,,,,1.3841E-7,15.06256,1.0183747,0.95627851,0
27502451.16,Error: Warning: Current field is 1111.125 Oe;
27502451.25,Error: but addenda was obtained at 0.007 Oe.
27502586.92,,4881,0,0.9999,1111.125,9.3E-6,1.0079697,0.020851166,0.96650932,0.00897,0.081115709,0.00238,1.047625,0.00897,2.2565466,7.5577509,0.0031415054,99.415699,0,0,1,,,,1.3931E-7,14.18256,1.0160029,0.95886743,0
27502658.84,,4881,0,0.9998,1111.125,9.4E-6,1.0081284,0.02122533,0.96622763,0.008339,0.081149901,0.00238,1.0473775,0.008339,2.288723,7.5382372,0.0049571633,99.07392,0,0,1,,,,1.4005E-7,15.1155,1.0163228,0.95843708,0
27502729.75,,4881,0,0.9999,1111.125,9.3E-6,1.0083259,0.021252971,0.96940104,0.007995,0.081181552,0.002381,1.0505826,0.007995,0.7063608,7.5705732,0.003633693,99.323612,0,0,1,,,,1.3958E-7,15.07647,1.016721,0.96139658,0
27502896.34,Error: Warning: Current field is 1666.678 Oe;
27502896.48,Error: but addenda was obtained at 0.007 Oe.
27503000.55,,4881,0,0.9999,1666.678,9.2E-6,1.0072191,0.020791072,0.97326891,0.008979,0.081005288,0.002378,1.0542742,0.008979,1.9024745,7.7401222,0.0057693643,98.94121,0,0,1,,,,1.3745E-7,14.18256,1.0144902,0.96629319,0
27503073.66,,4881,0,1.0001,1666.678,9.2E-6,1.0079392,0.021380267,0.98160981,0.009016,0.081105202,0.002379,1.062715,0.009016,1.9514077,7.6793768,0.0052677972,99.020103,0,0,1,,,,1.3955E-7,15.48024,1.0159414,0.97387802,0
27503147.08,,4881,0,1,1666.678,9.2E-6,1.0079652,0.021270389,0.97920523,0.008113,0.081106902,0.002379,1.0603121,0.008113,2.4770185,7.6599763,0.0053451398,99.005185,0,0,1,,,,1.3961E-7,15.35875,1.0159939,0.9714673,0
27503314.33,Error: Warning: Current field is 2222.24 Oe;
27503314.52,Error: but addenda was obtained at 0.007 Oe.
27503422.53,,4881,0,1.0002,2222.24,9.3E-6,1.0079661,0.0211748,1.0027667,0.008383,0.081107286,0.002379,1.083874,0.008383,1.602096,7.7681988,0.0034343846,99.358465,0,0,1,,,,1.403E-7,15.19473,1.0159957,0.99484166,0
27503495.48,,4881,0,1,2222.24,9.4E-6,1.0079558,0.021323753,0.99420026,0.008595,0.081109915,0.00238,1.0753102,0.008595,1.825271,7.7736227,0.0045187814,99.161467,0,0,1,,,,1.3933E-7,15.5364,1.0159748,0.98635308,0
27503568.55,,4881,0,0.9999,2222.24,9.4E-6,1.0077914,0.021483527,0.99169814,0.008427,0.081090813,0.002379,1.072789,0.008427,1.2752588,7.8745486,0.0048961763,99.104455,0,0,1,,,,1.3729E-7,15.54725,1.0156436,0.98403112,0
27503736.89,Error: Warning: Current field is 2777.797 Oe;
27503737.03,Error: but addenda was obtained at 0.007 Oe.
27503845.69,,4881,0,1.0002,2777.797,9.3E-6,1.0080934,0.021089512,1.0151726,0.008639,0.081136844,0.00238,1.0963094,0.008639,2.3149812,7.9598178,0.0049306308,99.090183,0,0,1,,,,1.3882E-7,15.19473,1.0162524,1.0070223,0
27503920.05,,4881,0,1,2777.797,9.3E-6,1.0080613,0.021324236,1.0237323,0.008518,0.081138083,0.00238,1.1048704,0.008518,2.1771278,8.0270424,0.0047387369,99.126913,0,0,1,,,,1.3868E-7,15.91964,1.0161877,1.0155457,0
27503993.31,,4881,0,0.9998,2777.797,9.3E-6,1.0082518,0.021261505,1.020031,0.009139,0.081157566,0.00238,1.1011885,0.009139,1.1166198,7.799702,0.0042123576,99.204356,0,0,1,,,,1.4216E-7,16.05408,1.0165718,1.0116827,0
27504162.7,Error: Warning: Current field is 3333.348 Oe;
27504162.88,Error: but addenda was obtained at 0.007 Oe.
27504274.42,,4881,0,0.9996,3333.348,9.3E-6,1.0088654,0.021350595,1.0368332,0.008626,0.081233035,0.002382,1.1180662,0.008626,0.66724848,7.7609244,0.002861906,99.450508,0,0,1,,,,1.4475E-7,16.2069,1.0178094,1.027722,0
27504365.33,,4881,0,0.9995,3333.348,9.2E-6,1.0080796,0.02095976,1.031772,0.009654,0.081138962,0.00238,1.112911,0.009654,1.8919981,8.1080037,0.0052272402,99.039518,0,0,1,,,,1.3841E-7,15.52185,1.0162245,1.0235025,0
27504440.75,,4881,0,0.9999,3333.348,9.3E-6,1.0082786,0.021090586,1.0524843,0.00911,0.081146779,0.00238,1.1336311,0.00911,2.0760141,8.0546055,0.0032345249,99.393067,0,0,1,,,,1.4148E-7,16.21601,1.0166258,1.0438428,0
27504609.48,Error: Warning: Current field is 3888.917 Oe;
27504609.64,Error: but addenda was obtained at 0.007 Oe.
27504712.72,,4881,0,1.0005,3888.917,9.3E-6,1.008157,0.020412512,1.0215551,0.009519,0.081165388,0.002381,1.1027205,0.009519,2.1334087,8.160757,0.0047248593,99.145654,0,0,1,,,,1.3612E-7,14.18256,1.0163806,1.0132897,0
27504787.44,,4881,0,0.9995,3888.917,9.4E-6,1.009056,0.021163159,1.009677,0.008887,0.081238693,0.002382,1.0909157,0.008887,1.6664625,7.2814047,0.0019830127,99.603741,0,0,1,,,,1.5033E-7,16.32151,1.0181939,1.0006155,0
27504857.33,,4881,0,1,3888.917,9.4E-6,1.00879,0.020589496,1.0047682,0.01037,0.081263705,0.002383,1.0860319,0.01037,0.39904184,8.0008365,0.0040074872,99.272686,0,0,1,,,,1.3659E-7,14.56281,1.0176573,0.9960132,0
27505026.38,Error: Warning: Current field is 4444.465 Oe;
27505026.52,Error: but addenda was obtained at 0.007 Oe.
27505168.64,,4881,0,1,4444.465,9.2E-6,1.008948,0.022053642,0.96855641,0.009391,0.081293392,0.002383,1.0498498,0.009391,0.22205964,7.9813012,0.0056643093,98.999482,0,0,1,,,,1.3267E-7,15.19473,1.0179762,0.95996658,0
27505243.02,,4881,0,1.0005,4444.465,9.3E-6,1.0092287,0.021471363,0.99261858,0.008846,0.081311546,0.002383,1.0739301,0.008846,1.2768681,7.5925888,0.0050182384,99.049113,0,0,1,,,,1.4261E-7,15.9626,1.0185426,0.98354175,0
27505314,,4881,0,0.9999,4444.465,9.4E-6,1.0087732,0.020882777,0.99333427,0.008726,0.081225351,0.002382,1.0745596,0.008726,1.4895123,7.5447353,0.0044887049,99.14334,0,0,1,,,,1.4348E-7,15.18518,1.0176234,0.98469535,0
27505483.84,Error: Warning: Current field is 5000.034 Oe;
27505484.03,Error: but addenda was obtained at 0.007 Oe.
27505599.55,,4881,0,1.0003,5000.034,9.4E-6,1.0092667,0.021846845,0.96239313,0.008552,0.081329047,0.002384,1.0437222,0.008552,2.0966566,7.6772734,0.0060954083,98.886249,0,0,1,,,,1.3725E-7,15.19473,1.0186192,0.95355683,0
27505672.78,,4881,0,0.9999,5000.034,9.2E-6,1.0091821,0.021047193,0.97888619,0.009348,0.081283676,0.002383,1.0601699,0.009348,0.39838387,7.3327041,0.0036951799,99.284531,0,0,1,,,,1.4547E-7,15.35455,1.0184485,0.96997975,0
27505743.89,,4881,0,0.9998,5000.034,9.3E-6,1.0091685,0.02143895,0.94997577,0.009285,0.081324077,0.002384,1.0312998,0.009285,0.85842723,7.6454994,0.0033535953,99.393559,0,0,1,,,,1.3559E-7,14.66541,1.0184212,0.94134501,0
27505860,Error: Warning: Current field is 5000.015 Oe;
27505860.11,Error: but addenda was obtained at 10000.056 Oe.
27505960.86,CALFILE: DRPuck93_2.cal - Addenda #14 measured on 11/12/2020 from 0.30767 to 3.7097 K
27505960.98,,4881,0,0.9993,5000.015,9.2E-6,1.0086368,0.020128634,0.93802897,0.009896,0.089134225,0.002389,1.0271632,0.009896,1.1007391,7.4589926,0.0064527461,98.900222,0,0,1,,,,1.3899E-7,13.17039,1.0173481,0.9299968,0
27506032.28,,4881,0,0.9991,5000.015,9.4E-6,1.0094261,0.021562278,0.92635326,0.009561,0.089235018,0.002393,1.0155883,0.009561,0.29101482,7.3343295,0.0040805752,99.302558,0,0,1,,,,1.3928E-7,14.91799,1.018941,0.91770291,0
27506110.08,,4881,0,0.9996,5000.015,9.2E-6,1.0093062,0.020879091,0.94249664,0.008997,0.089201313,0.002391,1.031698,0.008997,0.50701589,7.1629999,0.0030295475,99.462589,0,0,1,,,,1.4468E-7,14.66866,1.018699,0.93380644,0
27506275.73,Error: Warning: Current field is 5500.041 Oe;
27506275.89,Error: but addenda was obtained at 10000.056 Oe.
27506383.64,,4881,0,0.9996,5500.041,9.4E-6,1.00963,0.021413029,0.93123985,0.008171,0.08922386,0.002392,1.0204637,0.008171,1.9563551,6.9010412,0.0041050071,99.25074,0,0,1,,,,1.488E-7,15.19473,1.0193528,0.92235754,0
27506451.3,,4881,0,1,5500.041,9.2E-6,1.0092879,0.020625402,0.91963902,0.009342,0.089220583,0.002392,1.0088596,0.009342,0.57424941,7.2191016,0.0052364078,99.094782,0,0,1,,,,1.4081E-7,13.80208,1.018662,0.91117614,0
27506520.13,,4881,0,1.0002,5500.041,9.2E-6,1.0097088,0.020933467,0.92684123,0.008949,0.089257464,0.002393,1.0160987,0.008949,2.9934166,7.1089465,0.0048931886,99.135987,0,0,1,,,,1.4397E-7,14.4382,1.0195119,0.9179292,0
27506685.95,Error: Warning: Current field is 6000.042 Oe;
27506686.11,Error: but addenda was obtained at 10000.056 Oe.
27506799.13,,4881,0,0.9991,6000.042,9.3E-6,1.0103699,0.021538079,0.89349265,0.00835,0.089343374,0.002397,0.98283602,0.00835,0.72270341,6.879718,0.0019610624,99.654289,0,0,1,,,,1.4327E-7,14.18256,1.0208473,0.88432231,0
27506873.75,,4881,0,1.0001,6000.042,9.4E-6,1.0100137,0.021210204,0.89319973,0.01061,0.089335267,0.002396,0.982535,0.01061,0.20820271,7.3636346,0.0060339057,99.002101,0,0,1,,,,1.3454E-7,13.75944,1.0201276,0.88434419,0
27506952.92,,4881,0,0.9993,6000.042,9.3E-6,1.0098834,0.022004556,0.89558069,0.008982,0.089300489,0.002395,0.98488118,0.008982,0.2486891,7.2163656,0.005121125,99.134368,0,0,1,,,,1.3746E-7,14.72727,1.0198645,0.88681593,0
27507119.8,Error: Warning: Current field is 6500.05 Oe;
27507119.92,Error: but addenda was obtained at 10000.056 Oe.
27507221.05,,4881,0,0.9993,6500.05,9.4E-6,1.0097355,0.020201707,0.89090481,0.009247,0.089248695,0.002393,0.9801535,0.009247,0.80118544,6.5916273,0.0029803761,99.45173,0,0,1,,,,1.4937E-7,13.17039,1.0195657,0.88231507,0
27507287.95,,4881,0,0.9997,6500.05,9.4E-6,1.0096494,0.02080466,0.8845534,0.00903,0.089274295,0.002394,0.97382769,0.00903,0.60752576,7.2252561,0.0062635975,98.95173,0,0,1,,,,1.3596E-7,13.18325,1.0193919,0.87609955,0
27507356.42,,4881,0,1.0001,6500.05,9.2E-6,1.0101635,0.02135492,0.89325574,0.008266,0.089315982,0.002396,0.98257172,0.008266,2.1190153,6.8875599,0.0044500398,99.214101,0,0,1,,,,1.4359E-7,14.45051,1.0204303,0.88426848,0
27507524.09,Error: Warning: Current field is 7000.051 Oe;
27507524.25,Error: but addenda was obtained at 10000.056 Oe.
27507624.72,,4881,0,0.9996,7000.051,9.3E-6,1.0101027,0.021552996,0.86316074,0.008866,0.089345483,0.002397,0.95250622,0.008866,0.46624661,7.2088866,0.0052606407,99.136683,0,0,1,,,,1.3308E-7,13.17039,1.0203075,0.85452769,0
27507694.53,,4881,0,0.9996,7000.051,9.4E-6,1.0105502,0.021975849,0.86338538,0.007472,0.089374091,0.002398,0.95275947,0.007472,1.3938733,6.8424673,0.0035266675,99.391291,0,0,1,,,,1.3994E-7,14.41777,1.0212117,0.85437158,0
27507762.64,,4881,0,1,7000.051,9.2E-6,1.0102926,0.021815116,0.86297969,0.007808,0.089382591,0.002398,0.95236228,0.007808,1.605262,7.3270422,0.0070711235,98.856769,0,0,1,,,,1.3121E-7,13.68493,1.0206912,0.85418784,0
27507929.08,Error: Warning: Current field is 7500.054 Oe;
27507929.2,Error: but addenda was obtained at 10000.056 Oe.
27508051.39,,4881,0,1.0001,7500.054,9.2E-6,1.010391,0.02157526,0.849643,0.008308,0.08937422,0.002398,0.93901722,0.008308,0.74752979,6.9452789,0.0047965994,99.193896,0,0,1,,,,1.361E-7,13.17039,1.0208899,0.84090519,0
27508119.42,,4881,0,0.9999,7500.054,9.3E-6,1.0102938,0.021756497,0.87010893,0.00819,0.089371039,0.002398,0.95947997,0.00819,1.8087185,7.1544587,0.0041333389,99.312992,0,0,1,,,,1.3487E-7,13.89056,1.0206935,0.86124348,0
27508196.48,,4881,0,0.9995,7500.054,9.3E-6,1.0102773,0.022111757,0.85602647,0.007933,0.089343096,0.002397,0.94536957,0.007933,2.7285115,6.9088182,0.0050865285,99.134839,0,0,1,,,,1.3782E-7,14.30892,1.0206602,0.84731836,0
27508364.08,Error: Warning: Current field is 8000.057 Oe;
27508364.34,Error: but addenda was obtained at 10000.056 Oe.
27508463.58,,4881,0,0.9997,8000.057,9.4E-6,1.010207,0.021241537,0.84789513,0.008556,0.089328854,0.002396,0.93722399,0.008556,0.75817379,6.6169862,0.0033619906,99.408528,0,0,1,,,,1.4233E-7,13.17039,1.0205181,0.83932813,0
27508529.47,,4881,0,1.0006,8000.057,9.2E-6,1.0100763,0.020885616,0.86778337,0.008741,0.089329349,0.002396,0.95711272,0.008741,1.934156,7.015396,0.0088163839,98.500267,0,0,1,,,,1.3814E-7,13.23397,1.0202541,0.85912657,0
27508603.53,,4881,0,1,8000.057,9.2E-6,1.0101336,0.021744138,0.85098885,0.008215,0.089334483,0.002396,0.94032334,0.008215,1.9690892,6.7318043,0.0063537373,98.894381,0,0,1,,,,1.4096E-7,14.03079,1.0203698,0.84245182,0
27508771.39,Error: Warning: Current field is 8500.052 Oe;
27508771.53,Error: but addenda was obtained at 10000.056 Oe.
27508877.38,,4881,0,1.0001,8500.052,9.3E-6,1.0107824,0.021596286,0.83592793,0.008399,0.08942272,0.0024,0.92535065,0.008399,0.72595061,6.7660788,0.0062469995,98.935161,0,0,1,,,,1.3797E-7,13.17039,1.0216811,0.82701076,0
27508943.17,,4881,0,1.0002,8500.052,9.2E-6,1.0106079,0.0212455,0.84217585,0.008059,0.089380401,0.002398,0.93155625,0.008059,2.3793274,6.4999105,0.0045205135,99.19408,0,0,1,,,,1.4427E-7,13.53216,1.0213283,0.83333592,0
27509008.2,,4881,0,0.9995,8500.052,9.2E-6,1.0104105,0.020763344,0.84397284,0.008051,0.08936845,0.002398,0.93334129,0.008051,1.3778199,6.5089342,0.0037586829,99.330186,0,0,1,,,,1.4418E-7,12.99982,1.0209293,0.83527722,0
27509175.83,Error: Warning: Current field is 9000.064 Oe;
27509175.94,Error: but addenda was obtained at 10000.056 Oe.
27509276.06,,4881,0,0.9995,9000.064,9.3E-6,1.0109441,0.021572253,0.82334132,0.008152,0.08942436,0.0024,0.91276568,0.008152,2.9689726,6.4230772,0.0020360613,99.640488,0,0,1,,,,1.4252E-7,13.17039,1.022008,0.81442811,0
27509340.95,,4881,0,0.9998,9000.064,9.2E-6,1.0103109,0.02082126,0.83246501,0.008376,0.089360248,0.002397,0.92182526,0.008376,2.3123807,6.5660296,0.0054002848,99.054819,0,0,1,,,,1.4149E-7,12.84615,1.0207281,0.82396914,0
27509407.3,,4881,0,0.9998,9000.064,9.4E-6,1.0103425,0.021220253,0.82118428,0.007922,0.089337747,0.002396,0.91052202,0.007922,1.9579838,6.4001932,0.0033314311,99.409582,0,0,1,,,,1.4295E-7,13.13206,1.020792,0.81277812,0
27509574.72,Error: Warning: Current field is 9500.072 Oe;
27509574.98,Error: but addenda was obtained at 10000.056 Oe.
27509675.14,,4881,0,1.0003,9500.072,9.3E-6,1.0105738,0.021832372,0.83234653,0.007337,0.089399839,0.002399,0.92174637,0.007337,1.4960201,6.8544767,0.0053058847,99.111164,0,0,1,,,,1.3546E-7,13.17039,1.0212595,0.82363754,0
27509742.75,,4881,0,0.9998,9500.072,9.3E-6,1.0109223,0.022271057,0.80578513,0.007219,0.089436893,0.0024,0.89522202,0.007219,0.92367238,6.4980683,0.004381762,99.246584,0,0,1,,,,1.3862E-7,13.70895,1.0219639,0.79707918,0
27509807.48,,4881,0,0.9997,9500.072,9.3E-6,1.0111569,0.020436792,0.81180289,0.009252,0.089475219,0.002402,0.90127811,0.008935,1.1604422,6.0056018,0,100,0,0,1,,,,1.5007E-7,12.99614,1.0224382,0.80284564,0
27510075.31,,4881,0,1.0006,10000.055,9.4E-6,1.0105768,0.021710205,0.8254386,0.007757,0.089389245,0.002398,0.91482785,0.007757,0.80166429,6.6084738,0.0062337426,98.922725,0,0,1,,,,1.3966E-7,13.17039,1.0212654,0.81679949,0
27510148.84,,4881,0,1.0002,10000.055,9.3E-6,1.0110249,0.021884051,0.80358406,0.007421,0.089454647,0.002401,0.89303871,0.007421,0.98673534,6.61471,0.0072646328,98.77213,0,0,1,,,,1.3637E-7,13.21695,1.0221714,0.79482122,0
27510214.3,,4881,0,0.9999,10000.055,9.2E-6,1.0111196,0.021792438,0.8030509,0.007234,0.08945593,0.002401,0.89250683,0.007234,1.360414,6.4539553,0.0046239167,99.201603,0,0,1,,,,1.3919E-7,13.22942,1.0223629,0.79421947,0
27510383.66,Error: Warning: Current field is 10500.067 Oe;
27510383.84,Error: but addenda was obtained at 10000.056 Oe.
27510479.42,,4881,0,0.9995,10500.067,9.2E-6,1.0106305,0.020972409,0.79554611,0.007788,0.089387909,0.002398,0.88493402,0.007788,1.1756207,6.2210366,0.0028562665,99.492801,0,0,1,,,,1.4283E-7,12.15822,1.021374,0.78717802,0
27510542.19,,4881,0,0.9997,10500.067,9.2E-6,1.0108038,0.021087838,0.79523585,0.007786,0.089415156,0.002399,0.884651,0.007786,0.96415325,6.2792505,0.0023366888,99.589387,0,0,1,,,,1.4135E-7,12.44207,1.0217242,0.78673615,0
27510606.88,,4881,0,1,10500.067,9.3E-6,1.0107242,0.021116668,0.79644523,0.007939,0.08940958,0.002399,0.88585481,0.007939,2.2696281,6.3149601,0.0048339593,99.151977,0,0,1,,,,1.4125E-7,12.5585,1.0215634,0.78799464,0
27510776.25,Error: Warning: Current field is 11000.069 Oe;
27510776.39,Error: but addenda was obtained at 10000.056 Oe.
27510872.25,,4881,0,1.0002,11000.069,9.3E-6,1.01044,0.02099925,0.80626117,0.007765,0.089376976,0.002398,0.89563815,0.007765,1.1705269,6.4706473,0.0057944383,98.996867,0,0,1,,,,1.3955E-7,12.15822,1.020989,0.79793075,0
27510959.38,,4881,0,1.0001,11000.069,9.2E-6,1.0111247,0.021532711,0.79315281,0.007279,0.089469547,0.002401,0.88262236,0.007279,0.77446016,6.2908566,0.0049673694,99.128469,0,0,1,,,,1.413E-7,12.94129,1.0223733,0.78442627,0
27511023.34,,4881,0,1,11000.069,9.2E-6,1.0109583,0.021539416,0.77567091,0.007303,0.089444775,0.0024,0.86511568,0.007303,1.1833071,6.2354622,0.0053993332,99.060513,0,0,1,,,,1.398E-7,12.58171,1.0220366,0.76726302,0
27511192.42,Error: Warning: Current field is 11500.076 Oe;
27511192.52,Error: but addenda was obtained at 10000.056 Oe.
27511288.2,,4881,0,1.0001,11500.076,9.4E-6,1.0110985,0.021148924,0.79640241,0.008008,0.089465101,0.002401,0.88586751,0.008008,1.6622605,6.3944933,0.0049693729,99.139462,0,0,1,,,,1.3951E-7,12.15822,1.0223202,0.78766054,0
27511351.73,,4881,0,1.0002,11500.076,9.2E-6,1.0113661,0.021491592,0.78851393,0.007797,0.089501643,0.002403,0.87801557,0.007797,1.6282867,6.2657178,0.0054528677,99.043712,0,0,1,,,,1.4122E-7,12.78899,1.0228614,0.77965231,0
27511415.84,,4881,0,1.0004,11500.076,9.3E-6,1.0110784,0.021349007,0.79167321,0.007593,0.08946299,0.002401,0.8811362,0.007593,1.9053028,6.3719961,0.0041056927,99.290562,0,0,1,,,,1.3908E-7,12.53144,1.0222795,0.78299885,0
27511585.61,Error: Warning: Current field is 12000.064 Oe;
27511585.78,Error: but addenda was obtained at 10000.056 Oe.
27511682.44,,4881,0,1.0001,12000.064,9.2E-6,1.0113112,0.021256889,0.78650597,0.008009,0.089496594,0.002402,0.87600257,0.008009,1.0202674,6.3384595,0.0073308124,98.729155,0,0,1,,,,1.3964E-7,12.15822,1.0227504,0.77770911,0
[...]
27974538.3,,4881,0,3.7001,27500.082,9.4E-6,3.7368841,0.077188561,0.99928291,0.02406,2.3551693,0.02226,3.3544522,0.02406,1.229454,4.1984643,0.046884998,94.884771,0,0,1,,,,8.0284E-7,8.385914,13.964303,0.26741073,0
27974591.75,,4881,0,3.7001,27500.082,9.4E-6,3.7322528,0.077051994,1.0157719,0.0242,2.3440209,0.02214,3.3597928,0.0242,0.88426306,4.166675,0.035671879,96.07115,0,0,1,,,,8.0939E-7,8.396929,13.929711,0.27216052,0
27975650.5,,4881,0,3.7,30000.084,9.4E-6,3.7346997,0.081591924,1.0136582,0.0237,2.3490126,0.02219,3.3626708,0.0237,0.99153639,4.1970466,0.048846539,94.711501,0,0,1,,,,8.0531E-7,9.121707,13.947982,0.27141624,0
27975703.7,,4881,0,3.6991,30000.084,9.2E-6,3.7308049,0.076305075,1.0332351,0.03455,2.3411041,0.02211,3.3743392,0.02655,1.011697,4.1371503,0,100,0,0,1,,,,8.1562E-7,8.394093,13.918905,0.27694697,0
27975755.78,,4881,0,3.6998,30000.084,9.4E-6,3.7292819,0.076812327,1.0167303,0.02381,2.3375726,0.02207,3.3543028,0.02381,0.97934259,4.2209796,0.050438843,94.591893,0,0,1,,,,7.989E-7,8.274301,13.907543,0.27263433,0
27975990.16,,4881,0,3.5371,30000.084,9.3E-6,3.5633639,0.077011094,1.0206478,0.02026,1.986833,0.01853,3.0074808,0.02026,0.97768479,4.0528325,0.041856619,95.550596,0,0,1,,,,7.4609E-7,8.441959,12.697562,0.28642816,0
27976044.95,,4881,0,3.5373,30000.084,9.2E-6,3.5645607,0.074785338,1.0285632,0.02763,1.9888032,0.01855,3.0173664,0.02048,0.87583517,3.9463395,0,100,0,0,1,,,,7.646E-7,8.105665,12.706093,0.28855258,0
27976096.92,,4881,0,3.5369,30000.084,9.2E-6,3.5663678,0.074872678,1.0152023,0.02069,1.9917948,0.01857,3.0069971,0.02069,0.79783426,4.0141992,0.030337725,96.706191,0,0,1,,,,7.5202E-7,7.892679,12.718979,0.28466002,0
27976333.7,,4881,0,3.3815,30000.084,9.2E-6,3.414518,0.074124311,1.0060888,0.01816,1.7296983,0.0164,2.7357871,0.01816,1.0539616,3.8689442,0.025492562,97.223356,0,0,1,,,,7.0986E-7,8.028398,11.658933,0.29465032,0
27976384.88,,4881,0,3.3813,30000.084,9.3E-6,3.4113261,0.072389506,1.005934,0.01853,1.7263623,0.01638,2.7322963,0.01853,0.83331603,3.8907938,0.036711058,96.059817,0,0,1,,,,7.0619E-7,7.737888,11.637146,0.29488064,0
27976436.36,,4881,0,3.3809,30000.084,9.2E-6,3.4082128,0.072933252,1.0206041,0.01844,1.7218253,0.01635,2.7424293,0.01844,0.84827107,3.8986127,0.0337574,96.390475,0,0,1,,,,7.0712E-7,7.781588,11.615915,0.29945433,0
27976667.98,,4881,0,3.2325,30000.084,9.3E-6,3.2605359,0.069465806,1.0199677,0.0176,1.5316274,0.01555,2.5515951,0.0176,0.92535347,3.7768974,0.033228667,96.422175,0,0,1,,,,6.7962E-7,7.797225,10.631095,0.31282209,0
27976718.66,,4881,0,3.232,30000.084,9.3E-6,3.2571786,0.068553072,1.0281113,0.01745,1.5269285,0.01553,2.5550398,0.01745,0.8920505,3.6813807,0.012348412,98.618125,0,0,1,,,,6.9562E-7,7.553795,10.609212,0.31564475,0
27976768.97,,4881,0,3.2313,30000.084,9.3E-6,3.254942,0.067862239,1.0437353,0.01782,1.52455,0.01551,2.5682853,0.01782,0.83053474,3.7685877,0.021635433,97.657386,0,0,1,,,,6.8421E-7,7.362761,10.594647,0.32066171,0
27976997.84,,4881,0,3.0894,30000.084,9.3E-6,3.1187033,0.066067619,1.0095569,0.01584,1.3539332,0.01402,2.3634901,0.01584,0.97189427,3.6008825,0.019949489,97.76782,0,0,1,,,,6.5911E-7,7.537175,9.7263103,0.32371047,0
27977047.89,,4881,0,3.0889,30000.084,9.4E-6,3.1134319,0.06465452,1.0132902,0.01586,1.3470762,0.01394,2.3603664,0.01586,1.0913964,3.6179697,0.017320116,98.069748,0,0,1,,,,6.5478E-7,7.201765,9.693458,0.32545764,0
27977097.52,,4881,0,3.0888,30000.084,9.3E-6,3.1110831,0.064788588,1.0196959,0.01592,1.3442513,0.0139,2.3639473,0.01592,0.87951154,3.6368189,0.021182053,97.660222,0,0,1,,,,6.5292E-7,7.235939,9.6788381,0.32776236,0
27977325.97,,4881,0,2.9532,30000.084,9.3E-6,2.9770307,0.062611033,1.0031896,0.01374,1.1778172,0.01171,2.1810068,0.01374,1.2293426,3.4863545,0.012268633,98.594742,0,0,1,,,,6.2748E-7,7.273638,8.8627115,0.33697656,0
27977374.83,,4881,0,2.9532,30000.084,9.3E-6,2.9735554,0.06105226,1.0220537,0.01361,1.1736016,0.01165,2.1956553,0.01361,0.88101499,3.5024902,0.017244464,98.043002,0,0,1,,,,6.2961E-7,6.972709,8.8420317,0.34371436,0
27977423.5,,4881,0,2.9532,30000.084,9.3E-6,2.9814765,0.061688633,1.008486,0.01381,1.183029,0.01178,2.191515,0.01381,1.2866183,3.4953973,0.010606576,98.78699,0,0,1,,,,6.2861E-7,7.00498,8.8892023,0.33825052,0
27977650.2,,4881,0,2.8232,30000.084,9.2E-6,2.8530063,0.059435404,0.99194206,0.01194,1.0305244,0.009705,2.0224664,0.01194,1.040385,3.4080546,0.016696389,98.059255,0,0,1,,,,5.9628E-7,6.990795,8.1396449,0.3476831,0
27977699.14,,4881,0,2.8228,30000.084,9.3E-6,2.8459406,0.058851363,1.011652,0.01193,1.0222073,0.009586,2.0338592,0.01193,1.1364658,3.417497,0.010159827,98.817884,0,0,1,,,,5.969E-7,6.816109,8.099378,0.35547192,0
27977749.59,,4881,0,2.8232,30000.084,9.2E-6,2.8416589,0.058410338,1.0219206,0.01188,1.0172072,0.009515,2.0391278,0.01188,0.8710659,3.387279,0.010732339,98.740529,0,0,1,,,,6.0393E-7,6.834994,8.0750255,0.35962113,0
27977978.41,,4881,0,2.6982,30000.084,9.3E-6,2.7196547,0.055196195,1.0044599,0.01592,0.88806664,0.007517,1.8925266,0.01403,0.86420617,3.2831001,0,100,0,0,1,,,,5.7644E-7,6.774558,7.3965214,0.36933363,0
27978024.95,,4881,0,2.6981,30000.084,9.3E-6,2.7268782,0.055583329,0.98952416,0.0107,0.8949369,0.007644,1.8844611,0.0107,0.68232344,3.3788625,0.012126847,98.569929,0,0,1,,,,5.5996E-7,6.5662,7.4358646,0.36287802,0
27978073.36,,4881,0,2.6979,30000.084,9.3E-6,2.7265582,0.056693608,0.97751631,0.01016,0.89482098,0.007642,1.8723373,0.01016,1.0770102,3.3667912,0.017190596,97.972329,0,0,1,,,,5.5927E-7,6.757725,7.4341197,0.35851657,0
27978283.94,,4881,0,2.5792,30000.084,9.3E-6,2.6042237,0.053803825,0.97602548,0.00884,0.7819971,0.005505,1.7580226,0.00884,0.80446152,3.3057355,0.012291969,98.50287,0,0,1,,,,5.3431E-7,6.733582,6.7819811,0.37478558,0
27978331.02,,4881,0,2.5787,30000.084,9.3E-6,2.6033328,0.05364843,0.98009523,0.008967,0.78116492,0.005492,1.7612601,0.008967,0.87835266,3.3297567,0.0087793701,98.936012,0,0,1,,,,5.3071E-7,6.611471,6.7773418,0.37647711,0
27978378.7,,4881,0,2.5787,30000.084,9.2E-6,2.6008777,0.05355184,0.98454886,0.008695,0.77898537,0.005459,1.7635342,0.008695,0.9982429,3.3181556,0.0089661902,98.908718,0,0,1,,,,5.3331E-7,6.659513,6.7645647,0.37854485,0
27978604.13,,4881,0,2.4652,30000.084,9.3E-6,2.4892948,0.051395854,0.96313026,0.0083,0.6802902,0.005017,1.6434205,0.0083,0.77105965,3.270976,0.0098054819,98.769018,0,0,1,,,,5.0458E-7,6.636311,6.1965887,0.38690887,0
27978650.69,,4881,0,2.4648,30000.084,9.3E-6,2.4894664,0.051234456,0.95500744,0.008138,0.68044157,0.005016,1.635449,0.008138,0.89162987,3.2757905,0.010359169,98.70368,0,0,1,,,,5.015E-7,6.541952,6.1974429,0.38361933,0
27978697.66,,4881,0,2.4656,30000.084,9.3E-6,2.4846437,0.051201729,0.96382383,0.008351,0.67624124,0.005037,1.6400651,0.008351,0.83514146,3.289295,0.010941192,98.633,0,0,1,,,,5.01E-7,6.551581,6.1734541,0.3879123,0
27978907.42,,4881,0,2.3568,30000.084,9.3E-6,2.3784693,0.049504508,0.9437478,0.008241,0.58909348,0.005421,1.5328413,0.008241,0.89988729,3.2451013,0.0062353509,99.189517,0,0,1,,,,4.7382E-7,6.57859,5.6571164,0.39678788,0
27978954.97,,4881,0,2.3572,30000.084,9.2E-6,2.3820607,0.04897054,0.93908944,0.008382,0.59173516,0.005425,1.5308246,0.008382,0.89540716,3.2451392,0.0079329455,98.971684,0,0,1,,,,4.7358E-7,6.490203,5.6742132,0.39423405,0
27979003.02,,4881,0,2.3571,30000.084,9.2E-6,2.3769572,0.049360788,0.94449527,0.008141,0.58808378,0.005419,1.532579,0.008141,0.8245057,3.2796918,0.010905298,98.598562,0,0,1,,,,4.6982E-7,6.490278,5.6499254,0.39735477,0
27979214.56,,4881,0,2.2532,30000.084,9.3E-6,2.2737164,0.046758595,0.93350859,0.007547,0.51996214,0.004711,1.4534707,0.007547,0.74716125,3.2501493,0.010010875,98.662475,0,0,1,,,,4.4971E-7,6.559384,5.1697861,0.4105651,0
27979262.27,,4881,0,2.2527,30000.084,9.3E-6,2.2719357,0.04674315,0.93455879,0.007213,0.51882538,0.004698,1.4533842,0.007213,0.9243788,3.2229517,0.006913417,99.066995,0,0,1,,,,4.5271E-7,6.500299,5.1616918,0.41134914,0
27979310.22,,4881,0,2.2528,30000.084,9.4E-6,2.2716569,0.04664026,0.92864325,0.007384,0.51864154,0.004696,1.4472848,0.007384,0.96058173,3.2116231,0.0069164669,99.064922,0,0,1,,,,4.5239E-7,6.445903,5.1604251,0.40879556,0
27979517.8,,4881,0,2.153,30000.084,9.3E-6,2.1722793,0.043995231,0.92756437,0.01229,0.46045482,0.004939,1.3880192,0.01229,0.91582499,3.2919276,0.010434891,98.57219,0,0,1,,,,4.2438E-7,6.423246,4.7187974,0.42700051,0
27979566.33,,4881,0,2.1528,30000.084,9.4E-6,2.1731745,0.045110063,0.92073365,0.01162,0.46097675,0.004926,1.3817104,0.01162,0.68853726,3.2775124,0.0069247794,99.050628,0,0,1,,,,4.2337E-7,6.583855,4.7226872,0.42368142,0
27979613.45,,4881,0,2.1531,30000.084,9.4E-6,2.1730276,0.044882032,0.92207999,0.01183,0.46094506,0.004927,1.3830251,0.01183,0.8251938,3.3105782,0.010353457,98.594663,0,0,1,,,,4.2041E-7,6.555025,4.7220491,0.42432962,0
27979823.97,,4881,0,2.0582,30000.084,9.4E-6,2.0778461,0.043037236,0.90565065,0.01188,0.40935739,0.006473,1.315008,0.01188,0.91864122,3.3012081,0.0068742904,99.029156,0,0,1,,,,4.002E-7,6.621156,4.3174443,0.43586032,0
27979871.2,,4881,0,2.0579,30000.084,9.2E-6,2.0778818,0.043206018,0.89850776,0.01188,0.40942169,0.006472,1.3079295,0.01188,0.72996366,3.3050068,0.010001715,98.593719,0,0,1,,,,3.9841E-7,6.602416,4.3175926,0.43241525,0
27979919.66,,4881,0,2.0585,30000.084,9.3E-6,2.0781561,0.04328843,0.89700034,0.01212,0.40952613,0.00647,1.3065265,0.01212,0.9003654,3.2900044,0.0070166027,99.009477,0,0,1,,,,3.99E-7,6.610014,4.3187327,0.4316328,0
27980127.91,,4881,0,1.9668,30000.084,9.3E-6,1.9866277,0.041308194,0.88119558,0.01134,0.36437546,0.00608,1.245571,0.01134,0.87705452,3.2851492,0.0030520703,99.551088,0,0,1,,,,3.8001E-7,6.580009,3.9466897,0.44356352,0
27980175.48,,4881,0,1.9669,30000.084,9.2E-6,1.9866981,0.041324336,0.88180881,0.01111,0.36449745,0.006084,1.2463063,0.01111,0.83448944,3.338649,0.0087610215,98.731753,0,0,1,,,,3.757E-7,6.570298,3.9469695,0.44385646,0
27980222.33,,4881,0,1.967,30000.084,9.2E-6,1.9875389,0.041661041,0.88238969,0.0112,0.36484784,0.006094,1.2472375,0.0112,1.0730173,3.2952971,0.0052654387,99.227886,0,0,1,,,,3.7997E-7,6.677298,3.9503108,0.44396097,0
27980431.73,,4881,0,1.8812,30000.084,9.2E-6,1.9005795,0.039750944,0.85458601,0.01025,0.32452127,0.004975,1.1791073,0.01025,0.63091632,3.3893235,0.0096775496,98.567421,0,0,1,,,,3.5055E-7,6.590594,3.6122024,0.44964497,0
27980480.16,,4881,0,1.8811,30000.084,9.2E-6,1.9009622,0.040328888,0.85948859,0.009859,0.32468617,0.004978,1.1841748,0.009859,1.0328344,3.3513272,0.0069500624,98.957285,0,0,1,,,,3.5531E-7,6.778647,3.6136572,0.45213345,0
27980527.34,,4881,0,1.8809,30000.084,9.4E-6,1.9007174,0.040048998,0.8582546,0.01017,0.3245389,0.004976,1.1827935,0.01017,0.94372181,3.3310817,0.0063956172,99.035118,0,0,1,,,,3.569E-7,6.702654,3.6127267,0.45154245,0
27980735.3,,4881,0,1.7981,30000.084,9.2E-6,1.8169071,0.038087758,0.83662901,0.009577,0.28401477,0.004395,1.1206438,0.009577,0.80075311,3.3923368,0.0062059274,99.032007,0,0,1,,,,3.3215E-7,6.662163,3.3011514,0.46046879,0
27980783.8,,4881,0,1.798,30000.084,9.4E-6,1.8172612,0.038613173,0.838434,0.009273,0.28419547,0.004397,1.1226295,0.009273,0.75245243,3.3907033,0.0052767769,99.176062,0,0,1,,,,3.3263E-7,6.784674,3.3024384,0.46137231,0
27980832.36,,4881,0,1.7982,30000.084,9.2E-6,1.8170371,0.038685477,0.83588337,0.009638,0.28413909,0.004396,1.1200225,0.009638,0.64421502,3.4221164,0.0080666567,98.753111,0,0,1,,,,3.296E-7,6.781407,3.3016238,0.46002548,0
27981041.22,,4881,0,1.7179,30000.084,9.3E-6,1.7362663,0.036682172,0.81222394,0.008613,0.25179686,0.004137,1.0640208,0.008613,1.1222921,3.3938639,0.0054490513,99.109859,0,0,1,,,,3.1516E-7,6.844233,3.0146206,0.46779918,0
27981089.69,,4881,0,1.7179,30000.084,9.3E-6,1.7364768,0.036416878,0.82290652,0.008482,0.25205341,0.004137,1.0749599,0.008482,0.98026422,3.4444397,0.0055745019,99.096927,0,0,1,,,,3.1375E-7,6.787728,3.0153516,0.47389434,0
27981139.63,,4881,0,1.7178,30000.084,9.3E-6,1.7362476,0.037105537,0.81707319,0.008324,0.25184487,0.004137,1.0689181,0.008324,0.7689105,3.4823225,0.0073252515,98.829591,0,0,1,,,,3.0908E-7,6.888879,3.0145558,0.47059716,0
27981352.42,,4881,0,1.6432,30000.084,9.3E-6,1.6607777,0.035011797,0.79936122,0.008546,0.22909682,0.004143,1.028458,0.008546,0.68427565,3.5153597,0.0054687992,99.099742,0,0,1,,,,2.9417E-7,6.964645,2.7581826,0.48131741,0
27981401.19,,4881,0,1.6429,30000.084,9.2E-6,1.6609635,0.035134861,0.80106606,0.008336,0.22914568,0.004143,1.0302117,0.008336,0.86895652,3.4819702,0.0052347732,99.129126,0,0,1,,,,2.9744E-7,7.030719,2.7587997,0.48228999,0
27981450.55,,4881,0,1.6429,30000.084,9.4E-6,1.6607968,0.035073088,0.79727986,0.008612,0.22910414,0.004143,1.026384,0.008612,0.87018988,3.4979828,0.0063576671,98.949427,0,0,1,,,,2.953E-7,6.96394,2.7582459,0.48005865,0
27981661.25,,4881,0,1.57,30000.084,9.2E-6,1.5872467,0.033185592,0.77709295,0.00804,0.20563328,0.003974,0.98272623,0.00804,0.85644693,3.568976,0.0044406984,99.246574,0,0,1,,,,2.7666E-7,6.995966,2.5193519,0.4895855,0
27981710.09,,4881,0,1.5698,30000.084,9.3E-6,1.5874019,0.033557039,0.77913706,0.007917,0.20570224,0.003974,0.9848393,0.007917,0.73356736,3.5684354,0.0057303083,99.025758,0,0,1,,,,2.7769E-7,7.137952,2.5198447,0.49082534,0
27981759.41,,4881,0,1.57,30000.084,9.3E-6,1.5873318,0.033747502,0.77612714,0.00783,0.20567987,0.003974,0.981807,0.00783,0.96603517,3.5741985,0.0044008895,99.255077,0,0,1,,,,2.7598E-7,7.136871,2.5196223,0.48895078,0
27981971.84,,4881,0,1.5009,30000.084,9.4E-6,1.5172521,0.032077196,0.74521479,0.007266,0.18399997,0.003605,0.92921476,0.007266,0.88794305,3.6684069,0.0059600138,98.973863,0,0,1,,,,2.5499E-7,7.148397,2.3020538,0.49116084,0
27982021.64,,4881,0,1.5006,30000.084,9.3E-6,1.517511,0.032581864,0.74414541,0.007491,0.18407312,0.003607,0.92821853,0.007491,0.67589162,3.6169924,0.004946956,99.137557,0,0,1,,,,2.5806E-7,7.336814,2.3028397,0.49037233,0
27982071.63,,4881,0,1.5008,30000.084,9.3E-6,1.5173152,0.032400524,0.75079245,0.007797,0.18405488,0.003607,0.93484733,0.007797,1.0905074,3.7399441,0.0076755614,98.697003,0,0,1,,,,2.521E-7,7.233985,2.3022455,0.49481639,0
27982284.58,,4881,0,1.4349,30000.084,9.2E-6,1.4508743,0.031026517,0.72145724,0.006598,0.16518495,0.002758,0.88664219,0.006598,0.91262854,3.7191731,0.0052709931,99.062212,0,0,1,,,,2.3989E-7,7.479888,2.1050363,0.49725688,0
27982334.89,,4881,0,1.4349,30000.084,9.3E-6,1.4507887,0.031067201,0.72001078,0.006721,0.1651646,0.002757,0.88517537,0.006721,0.9299225,3.7153588,0.0058356524,98.961571,0,0,1,,,,2.399E-7,7.438346,2.1047878,0.49628921,0
27982384.59,,4881,0,1.435,30000.084,9.4E-6,1.4505284,0.030896236,0.72139585,0.006542,0.16506542,0.002754,0.88646127,0.006542,0.74625007,3.6570358,0.0036458024,99.340683,0,0,1,,,,2.4347E-7,7.430718,2.1040326,0.49733315,0
27982598.97,,4881,0,1.3709,30000.084,9.3E-6,1.3858228,0.028859805,0.69750686,0.006505,0.14782886,0.003266,0.84533572,0.006505,0.88892752,3.7767417,0.0045280517,99.166565,0,0,1,,,,2.2511E-7,7.314072,1.9205048,0.50331605,0
27982649.89,,4881,0,1.3709,30000.084,9.3E-6,1.3861889,0.029492432,0.69941917,0.006437,0.14794227,0.003255,0.84736144,0.006437,0.9069597,3.7828757,0.0044211768,99.186567,0,0,1,,,,2.2525E-7,7.553483,1.9215198,0.50456266,0
27982701.55,,4881,0,1.3709,30000.084,9.4E-6,1.3862099,0.029487918,0.69675543,0.006193,0.14794324,0.003255,0.84469867,0.006193,1.0592716,3.7521418,0.0047757821,99.116109,0,0,1,,,,2.2649E-7,7.565751,1.9215778,0.50263343,0
27982915.91,,4881,0,1.3111,30000.084,9.3E-6,1.3238635,0.027845762,0.66863909,0.01091,0.1326138,0.004683,0.80125289,0.01091,0.81753529,3.916743,0.0065089345,98.79095,0,0,1,,,,2.0632E-7,7.504284,1.7526147,0.50506647,0
27982966.72,,4881,0,1.3108,30000.084,9.4E-6,1.3241874,0.028653152,0.66161607,0.01014,0.13269273,0.00468,0.7943088,0.01014,1.0156166,3.8320759,0.0063639853,98.80084,0,0,1,,,,2.0903E-7,7.833486,1.7534723,0.4996393,0
27983017.64,,4881,0,1.311,30000.084,9.3E-6,1.3242746,0.028288257,0.66298669,0.01097,0.13270115,0.004679,0.79568784,0.01097,0.85192105,3.8390664,0.0054698002,98.970523,0,0,1,,,,2.0876E-7,7.664152,1.7537031,0.50064142,0
27983232.92,,4881,0,1.253,30000.084,9.2E-6,1.2650654,0.026569119,0.63814003,0.009943,0.12089919,0.004363,0.75903923,0.009943,0.64335071,3.9487303,0.0069432967,98.67957,0,0,1,,,,1.9404E-7,7.678133,1.6003904,0.50443245,0
27983285.77,,4881,0,1.2532,30000.084,9.3E-6,1.2654884,0.027334525,0.63590914,0.00946,0.12093001,0.004366,0.75683915,0.00946,0.86614277,3.9760884,0.0074578801,98.594587,0,0,1,,,,1.9227E-7,7.897461,1.6014609,0.50250097,0
27983337.97,,4881,0,1.253,30000.084,9.3E-6,1.2655955,0.027104022,0.64155897,0.009646,0.12092827,0.004366,0.76248724,0.009646,1.0292987,3.8985278,0.0044554126,99.140472,0,0,1,,,,1.9679E-7,7.952177,1.601732,0.5069226,0
27983556.64,,4881,0,1.1981,30000.084,9.2E-6,1.2100104,0.025143138,0.61888856,0.00934,0.11050326,0.003684,0.72939181,0.00934,0.79979037,3.9249996,0.0010804689,99.785653,0,0,1,,,,1.8612E-7,7.797056,1.4641252,0.51147374,0
27983608.44,,4881,0,1.1979,30000.084,9.2E-6,1.2100969,0.025402392,0.61467182,0.008988,0.11047026,0.003682,0.72514208,0.008988,0.79101623,3.9315402,0.0039504316,99.219204,0,0,1,,,,1.8549E-7,7.849999,1.4643345,0.50795256,0
27983658.92,,4881,0,1.1982,30000.084,9.2E-6,1.209992,0.025601464,0.61377171,0.008716,0.11045457,0.003682,0.72422627,0.008716,0.76725743,3.9591719,0.0032142518,99.370149,0,0,1,,,,1.8376E-7,7.86308,1.4640807,0.50725268,0
27983879.16,,4881,0,1.145,30000.084,9.3E-6,1.1567435,0.024253259,0.58280209,0.00785,0.099483276,0.003175,0.68228537,0.00785,0.84795756,3.949101,0.0025193825,99.486562,0,0,1,,,,1.7342E-7,7.918344,1.3380556,0.50383001,0
27983930.02,,4881,0,1.1454,30000.084,9.4E-6,1.1563553,0.024327429,0.58780548,0.008319,0.099420448,0.003172,0.68722592,0.008319,0.6601882,4.0486362,0.0041044307,99.177556,0,0,1,,,,1.7077E-7,7.898202,1.3371575,0.50832602,0
27983982.33,,4881,0,1.145,30000.084,9.3E-6,1.1569463,0.02464692,0.58364439,0.007943,0.099541358,0.003178,0.68318574,0.007943,0.99815031,3.9746488,0.0042047263,99.146728,0,0,1,,,,1.7297E-7,8.097272,1.3385248,0.50446971,0
27984206.16,,4881,0,1.0943,30000.084,9.4E-6,1.1049203,0.02337415,0.5546564,0.00723,0.088859935,0.002713,0.64351634,0.00723,1.0265853,4.1690158,0.0064013903,98.701582,0,0,1,,,,1.5587E-7,7.949298,1.2208489,0.5019877,0
27984258.22,,4881,0,1.0943,30000.084,9.3E-6,1.1059389,0.023830561,0.55341433,0.00702,0.089042801,0.002721,0.64245713,0.00702,1.1695088,3.9721717,0.0036094564,99.236033,0,0,1,,,,1.6266E-7,8.338032,1.2231008,0.50040228,0
27984310.14,,4881,0,1.094,30000.084,9.2E-6,1.1051526,0.023354969,0.55616469,0.006983,0.088882278,0.002714,0.64504696,0.006983,0.76608742,4.0451502,0.0026371779,99.449775,0,0,1,,,,1.6012E-7,7.944343,1.2213623,0.50324695,0
27984538.27,,4881,0,1.0463,30000.084,9.4E-6,1.0569429,0.02239882,0.5260115,0.006565,0.079786552,0.002345,0.60579805,0.006565,0.90700267,4.1494811,0.0054691894,98.840546,0,0,1,,,,1.4729E-7,8.0903,1.1171283,0.49767258,0
27984591.53,,4881,0,1.0457,30000.084,9.3E-6,1.0570653,0.022717949,0.52330912,0.006616,0.079794721,0.002346,0.60310384,0.006616,1.2736445,4.0033778,0.0032243048,99.295922,0,0,1,,,,1.5145E-7,8.298962,1.1173871,0.49505844,0
27984644.92,,4881,0,1.0461,30000.084,9.3E-6,1.0565043,0.022482211,0.52608929,0.006822,0.079722284,0.002343,0.60581157,0.006822,0.81963083,4.2323765,0.0070037556,98.540983,0,0,1,,,,1.4474E-7,8.006756,1.1162014,0.4979528,0
27984901.5,,4881,0,1.0002,30000.084,9.2E-6,1.0105562,0.022044757,0.4958526,0.005792,0.07197309,0.00206,0.56782569,0.005792,1.0312398,4.1946793,0.004679477,98.986685,0,0,1,,,,1.3643E-7,8.464753,1.0212238,0.49067297,0
27984954.52,,4881,0,1.0002,30000.084,9.3E-6,1.0104974,0.022175091,0.49175218,0.005964,0.071970695,0.00206,0.56372288,0.005964,0.8968751,4.22224,0.0059251779,98.731454,0,0,1,,,,1.3482E-7,8.389359,1.021105,0.48664369,0
27985009.08,,4881,0,0.9999,30000.084,9.3E-6,1.0109107,0.021955436,0.49350842,0.005865,0.072015884,0.002062,0.56552431,0.005865,1.801884,4.0679422,0.0034891994,99.22499,0,0,1,,,,1.3985E-7,8.44448,1.0219405,0.488182,0