File: Data/HeatCapacity/0p19mg_drhc_EuPd2S4_09152020_0T1T3T5T.dat
[Header]
TITLE,0p19mg_drhc_EuPd2S4_09152020_0T1T3T5T.dat
BYAPP,HeatCapacity,3.8.14,1.7
INFO,0.20,MASS:Sample Mass (mg)
INFO,0,MASSERR:Sample Mass Error (mg)
INFO,0,MOLWGHT:Formula Weight (g/mole)
INFO,0,ATOMS:Atoms per Formula Unit
INFO,PPMS Heat Capacity Option 3.8.14 Build 19,APPNAME
DATATYPE,TIME,1
DATATYPE,COMMENT,2
STARTUPAXIS, X, 8, LINEAR, AUTO
STARTUPAXIS, Y1, 10, LINEAR, AUTO
[Data]
Time Stamp (Seconds),Comment (),System Status (Code),Puck Temp (Kelvin),System Temp (Kelvin),Field (Oersted),Pressure (Torr),Sample Temp (Kelvin),Temp Rise (Kelvin),Samp HC (µJ/K),Samp HC Err (µJ/K),Addenda HC (µJ/K),Addenda HC Err (µJ/K),Total HC (µJ/K),Total HC Err (µJ/K),Fit Deviation (ChiSquare),Time Const tau1 (seconds),Time Const tau2 (seconds),Sample Coupling (Percent),Debye Temp (Kelvin),Debye Temp Err (Kelvin),Cal Correction (Factor),Therm Resist (Ohms),Htr Resist (Ohms),Puck Resist (Ohms),Wire Cond (W/K),Meas Time (seconds),Temp Squared (K^2),Samp HC/Temp (µJ/K/K),Addenda Offset HC (µJ/K)
22363191.3,Error: Error at T = 0.12 K while attempting to measure time window: The requested temperature rise delT = 0.00240344432935772 will produce a resistance change of only delRtrip = -77.4144611098654.  However; I measure the noise to be SigmaThRes = 10.9562841130078
22363191.44,Error: Using default time-constant of 1.0199 seconds
22363250.56,Error: Warning:  Measured time constant less than time constant calculated from addenda table.  Changing time constant to addenda table value
22363250.67,CALFILE: DRPuck93_2.cal - Addenda #1 measured on 9/14/2020 from 0.1007 to 3.8314 K
22363250.83,,4881,0,0.12,-0.044,9.3E-6,0.12039395,0.00019833543,0.04648745,0.0003789,0.0051952341,0.0003789,0.051682684,0,0.93759486,0.97993162,0,100,0,0,1,,,,5.2741E-8,2.03984,0.014494703,0.38612779,0
22363497.97,Error: Error at T = 0.12 K while attempting to measure time window: The requested temperature rise delT = 0.00240617281918198 will produce a resistance change of only delRtrip = -77.4182792167649.  However; I measure the noise to be SigmaThRes = 9.17405046466057
22363498.22,Error: Using default time-constant of 1.0199 seconds
22363846.08,,4881,0,0.1201,-0.044,9.4E-6,0.12180618,0.0030606159,0.05266238,0.001245,0.0052199516,0.000396,0.057882331,0.00118,1.2734149,17.565947,0,100,0,0,1,,,,3.2951E-9,66.15759,0.014836746,0.43234571,0
22364062.31,,4881,0,0.1201,-0.044,9.3E-6,0.12192532,0.0031390974,0.05218558,0.001048,0.0052217673,0.000397,0.057407347,0.00097,1.0608413,17.481542,0,100,0,0,1,,,,3.2839E-9,70.26379,0.014865784,0.42801266,0
22364264.52,,4881,0,0.1201,-0.044,9.3E-6,0.1220545,0.0030490691,0.053671694,0.001341,0.0052239059,0.0003981,0.0588956,0.00128,1.1923209,17.481064,0,100,0,0,1,,,,3.3691E-9,69.92617,0.014897301,0.43973548,0
22364704.56,,4881,0,0.2901,-0.044,9.4E-6,0.29373963,0.0067202589,0.01874355,0.0009959,0.010675195,0.0006034,0.029418745,0.0007923,1.118929,1.8638485,0,100,0,0,1,,,,1.5784E-8,7.603456,0.086282972,0.063810082,0
22364747.75,,4881,0,0.2902,-0.044,9.4E-6,0.29382668,0.0067028529,0.018300721,0.00105,0.010678533,0.0006034,0.028979253,0.0008588,1.3160722,1.8371191,0,100,0,0,1,,,,1.5774E-8,7.455394,0.08633412,0.062284066,0
22364790.52,,4881,0,0.29,-0.044,9.3E-6,0.29397167,0.0068935875,0.018537702,0.0007332,0.01068431,0.0006034,0.029222011,0.0007332,1.6093379,1.9625044,0.020308041,95.573885,0,0,1,,,,1.5171E-8,7.348476,0.08641934,0.063059485,0
22365075.28,,4881,0,0.4601,-0.044,9.3E-6,0.46503918,0.0098984591,0.088556296,0.001753,0.020083307,0.000609,0.1086396,0.001644,1.3220987,2.8831165,0,100,0,0,1,,,,3.7681E-8,11.47333,0.21626144,0.1904276,0
22365128.28,,4881,0,0.46,-0.044,9.3E-6,0.46509214,0.0099847937,0.087749293,0.001596,0.020087555,0.0006088,0.10783685,0.001476,1.108872,2.8906302,0,100,0,0,1,,,,3.7306E-8,11.53247,0.2163107,0.18867077,0
22365180.78,,4881,0,0.4601,-0.044,9.4E-6,0.46531983,0.010267506,0.08806328,0.001303,0.020096203,0.0006084,0.10815948,0.001303,0.91275035,2.9438052,0.0062304872,98.594363,0,0,1,,,,3.7089E-8,11.56252,0.21652254,0.18925323,0
22365488.36,,4881,0,0.6302,-0.044,9.2E-6,0.63731275,0.013885924,0.28762825,0.001853,0.034035691,0.0006784,0.32166394,0.001853,1.1914344,5.0597857,0.0031305956,99.343472,0,0,1,,,,6.3909E-8,20.21182,0.40616754,0.45131414,0
22365558.98,,4881,0,0.6301,-0.044,9.3E-6,0.6371725,0.013872642,0.2862277,0.001974,0.034021198,0.0006777,0.3202489,0.001974,1.3347587,5.0286335,0.0032213625,99.322555,0,0,1,,,,6.4032E-8,20.23914,0.4059888,0.4492154,0
22365628.97,,4881,0,0.6302,-0.044,9.2E-6,0.63689988,0.013819159,0.28679235,0.001962,0.033993858,0.0006765,0.32078621,0.001962,1.6191215,5.0154205,0.0027453236,99.420217,0,0,1,,,,6.4258E-8,20.11453,0.40564146,0.45029424,0
22365883.53,,4881,0,0.7999,-0.044,9.2E-6,0.80842111,0.015704778,0.57470657,0.002572,0.053185092,0.0006592,0.62789166,0.002572,1.1119214,6.6052787,0.0033930301,99.334429,0,0,1,,,,9.5593E-8,20.06168,0.65354468,0.7109,0
22365965.75,,4881,0,0.8001,-0.044,9.4E-6,0.80960746,0.017459819,0.57941741,0.002138,0.05329828,0.0006612,0.63271569,0.002138,1.1775364,6.6117068,0.002070461,99.592931,0,0,1,,,,9.6024E-8,26.42111,0.65546424,0.71567697,0
22366046.83,,4881,0,0.8002,-0.044,9.3E-6,0.80940165,0.01736984,0.57981719,0.00212,0.053269353,0.0006607,0.63308654,0.00212,1.0864591,6.5708158,0.0022172328,99.560815,0,0,1,,,,9.6705E-8,26.44683,0.65513103,0.71635286,0
22366319.03,,4881,0,0.9702,-0.044,9.2E-6,0.97999783,0.01996644,0.90427741,0.003628,0.079876206,0.0009775,0.98415362,0.003628,1.2439793,7.5515314,0.0038254716,99.317489,0,0,1,,,,1.3108E-7,26.28326,0.96039574,0.9227341,0
22366409.44,,4881,0,0.9703,-0.044,9.4E-6,0.98055706,0.021035881,0.90626823,0.003235,0.079936637,0.0009783,0.98620487,0.003235,1.2994781,7.5340332,0.0026430149,99.527477,0,0,1,,,,1.3142E-7,30.20613,0.96149214,0.92423814,0
22366499.06,,4881,0,0.9702,-0.044,9.4E-6,0.98044907,0.020932586,0.90467689,0.003489,0.079912216,0.000978,0.98458911,0.003489,1.0314405,7.4631974,0.0014066347,99.746826,0,0,1,,,,1.3221E-7,30.13613,0.96128037,0.92271687,0
22372281.19,,4881,0,1.1405,-0.044,9.2E-6,1.1523282,0.024094098,1.2228979,0.005947,0.11313424,0.001482,1.3360322,0.005947,0.98330183,8.0053228,0.0029325632,99.525851,0,0,1,,,,1.6756E-7,29.85279,1.3278604,1.061241,0
22372374.44,,4881,0,1.141,-0.044,9.2E-6,1.1525134,0.024680242,1.2177461,0.00517,0.11314301,0.001482,1.3308891,0.00517,1.0876844,7.9213634,0.0032228462,99.475092,0,0,1,,,,1.6876E-7,32.02129,1.3282871,1.0566004,0
22372465.47,,4881,0,1.1411,-0.044,9.3E-6,1.1528629,0.02441444,1.2378745,0.005947,0.11322309,0.001484,1.3510976,0.005947,0.67890318,7.9749513,0.0018744097,99.693235,0,0,1,,,,1.6986E-7,31.68545,1.3290929,1.0737395,0
22372765.27,,4881,0,1.3102,-0.044,9.2E-6,1.3232565,0.028111284,1.5043813,0.007117,0.1441976,0.002194,1.6485789,0.007117,1.4811985,7.8551535,0.001118057,99.821462,0,0,1,,,,2.1018E-7,31.89981,1.7510078,1.1368781,0
22372856.42,,4881,0,1.31,-0.044,9.4E-6,1.3232962,0.02828577,1.5022723,0.007308,0.14423882,0.002194,1.6465111,0.007308,1.4380332,8.0055845,0.0051644633,99.188494,0,0,1,,,,2.0707E-7,31.42061,1.7511128,1.1352502,0
22372950.16,,4881,0,1.3101,-0.044,9.2E-6,1.3229628,0.028652807,1.5207974,0.006944,0.14416707,0.002194,1.6649644,0.006944,1.0624053,8.2476139,0.0070307875,98.914244,0,0,1,,,,2.0372E-7,32.02234,1.7502306,1.149539,0
22373245.58,,4881,0,1.4798,-0.044,9.2E-6,1.4960592,0.032066954,1.7912459,0.005213,0.1907376,0.001256,1.9819835,0.005213,1.813175,7.8788506,0.0043117484,99.368246,0,0,1,,,,2.5286E-7,32.99046,2.2381932,1.1973095,0
22373337.39,,4881,0,1.4801,-0.044,9.3E-6,1.4963407,0.032168793,1.7582903,0.004413,0.19087208,0.001256,1.9491624,0.004413,1.8826066,7.847281,0.0055131392,99.200648,0,0,1,,,,2.5002E-7,31.5154,2.2390354,1.1750602,0
22373428.17,,4881,0,1.48,-0.044,9.3E-6,1.4960258,0.032004309,1.7635508,0.005086,0.19077048,0.001256,1.9543212,0.005086,1.7547548,7.8029913,0.0040757176,99.40479,0,0,1,,,,2.5168E-7,31.38912,2.2380933,1.1788237,0
22373716.91,,4881,0,1.65,-0.044,9.4E-6,1.667975,0.035941129,1.953515,0.005528,0.24737356,0.001458,2.2008885,0.005528,1.4600304,7.5162821,0.0047042891,99.370346,0,0,1,,,,2.9428E-7,31.21197,2.7821405,1.1711896,0
22373806.38,,4881,0,1.6499,-0.044,9.3E-6,1.66799,0.035675024,1.9635292,0.005276,0.24741832,0.001458,2.2109475,0.005276,1.5154327,7.5633107,0.0040215111,99.463316,0,0,1,,,,2.9357E-7,30.06513,2.7821906,1.1771829,0
22373895.38,,4881,0,1.6498,-0.044,9.4E-6,1.6677181,0.036032896,1.9580697,0.004804,0.24733898,0.001458,2.2054087,0.004804,0.934788,7.6468452,0.0053485938,99.294667,0,0,1,,,,2.9002E-7,30.25324,2.7812838,1.1741011,0
22374183.17,,4881,0,1.82,-0.044,9.2E-6,1.8395845,0.039971501,2.1141642,0.006021,0.31646071,0.00193,2.4306249,0.006021,1.0534346,7.2586163,0.0024136186,99.705931,0,0,1,,,,3.3561E-7,30.58738,3.384071,1.1492618,0
22374270.28,,4881,0,1.8197,-0.044,9.2E-6,1.839456,0.039318284,2.1109406,0.006587,0.3164307,0.001929,2.4273713,0.006587,1.9495459,7.1998211,0.0011436665,99.859781,0,0,1,,,,3.375E-7,29.03447,3.3835982,1.1475896,0
22374356.23,,4881,0,1.8199,-0.044,9.3E-6,1.8392951,0.039708408,2.1048767,0.006099,0.3163935,0.001929,2.4212702,0.006099,0.98714168,7.3201791,0.0030809642,99.628785,0,0,1,,,,3.317E-7,28.79928,3.3830064,1.1443932,0
22374640.97,,4881,0,1.9898,-0.044,9.3E-6,2.0108668,0.04317542,2.2563701,0.007262,0.40203693,0.002786,2.658407,0.007262,0.94682867,7.0950362,0.0052760977,99.419174,0,0,1,,,,3.7626E-7,29.28072,4.0435853,1.1220883,0
22374726.81,,4881,0,1.9898,-0.044,9.2E-6,2.0105845,0.042794958,2.2558573,0.00689,0.40192587,0.002786,2.6577831,0.00689,1.3003837,7.0540906,0.0025448163,99.718591,0,0,1,,,,3.7754E-7,28.38014,4.04245,1.1219908,0
22374814.64,,4881,0,1.9899,-0.044,9.4E-6,2.0110782,0.042744311,2.2580648,0.007355,0.40220878,0.002787,2.6602736,0.007355,1.1500526,7.0740002,0.0031899213,99.64807,0,0,1,,,,3.7702E-7,28.21636,4.0444356,1.122813,0
22375086.34,,4881,0,2.1602,-0.044,9.4E-6,2.1825123,0.046255686,2.3902239,0.005129,0.5089641,0.00233,2.899188,0.005129,1.3772529,6.9317573,0.0029175502,99.708889,0,0,1,,,,4.1908E-7,28.296,4.7633599,1.0951709,0
22375170.33,,4881,0,2.1601,-0.044,9.2E-6,2.1817964,0.045912208,2.4010419,0.004771,0.50849455,0.002333,2.9095365,0.004771,1.2094856,6.9532179,0.0074867829,99.251378,0,0,1,,,,4.206E-7,27.72703,4.7602354,1.1004885,0
22375254.66,,4881,0,2.1599,-0.044,9.2E-6,2.1823591,0.046059512,2.4017674,0.004954,0.50886994,0.002331,2.9106373,0.004954,1.4596753,6.949678,0.0049966354,99.500722,0,0,1,,,,4.2025E-7,27.81287,4.7626912,1.1005372,0
22375525.84,,4881,0,2.3301,-0.044,9.3E-6,2.3533205,0.049417511,2.5451223,0.006203,0.63291324,0.002257,3.1780355,0.006203,3.6915357,6.8877289,0.0041704528,99.619949,0,0,1,,,,4.6254E-7,27.79871,5.5381172,1.0815026,0
22375608.67,,4881,0,2.33,-0.044,9.2E-6,2.3540391,0.049815787,2.5533734,0.00474,0.6336572,0.002259,3.1870306,0.00474,1.4097718,6.9896544,0.0057873933,99.47943,0,0,1,,,,4.575E-7,27.55092,5.5415003,1.0846775,0
22375693.02,,4881,0,2.33,-0.044,9.4E-6,2.3556041,0.049624456,2.5494342,0.005663,0.63466759,0.002261,3.1841018,0.005663,1.0218883,6.8720964,0.0024786087,99.773858,0,0,1,,,,4.6401E-7,27.95862,5.5488707,1.0822847,0
22375968.53,,4881,0,2.5002,-0.044,9.4E-6,2.5271005,0.053332305,2.7067551,0.005863,0.7812776,0.002729,3.4880327,0.005863,1.0184444,6.9857464,0.0053492476,99.559057,0,0,1,,,,5.0064E-7,27.48839,6.3862368,1.0710912,0
22376052.45,,4881,0,2.4997,-0.044,9.2E-6,2.5289713,0.053436925,2.7076209,0.006633,0.78285512,0.002735,3.490476,0.006633,1.9840104,6.9530865,0.0043262112,99.64211,0,0,1,,,,5.0309E-7,27.94299,6.395696,1.0706412,0
22376136.56,,4881,0,2.4998,-0.044,9.2E-6,2.5282318,0.053510026,2.7092061,0.005997,0.78220079,0.002732,3.4914069,0.005997,0.7355331,6.9944127,0.0069707932,99.426031,0,0,1,,,,5.0091E-7,27.81235,6.3919559,1.0715814,0
22376394.53,,4881,0,2.6004,-0.044,9.4E-6,2.6235751,0.054012865,2.8238501,0.009106,0.87996599,0.003169,3.7038161,0.009106,1.9105819,6.9595685,0.0057245242,99.545563,0,0,1,,,,5.336E-7,13.17039,6.8831464,1.0763367,0
22376465.86,,4881,0,2.5998,-0.044,9.4E-6,2.628066,0.055398226,2.8084538,0.00802,0.884876,0.003192,3.6933298,0.00802,1.2378204,7.0480586,0.0081884777,99.361643,0,0,1,,,,5.2597E-7,13.91914,6.9067307,1.068639,0
22376538.27,,4881,0,2.5999,-0.044,9.3E-6,2.6281289,0.055861554,2.7966943,0.00788,0.8850994,0.003193,3.6817937,0.00788,1.0697421,7.1002464,0.012395824,99.042485,0,0,1,,,,5.2144E-7,14.09612,6.9070618,1.0641389,0
22376749.13,,4881,0,2.6141,-0.044,9.3E-6,2.6434884,0.056167177,2.7963786,0.007746,0.90071568,0.003265,3.6970942,0.007746,1.0479017,7.0508423,0.010895262,99.160393,0,0,1,,,,5.2689E-7,14.20049,6.9880309,1.0578365,0
22376820.05,,4881,0,2.6137,-0.044,9.3E-6,2.6417344,0.05591632,2.8196542,0.008279,0.89922869,0.003258,3.7188829,0.008279,1.1839624,7.0157671,0.010015291,99.220406,0,0,1,,,,5.3247E-7,14.10168,6.9787606,1.0673496,0
22376890.3,,4881,0,2.6137,-0.044,9.2E-6,2.638284,0.05574828,2.8235209,0.008001,0.89549366,0.003241,3.7190146,0.008001,0.69946571,6.9844511,0.005911627,99.536671,0,0,1,,,,5.339E-7,14.03153,6.9605425,1.0702111,0
22377097.47,,4881,0,2.6286,-0.044,9.3E-6,2.6566111,0.055737655,2.8204069,0.008784,0.91502001,0.003329,3.7354269,0.008784,0.83124128,7.0647345,0.010032414,99.231349,0,0,1,,,,5.3108E-7,13.9689,7.0575823,1.061656,0
22377172.03,,4881,0,2.628,-0.044,9.3E-6,2.6558068,0.056578425,2.8231418,0.008142,0.91373969,0.003323,3.7368815,0.008142,1.0639029,7.0101414,0.0077027205,99.404674,0,0,1,,,,5.3489E-7,14.12947,7.0533099,1.0630072,0
22377243.92,,4881,0,2.628,-0.044,9.3E-6,2.6565615,0.056203681,2.8201772,0.008025,0.91504866,0.003329,3.7352259,0.008025,1.3393001,7.0748426,0.01130147,99.135282,0,0,1,,,,5.3059E-7,14.02028,7.0573188,1.0615893,0
22377456.61,,4881,0,2.6408,-0.044,9.3E-6,2.6707482,0.056231133,2.8418453,0.007407,0.92979982,0.003393,3.7716451,0.007407,1.2772438,7.0224401,0.009815672,99.246714,0,0,1,,,,5.394E-7,14.14969,7.1328959,1.0640634,0
22377526.45,,4881,0,2.6411,-0.044,9.2E-6,2.6696111,0.056487073,2.8422496,0.00883,0.92904448,0.00339,3.7712941,0.00883,1.1488569,7.0403675,0.0092295283,99.293202,0,0,1,,,,5.3784E-7,14.04488,7.1268234,1.064668,0
22377597.42,,4881,0,2.6409,-0.044,9.4E-6,2.6690539,0.056763394,2.832994,0.009046,0.92846906,0.003387,3.761463,0.009046,1.680919,7.0315261,0.0094090796,99.279505,0,0,1,,,,5.3715E-7,14.08074,7.1238487,1.0614225,0
22377809.64,,4881,0,2.6555,-0.044,9.2E-6,2.6831268,0.056529337,2.8466552,0.008461,0.9437618,0.00345,3.790417,0.008461,1.0570112,7.0165951,0.010174636,99.223727,0,0,1,,,,5.4259E-7,14.06305,7.1991697,1.0609469,0
22377880.13,,4881,0,2.6551,-0.044,9.2E-6,2.6855541,0.056934382,2.8414388,0.008489,0.94644346,0.003461,3.7878823,0.008489,0.63308293,7.0242934,0.0080908618,99.384971,0,0,1,,,,5.4113E-7,14.03319,7.2122011,1.0580456,0
22377953.58,,4881,0,2.6551,-0.044,9.3E-6,2.6804796,0.056930565,2.8659566,0.008923,0.94098382,0.003439,3.8069404,0.008923,0.85112973,7.1034495,0.010225384,99.225586,0,0,1,,,,5.383E-7,14.04859,7.1849707,1.0691955,0
22378160.22,,4881,0,2.669,-0.044,9.3E-6,2.6971824,0.056955045,2.857093,0.007992,0.95883886,0.003509,3.8159319,0.007992,0.91800252,6.9842883,0.010234481,99.220351,0,0,1,,,,5.4877E-7,14.2069,7.2747927,1.0592881,0
22378230.48,,4881,0,2.6687,-0.044,9.2E-6,2.694791,0.056821873,2.8713527,0.008696,0.95668653,0.003501,3.8280392,0.008696,0.86245713,7.0496472,0.010387151,99.213194,0,0,1,,,,5.4544E-7,13.96858,7.2618986,1.0655196,0
22378301.38,,4881,0,2.6689,-0.044,9.3E-6,2.696337,0.057211987,2.8749184,0.009027,0.95847148,0.003508,3.8333899,0.009027,0.91451234,7.0807244,0.01021626,99.229794,0,0,1,,,,5.4375E-7,14.09929,7.2702332,1.0662311,0
22378513.64,,4881,0,2.6827,-0.044,9.3E-6,2.7099706,0.057161564,2.8893221,0.009324,0.97319884,0.003562,3.862521,0.009324,1.364285,7.0613847,0.0084624294,99.363662,0,0,1,,,,5.4895E-7,14.16145,7.3439406,1.0661821,0
22378586.13,,4881,0,2.6829,-0.044,9.2E-6,2.7139211,0.057368496,2.8942737,0.008721,0.97775737,0.003577,3.872031,0.008721,1.2844684,7.1053382,0.011190854,99.164729,0,0,1,,,,5.4752E-7,14.12277,7.3653675,1.0664546,0
22378659.31,,4881,0,2.6827,-0.044,9.4E-6,2.7123141,0.057489256,2.8950264,0.009388,0.97588377,0.003571,3.8709102,0.009388,1.3724926,7.066507,0.0087207226,99.344956,0,0,1,,,,5.4981E-7,14.21068,7.3566477,1.067364,0
22378863.38,,4881,0,2.6968,-0.044,9.4E-6,2.7267461,0.057240018,2.9032278,0.009151,0.99216571,0.003624,3.8953935,0.009151,2.2926524,7.0238266,0.0058745029,99.55919,0,0,1,,,,5.5596E-7,14.13301,7.4351441,1.0647225,0
22378934.27,,4881,0,2.6971,-0.044,9.4E-6,2.7253022,0.057479322,2.8996447,0.0096,0.99112567,0.003621,3.8907703,0.0096,1.5967102,7.0770579,0.0097119819,99.276543,0,0,1,,,,5.52E-7,14.04765,7.4272721,1.0639718,0
22379006.81,,4881,0,2.6971,-0.044,9.3E-6,2.7262061,0.057469983,2.917759,0.009021,0.99160985,0.003623,3.9093688,0.009021,1.5660241,7.0374444,0.0073435518,99.448438,0,0,1,,,,5.5723E-7,14.15412,7.4322,1.0702635,0
22379215.89,,4881,0,2.7099,-0.044,9.2E-6,2.7379627,0.05716284,2.9380909,0.009761,1.0057011,0.003665,3.943792,0.009761,1.227001,7.1181587,0.010608806,99.214797,0,0,1,,,,5.5648E-7,14.07489,7.4964396,1.0730938,0
22379288.81,,4881,0,2.7096,-0.044,9.3E-6,2.7358634,0.058026685,2.9315569,0.009345,1.0028681,0.003657,3.934425,0.009345,1.421915,7.0842014,0.01082699,99.194551,0,0,1,,,,5.5789E-7,14.23632,7.4849483,1.071529,0
22379361.14,,4881,0,2.7098,-0.044,9.4E-6,2.7422559,0.058216454,2.898785,0.008295,1.0102215,0.003677,3.9090066,0.008295,1.7870343,7.0609133,0.0077275096,99.428608,0,0,1,,,,5.5536E-7,14.1684,7.5199676,1.0570804,0
22379572.52,,4881,0,2.7241,-0.044,9.4E-6,2.753471,0.0575312,2.9601203,0.009826,1.0232633,0.00371,3.9833836,0.009826,1.5663192,7.0965984,0.0066934445,99.505648,0,0,1,,,,5.6285E-7,14.12183,7.5816026,1.0750505,0
22379645.77,,4881,0,2.7243,-0.044,9.3E-6,2.7532711,0.0578771,2.9535233,0.009725,1.0230643,0.00371,3.9765876,0.009725,1.5822535,7.0745705,0.0076557065,99.433338,0,0,1,,,,5.6386E-7,14.1932,7.5805017,1.0727325,0
22379717.47,,4881,0,2.724,-0.044,9.3E-6,2.7504258,0.058119784,2.9608793,0.009657,1.0198964,0.003702,3.9807757,0.009657,1.1125874,7.1702265,0.010930105,99.199365,0,0,1,,,,5.5766E-7,14.14914,7.5648422,1.0765167,0
22379929.48,,4881,0,2.7381,-0.044,9.3E-6,2.7661092,0.05811554,2.9862369,0.01004,1.0383787,0.003744,4.0246156,0.01004,2.2442005,7.1603099,0.0092664053,99.323519,0,0,1,,,,5.6418E-7,14.34045,7.65136,1.0795803,0
22380002.45,,4881,0,2.7375,-0.044,9.4E-6,2.7646387,0.05830448,3.0003264,0.009722,1.0365583,0.00374,4.0368847,0.009722,1.2792172,7.1050168,0.0067378199,99.502817,0,0,1,,,,5.6974E-7,14.32062,7.6432273,1.0852508,0
22380073.67,,4881,0,2.7378,-0.044,9.3E-6,2.764531,0.058179846,2.9974979,0.009726,1.036496,0.00374,4.0339938,0.009726,2.0384137,7.1308202,0.010058455,99.260594,0,0,1,,,,5.6804E-7,14.21003,7.6426319,1.0842699,0
22380283.5,,4881,0,2.7521,-0.044,9.2E-6,2.7814735,0.058006435,3.0089787,0.009888,1.056821,0.003776,4.0657997,0.009888,1.8131392,7.1768645,0.010031512,99.272863,0,0,1,,,,5.6879E-7,14.26164,7.7365951,1.081793,0
22380356.3,,4881,0,2.7518,-0.044,9.3E-6,2.7809317,0.058688477,3.0198518,0.01057,1.0563075,0.003775,4.0761593,0.01057,1.8829827,7.2256918,0.010754485,99.224147,0,0,1,,,,5.6654E-7,14.35373,7.7335809,1.0859137,0
22380427.86,,4881,0,2.7519,-0.044,9.4E-6,2.7772571,0.05853822,3.0495266,0.01003,1.0517105,0.003768,4.101237,0.01003,0.89714505,7.1477772,0.0063944178,99.530591,0,0,1,,,,5.7528E-7,14.45138,7.7131571,1.0980354,0
22380640.22,,4881,0,2.7667,-0.044,9.3E-6,2.795271,0.058124541,3.0750667,0.01009,1.0736911,0.003796,4.1487578,0.01009,0.8334507,7.2715162,0.0082574295,99.407642,0,0,1,,,,5.7242E-7,14.29555,7.8135398,1.1000961,0
22380713.53,,4881,0,2.7663,-0.044,9.2E-6,2.7966474,0.059072977,3.0658539,0.01097,1.0754238,0.003798,4.1412776,0.01097,1.0152746,7.2307381,0.0062734576,99.548503,0,0,1,,,,5.7416E-7,14.54303,7.8212369,1.0962604,0
22380786.13,,4881,0,2.7658,-0.044,9.3E-6,2.7961682,0.058965771,3.0650527,0.01182,1.0749305,0.003797,4.1399832,0.01182,2.2483601,7.2527924,0.011199285,99.196077,0,0,1,,,,5.7335E-7,14.46148,7.8185565,1.0961618,0
22381003.34,,4881,0,2.7791,-0.044,9.4E-6,2.8068911,0.05820797,3.1192833,0.01096,1.0880837,0.003805,4.207367,0.01096,1.2070216,7.2910598,0.009799261,99.298513,0,0,1,,,,5.793E-7,14.50558,7.8786378,1.1112947,0
22381075.75,,4881,0,2.779,-0.044,9.4E-6,2.8113061,0.058852737,3.1174584,0.01163,1.0936601,0.003806,4.2111185,0.01163,1.4944408,7.305802,0.0091912039,99.345214,0,0,1,,,,5.7849E-7,14.58212,7.9034422,1.1089004,0
22381147.88,,4881,0,2.779,-0.044,9.2E-6,2.8071237,0.059065961,3.1239872,0.01165,1.088534,0.003805,4.2125212,0.01165,1.6962928,7.3246998,0.010971589,99.217714,0,0,1,,,,5.7761E-7,14.6116,7.8799433,1.1128784,0
22381360.33,,4881,0,2.7935,-0.044,9.3E-6,2.8232049,0.058749706,3.1653773,0.01178,1.1087782,0.003806,4.2741556,0.01178,1.8086107,7.4566785,0.012805767,99.105284,0,0,1,,,,5.7604E-7,14.6494,7.970486,1.1212,0
22381434.41,,4881,0,2.7928,-0.044,9.3E-6,2.8205845,0.05980846,3.1814071,0.01161,1.1054782,0.003806,4.2868853,0.01161,1.7361462,7.4036776,0.0080848492,99.429051,0,0,1,,,,5.8085E-7,14.91336,7.9556968,1.1279248,0
22381507.48,,4881,0,2.793,-0.044,9.3E-6,2.823203,0.059388271,3.1801699,0.01111,1.1087262,0.003806,4.2888961,0.01111,2.0426688,7.4153998,0.0076607926,99.460744,0,0,1,,,,5.801E-7,14.80736,7.9704753,1.1264404,0
22381716.92,,4881,0,2.8066,-0.044,9.4E-6,2.8344507,0.058828411,3.2483507,0.01239,1.1230198,0.003799,4.3713706,0.01239,2.6374633,7.4738835,0.010093921,99.292004,0,0,1,,,,5.8719E-7,14.8308,8.0341106,1.1460248,0
22381790.44,,4881,0,2.8072,-0.044,9.3E-6,2.8352781,0.059437447,3.260389,0.01199,1.1241286,0.003798,4.3845176,0.01199,2.1585778,7.489564,0.007822647,99.451831,0,0,1,,,,5.872E-7,14.94777,8.0388019,1.1499362,0
22381864.3,,4881,0,2.8069,-0.044,9.2E-6,2.8359437,0.059995647,3.2402194,0.01219,1.1251133,0.003798,4.3653327,0.01219,1.7246251,7.5189805,0.0095477384,99.335784,0,0,1,,,,5.8272E-7,14.97913,8.0425768,1.1425542,0
22382074.84,,4881,0,2.8212,-0.044,9.4E-6,2.8499905,0.058744862,3.3632652,0.01473,1.1430505,0.003782,4.5063157,0.01473,1.9270883,7.617613,0.0072770693,99.495094,0,0,1,,,,5.9324E-7,15.03796,8.1224459,1.180097,0
22382150.03,,4881,0,2.8214,-0.044,9.4E-6,2.8494909,0.059658152,3.3591324,0.0138,1.1419596,0.003783,4.501092,0.0138,1.5786062,7.5791003,0.0062450893,99.56459,0,0,1,,,,5.9533E-7,15.23523,8.1195984,1.1788535,0
22382224.17,,4881,0,2.8213,-0.044,9.2E-6,2.8512534,0.059713822,3.3374563,0.01442,1.144247,0.003781,4.4817033,0.01442,2.791212,7.5695584,0.0068138537,99.526301,0,0,1,,,,5.9363E-7,15.1582,8.1296457,1.1705225,0
22382433.69,,4881,0,2.8343,-0.044,9.4E-6,2.8689315,0.059177452,3.3663713,0.01258,1.1680345,0.003751,4.5344058,0.01258,1.8550042,7.7307639,0.012990201,99.120523,0,0,1,,,,5.8941E-7,15.13912,8.2307681,1.1733885,0
22382508.67,,4881,0,2.8345,-0.044,9.3E-6,2.8640941,0.060309186,3.4041252,0.01279,1.1613126,0.003761,4.5654378,0.01279,1.6056478,7.7378172,0.012626133,99.138813,0,0,1,,,,5.9287E-7,15.46153,8.203035,1.1885521,0
22382583.91,,4881,0,2.8336,-0.044,9.4E-6,2.8645931,0.060628586,3.3791416,0.012,1.1619787,0.00376,4.5411202,0.012,2.5962866,7.7246399,0.011707243,99.20332,0,0,1,,,,5.9049E-7,15.47563,8.2058938,1.1796236,0
22382804.95,,4881,0,2.8481,-0.044,9.3E-6,2.8781361,0.061344271,3.2971064,0.01654,1.1800837,0.003733,4.4771901,0.01654,4.1006314,7.7543031,0.019331577,98.714124,0,0,1,,,,5.8147E-7,15.44928,8.2836672,1.14557,0
22382880.81,,4881,0,2.8483,-0.044,9.2E-6,2.8800726,0.062213517,3.2701008,0.01583,1.1828233,0.003729,4.4529241,0.01583,2.0962914,7.7769523,0.021072423,98.609305,0,0,1,,,,5.7695E-7,15.50861,8.2948181,1.135423,0
22382955.83,,4881,0,2.8478,-0.044,9.3E-6,2.8772068,0.061726826,3.2993728,0.01678,1.1789307,0.003735,4.4783035,0.01678,2.6331969,7.7493973,0.021151914,98.590851,0,0,1,,,,5.8239E-7,15.5539,8.2783187,1.1467277,0
22383168.25,,4881,0,2.8617,-0.044,9.4E-6,2.8885978,0.064777265,3.0193012,0.02864,1.1945701,0.00371,4.2138713,0.02864,19.984144,7.5863784,0.03702427,97.595096,0,0,1,,,,5.6251E-7,15.49879,8.3439972,1.045248,0
22383243.48,,4881,0,2.862,-0.044,9.3E-6,2.8882412,0.064575168,3.0216545,0.02794,1.1940603,0.003711,4.2157148,0.02794,17.150532,7.5926037,0.036188612,97.650101,0,0,1,,,,5.6214E-7,15.17276,8.341937,1.0461919,0
22383318.69,,4881,0,2.862,-0.044,9.4E-6,2.8900297,0.064307211,3.0157536,0.02706,1.1964488,0.003707,4.2122024,0.02706,15.432566,7.5941916,0.038433412,97.509086,0,0,1,,,,5.6196E-7,15.18521,8.3522719,1.0435026,0
22383532.86,,4881,0,2.8761,-0.044,9.2E-6,2.9049605,0.068593436,2.6272182,0.03026,1.2166297,0.003671,3.8438479,0.03026,34.596815,7.0976666,0.046603711,96.969662,0,0,1,,,,5.4952E-7,15.18838,8.4387953,0.90439036,0
22383604.88,,4881,0,2.8765,-0.044,9.3E-6,2.9033099,0.065716796,2.6740113,0.03076,1.2144723,0.003675,3.8884836,0.03076,28.861129,7.0432554,0.037892579,97.497809,0,0,1,,,,5.5882E-7,14.19533,8.4292087,0.92102164,0
22383677.34,,4881,0,2.8758,-0.044,9.3E-6,2.9052343,0.065340207,2.6783794,0.03097,1.2173859,0.00367,3.8957652,0.03097,19.666069,6.9564288,0.025134531,98.319557,0,0,1,,,,5.6456E-7,14.08651,8.4403863,0.92191511,0
22383884.94,,4881,0,2.8896,-0.044,9.4E-6,2.9210445,0.068661023,2.321306,0.02354,1.2389978,0.003631,3.5603038,0.02354,22.489327,6.4545511,0.04158945,97.171353,0,0,1,,,,5.5847E-7,13.91286,8.5325008,0.79468356,0
22383951.38,,4881,0,2.8896,-0.044,9.3E-6,2.9198686,0.065639213,2.3543675,0.02389,1.237361,0.003634,3.5917285,0.02389,13.733928,6.3884724,0.025773243,98.217737,0,0,1,,,,5.6662E-7,12.9091,8.5256328,0.80632651,0
22384018.8,,4881,0,2.8898,-0.044,9.4E-6,2.9179105,0.06549514,2.3528857,0.02404,1.2346018,0.003639,3.5874875,0.02404,13.325464,6.3681109,0.024177288,98.321668,0,0,1,,,,5.675E-7,12.77694,8.5142016,0.80635981,0
22384222.53,,4881,0,2.9032,-0.044,9.3E-6,2.9351994,0.067497449,2.0936431,0.0157,1.2580415,0.003597,3.3516846,0.0157,12.477564,5.8712117,0.028779679,97.918569,0,0,1,,,,5.7563E-7,12.73622,8.6153954,0.71328821,0
22384287.27,,4881,0,2.903,-0.044,9.3E-6,2.9300979,0.064635434,2.1192446,0.0162,1.2512896,0.003609,3.3705341,0.0162,5.9668317,5.8653267,0.023992953,98.253752,0,0,1,,,,5.7871E-7,11.74242,8.5854737,0.72326749,0
22384350.8,,4881,0,2.9025,-0.044,9.3E-6,2.9353918,0.06460264,2.111276,0.01702,1.2587303,0.003595,3.3700062,0.01702,7.9966208,5.9035932,0.027706629,98.002706,0,0,1,,,,5.7543E-7,11.73065,8.6165249,0.71924844,0
22384541.41,,4881,0,2.9174,-0.044,9.2E-6,2.9486061,0.066802262,1.933158,0.0119,1.2768372,0.003564,3.2099952,0.0119,3.163492,5.5730693,0.022447682,98.326137,0,0,1,,,,5.7955E-7,11.80719,8.6942777,0.65561757,0
22384602.55,,4881,0,2.9166,-0.044,9.2E-6,2.9483823,0.064897026,1.9345446,0.01206,1.2761133,0.003565,3.210658,0.01206,3.9183748,5.5141702,0.020069269,98.486444,0,0,1,,,,5.8552E-7,11.14614,8.6929579,0.65613766,0
22384664.31,,4881,0,2.917,-0.044,9.3E-6,2.9477695,0.064427696,1.9455375,0.01126,1.2753498,0.003567,3.2208874,0.01126,3.1900061,5.5496166,0.025633347,98.078617,0,0,1,,,,5.8455E-7,11.02834,8.689345,0.66000328,0
22384857.23,,4881,0,2.9309,-0.044,9.3E-6,2.9619119,0.065991085,1.8068157,0.009534,1.2950127,0.003535,3.1018284,0.009534,5.1432416,5.291767,0.026482303,97.955477,0,0,1,,,,5.9033E-7,11.09923,8.7729222,0.61001669,0
22384917.33,,4881,0,2.9308,-0.044,9.3E-6,2.9584408,0.064180143,1.8120193,0.009372,1.290625,0.003542,3.1026443,0.009372,3.2654566,5.2529811,0.023378221,98.17851,0,0,1,,,,5.944E-7,10.58353,8.752372,0.61249132,0
22384978.27,,4881,0,2.9309,-0.044,9.4E-6,2.9603654,0.064166167,1.817324,0.01023,1.293348,0.003538,3.110672,0.01023,3.1478716,5.2978194,0.020384149,98.423807,0,0,1,,,,5.9038E-7,10.50596,8.7637634,0.61388503,0
22385168.73,,4881,0,2.9453,-0.044,9.3E-6,2.9759448,0.065727585,1.7018881,0.008326,1.3152105,0.003507,3.0170985,0.008326,2.092439,5.0383487,0.020843538,98.327681,0,0,1,,,,6.0208E-7,10.59564,8.8562474,0.5718816,0
22385229.61,,4881,0,2.945,-0.044,9.3E-6,2.9716177,0.064174533,1.6915212,0.008619,1.3090059,0.003515,3.0005271,0.008619,2.127602,5.0708011,0.02705142,97.847598,0,0,1,,,,5.9589E-7,10.0767,8.8305118,0.56922571,0
22385288.8,,4881,0,2.9452,-0.044,9.3E-6,2.9744024,0.064245478,1.6914177,0.008142,1.3128408,0.00351,3.0042585,0.008142,1.9917746,5.0335343,0.023355565,98.126813,0,0,1,,,,6.0048E-7,10.1416,8.8470694,0.56865799,0
22385477.09,,4881,0,2.9594,-0.044,9.3E-6,2.9910431,0.064923924,1.6041167,0.007633,1.3364049,0.003482,2.9405216,0.007633,1.739639,4.8720179,0.021954855,98.195542,0,0,1,,,,6.0687E-7,10.06707,8.946339,0.53630677,0
22385534.94,,4881,0,2.9587,-0.044,9.3E-6,2.9857313,0.063876868,1.6128618,0.008221,1.3296247,0.003489,2.9424866,0.008221,1.34106,4.8902787,0.021209461,98.260973,0,0,1,,,,6.0491E-7,9.744036,8.9145913,0.54018988,0
22385592.78,,4881,0,2.9589,-0.044,9.2E-6,2.990421,0.064410283,1.5896441,0.008215,1.3364323,0.003482,2.9260764,0.008215,1.5161174,4.8738838,0.022459047,98.156752,0,0,1,,,,6.037E-7,9.780557,8.9426177,0.53157869,0
22385779.55,,4881,0,2.9719,-0.044,9.3E-6,3.0041201,0.064824262,1.5202486,0.007514,1.3559353,0.003465,2.8761839,0.007514,1.1452452,4.7125467,0.02150062,98.183596,0,0,1,,,,6.1349E-7,9.747768,9.0247373,0.50605454,0
22385836.28,,4881,0,2.972,-0.044,9.4E-6,3.0030721,0.064134658,1.5209801,0.007319,1.3544221,0.003466,2.8754022,0.007319,1.8838299,4.7567637,0.022820216,98.090604,0,0,1,,,,6.078E-7,9.425093,9.0184419,0.50647471,0
22385893.11,,4881,0,2.9721,-0.044,9.4E-6,3.0044512,0.064336657,1.5322383,0.006952,1.3563179,0.003465,2.8885562,0.006952,1.5884375,4.7385398,0.018186047,98.469356,0,0,1,,,,6.1226E-7,9.513527,9.0267272,0.50998942,0
22386078,,4881,0,2.9862,-0.044,9.2E-6,3.0193439,0.065257158,1.4409943,0.00685,1.3781058,0.003454,2.8191001,0.00685,1.7734586,4.6474775,0.026000164,97.784556,0,0,1,,,,6.102E-7,9.47708,9.1164373,0.47725412,0
22386135.06,,4881,0,2.986,-0.044,9.2E-6,3.0155808,0.064386649,1.4623581,0.006796,1.3723893,0.003456,2.8347474,0.006796,1.2345954,4.6444998,0.02160323,98.153534,0,0,1,,,,6.1341E-7,9.294955,9.0937277,0.48493414,0
22386190.98,,4881,0,2.9861,-0.044,9.4E-6,3.015822,0.064616043,1.4639559,0.006682,1.3725994,0.003456,2.8365553,0.006682,1.8538584,4.6063548,0.016918205,98.539328,0,0,1,,,,6.1823E-7,9.289,9.0951825,0.48542517,0
22386376.66,,4881,0,2.9999,-0.044,9.2E-6,3.0325472,0.065061405,1.3946314,0.006133,1.3972132,0.003452,2.7918447,0.006133,1.3040078,4.5640692,0.023420413,97.968137,0,0,1,,,,6.1488E-7,9.21271,9.1963426,0.45988779,0
22386431.89,,4881,0,3.0006,-0.044,9.3E-6,3.0303099,0.064681018,1.3945433,0.006717,1.3937558,0.003452,2.7882991,0.006717,1.4804677,4.5184476,0.022502649,98.027418,0,0,1,,,,6.2021E-7,9.128138,9.1827781,0.46019825,0
22386488.16,,4881,0,3,-0.044,9.4E-6,3.0272748,0.064417328,1.4085927,0.006502,1.3891693,0.003452,2.797762,0.006502,1.111529,4.5174573,0.018228665,98.398522,0,0,1,,,,6.2189E-7,9.036895,9.1643927,0.46530057,0
22386728.42,,4881,0,3.0496,-0.044,9.3E-6,3.0835718,0.068781522,1.1981624,0.00539,1.4731724,0.003534,2.6713348,0.00539,0.91658532,4.2610046,0.025573853,97.608036,0,0,1,,,,6.3004E-7,9.121707,9.5084148,0.38856318,0
22386782.27,,4881,0,3.0492,-0.044,9.3E-6,3.0785199,0.065033192,1.2166483,0.005978,1.4658168,0.003519,2.682465,0.005978,0.86587988,4.1827087,0.016839829,98.390884,0,0,1,,,,6.4349E-7,8.522009,9.4772849,0.39520558,0
22386835.42,,4881,0,3.0506,-0.044,9.3E-6,3.0823395,0.064829616,1.2090607,0.005866,1.4716699,0.00353,2.6807306,0.005866,1.1020018,4.2288297,0.018092208,98.289555,0,0,1,,,,6.3617E-7,8.365417,9.5008168,0.39225423,0
22387051.27,,4881,0,3.1327,-0.044,9.3E-6,3.1586833,0.068625492,1.0086648,0.00565,1.5891185,0.003963,2.5977832,0.00565,1.0812467,3.9859609,0.033714078,96.52494,0,0,1,,,,6.553E-7,8.457659,9.97728,0.31933077,0
22387105.09,,4881,0,3.1337,-0.044,9.3E-6,3.1636106,0.066448046,0.99540102,0.005829,1.5964063,0.004,2.5918073,0.005829,0.93021103,3.9582575,0.034092512,96.449709,0,0,1,,,,6.5837E-7,7.971922,10.008432,0.31464082,0
22387156.69,,4881,0,3.133,-0.044,9.4E-6,3.1614419,0.06650361,1.0157898,0.005739,1.5928238,0.003982,2.6086136,0.005739,1.0112964,3.9789163,0.021212194,97.792213,0,0,1,,,,6.5787E-7,7.916515,9.9947148,0.32130584,0
22387371.27,,4881,0,3.2176,-0.044,9.3E-6,3.2478092,0.070017551,0.82972194,0.006028,1.7314287,0.004805,2.5611506,0.006028,1.0172883,3.8220463,0.035132862,95.9372,0,0,1,,,,6.7311E-7,7.957833,10.548265,0.25547127,0
22387422.67,,4881,0,3.2172,-0.044,9.4E-6,3.2431611,0.067989748,0.84484311,0.006348,1.7249406,0.004763,2.5697837,0.006348,0.85593253,3.8003948,0.038262976,95.594594,0,0,1,,,,6.7959E-7,7.644093,10.518094,0.26049989,0
22387475.3,,4881,0,3.2167,-0.044,9.2E-6,3.2496856,0.06825171,0.82726599,0.006492,1.7355024,0.004831,2.5627683,0.006492,0.76973035,3.7948883,0.027200313,96.803897,0,0,1,,,,6.7766E-7,7.60079,10.560456,0.25456801,0
22387687.72,,4881,0,3.3002,-0.044,9.4E-6,3.3293038,0.070530411,0.71427438,0.006932,1.8696515,0.005692,2.5839259,0.006932,1.2255513,3.7277979,0.034112201,95.595368,0,0,1,,,,6.9561E-7,7.589777,11.084264,0.21454166,0
22387739.7,,4881,0,3.2999,-0.044,9.3E-6,3.3296747,0.070035098,0.7226506,0.006822,1.8703817,0.005696,2.5930323,0.006822,1.2420621,3.766948,0.038681391,95.102604,0,0,1,,,,6.9115E-7,7.455596,11.086733,0.2170334,0
22387791.38,,4881,0,3.3003,-0.044,9.2E-6,3.3332818,0.070664519,0.70242899,0.006792,1.8767341,0.005735,2.5791631,0.006792,1.7852374,3.7320373,0.046666762,94.011195,0,0,1,,,,6.9439E-7,7.533896,11.110767,0.21073196,0
22388007.19,,4881,0,3.3832,-0.044,9.3E-6,3.4111858,0.071862887,0.61797662,0.007565,2.0150194,0.00647,2.632996,0.007565,0.82764145,3.7145907,0.050909719,92.853967,0,0,1,,,,7.1187E-7,7.464075,11.636188,0.18116182,0
22388057.66,,4881,0,3.3834,-0.044,9.2E-6,3.4105202,0.07196363,0.61515157,0.007529,2.013643,0.006464,2.6287945,0.007529,0.89745046,3.6916363,0.043725788,93.758669,0,0,1,,,,7.1472E-7,7.429181,11.631648,0.18036884,0
22388108.63,,4881,0,3.383,-0.044,9.4E-6,3.4098558,0.071676526,0.61963884,0.007286,2.0126002,0.00646,2.632239,0.007286,1.1464737,3.718662,0.052398852,92.679808,0,0,1,,,,7.1099E-7,7.383273,11.627117,0.18171995,0
22388320.17,,4881,0,3.4664,-0.044,9.3E-6,3.4882015,0.073425564,0.54829926,0.007662,2.1595561,0.007001,2.7078553,0.007662,1.7141901,3.7660563,0.080954116,88.135294,0,0,1,,,,7.2307E-7,7.437324,12.16755,0.15718681,0
22388370.89,,4881,0,3.4669,-0.044,9.4E-6,3.4938528,0.074256489,0.52899117,0.007695,2.1698592,0.007035,2.6988504,0.007695,1.5494621,3.6904071,0.057286287,90.969565,0,0,1,,,,7.3415E-7,7.532113,12.207008,0.15140625,0
22388422.36,,4881,0,3.467,-0.044,9.3E-6,3.4937743,0.073286033,0.53229416,0.007868,2.1696311,0.007034,2.7019252,0.007868,1.0503551,3.6952294,0.064190516,90.02746,0,0,1,,,,7.3439E-7,7.380814,12.206459,0.15235505,0
22388637.89,,4881,0,3.5511,-0.044,9.3E-6,3.5780075,0.074318987,0.46946953,0.01422,2.3349245,0.007514,2.804394,0.01207,0.75257357,3.709931,0,100,0,0,1,,,,7.5592E-7,7.390459,12.802138,0.13120977,0
22388690.86,,4881,0,3.5508,-0.044,9.2E-6,3.5758352,0.074333589,0.47835547,0.01542,2.3304888,0.007503,2.8088443,0.01347,1.0537718,3.6856677,0,100,0,0,1,,,,7.621E-7,7.419862,12.786597,0.13377447,0
22388743.44,,4881,0,3.5498,-0.044,9.4E-6,3.5747232,0.073695186,0.48335469,0.0155,2.328131,0.007497,2.8114857,0.01357,1.4082667,3.688515,0,100,0,0,1,,,,7.6223E-7,7.371335,12.778646,0.13521458,0
22388959.08,,4881,0,3.6335,-0.044,9.3E-6,3.6565242,0.074567941,0.42460231,0.01618,2.4955996,0.007884,2.9202019,0.01413,1.7132549,3.7137257,0,100,0,0,1,,,,7.8633E-7,7.37703,13.370169,0.11612184,0
22389010.88,,4881,0,3.633,-0.044,9.3E-6,3.6589956,0.075490433,0.42763684,0.01691,2.5011272,0.007895,2.928764,0.01496,1.1778593,3.7509893,0,100,0,0,1,,,,7.808E-7,7.427451,13.388249,0.11687274,0
22389063.59,,4881,0,3.6333,-0.044,9.2E-6,3.6590842,0.075732596,0.42693639,0.01664,2.5013335,0.007895,2.9282699,0.01464,1.7483908,3.7415316,0,100,0,0,1,,,,7.8264E-7,7.501979,13.388897,0.11667848,0
22389276.97,,4881,0,3.7173,-0.044,9.4E-6,3.7428325,0.076401619,0.36929897,0.01752,2.6806212,0.008205,3.0499202,0.01548,1.2826478,3.8023966,0,100,0,0,1,,,,8.021E-7,7.483063,14.008795,0.098668312,0
22389329.64,,4881,0,3.7171,-0.044,9.3E-6,3.7474527,0.077367801,0.36260662,0.0157,2.6910279,0.00822,3.0536345,0.01338,1.2259222,3.8203671,0,100,0,0,1,,,,7.993E-7,7.604793,14.043402,0.096760825,0
22389383.45,,4881,0,3.7173,-0.044,9.3E-6,3.7479327,0.077518737,0.36468374,0.01799,2.6921498,0.008221,3.0568335,0.016,1.3222885,3.8287266,0,100,0,0,1,,,,7.9839E-7,7.640734,14.047,0.097302638,0
22389599.53,,4881,0,3.8004,-0.044,9.4E-6,3.8315479,0.077957081,0.31679467,0.01855,2.8791669,0.00844,3.1959615,0.01652,1.1244321,3.8954361,0,100,0,0,1,,,,8.2044E-7,7.657453,14.68076,0.082680596,0
22389653.55,,4881,0,3.8008,-0.044,9.3E-6,3.8313175,0.07881213,0.32294722,0.01753,2.8789519,0.008439,3.2018991,0.01537,1.7702331,3.9144924,0,100,0,0,1,,,,8.1796E-7,7.790872,14.678994,0.084291427,0
22389707.47,,4881,0,3.7998,-0.044,9.3E-6,3.828754,0.079475653,0.32146213,0.01712,2.8733065,0.008434,3.1947686,0.01489,1.494536,3.9167301,0,100,0,0,1,,,,8.1567E-7,7.828985,14.659357,0.083959986,0