File: Data/HeatCapacity/0p19mg_drhc_EuPd2S4_09182020_fieldsweeps.dat
[Header]
TITLE,eupd3s4_field_sweeps
BYAPP,HeatCapacity,3.8.14,1.7
INFO,0,MASS:Sample Mass (mg)
INFO,0,MASSERR:Sample Mass Error (mg)
INFO,0,MOLWGHT:Formula Weight (g/mole)
INFO,0,ATOMS:Atoms per Formula Unit
INFO,PPMS Heat Capacity Option 3.8.14 Build 19,APPNAME
DATATYPE,TIME,1
DATATYPE,COMMENT,2
STARTUPAXIS, X, 8, LINEAR, AUTO
STARTUPAXIS, Y1, 10, LINEAR, AUTO
[Data]
Time Stamp (Seconds),Comment (),System Status (Code),Puck Temp (Kelvin),System Temp (Kelvin),Field (Oersted),Pressure (Torr),Sample Temp (Kelvin),Temp Rise (Kelvin),Samp HC (µJ/K),Samp HC Err (µJ/K),Addenda HC (µJ/K),Addenda HC Err (µJ/K),Total HC (µJ/K),Total HC Err (µJ/K),Fit Deviation (ChiSquare),Time Const tau1 (seconds),Time Const tau2 (seconds),Sample Coupling (Percent),Debye Temp (Kelvin),Debye Temp Err (Kelvin),Cal Correction (Factor),Therm Resist (Ohms),Htr Resist (Ohms),Puck Resist (Ohms),Wire Cond (W/K),Meas Time (seconds),Temp Squared (K^2),Samp HC/Temp (µJ/K/K),Addenda Offset HC (µJ/K)
22563901.17,Error: Warning: Current field is 6000.029 Oe;
22563901.34,Error: but addenda was obtained at 10000.058 Oe.
22564455.11,,4881,0,1.75,6000.029,9.3E-6,1.7675792,0.038588677,1.8227895,0.007291,0.29513983,0.001858,2.1179293,0.007291,1.5234918,6.7220331,0.0044774531,99.44312,0,0,1,,,,3.1638E-7,14,3.1243362,1.031235,0
22564505.44,,4881,0,1.7499,6000.029,9.3E-6,1.7675241,0.038102154,1.8226194,0.00794,0.29511461,0.001857,2.117734,0.00794,0.33696028,6.7711172,0.0057400419,99.290737,0,0,1,,,,3.1442E-7,13.44407,3.1241413,1.0311709,0
22564553.2,,4881,0,1.7503,6000.029,9.4E-6,1.7675157,0.03803712,1.8280348,0.007806,0.29508754,0.001857,2.1231223,0.007806,0.2722473,6.7041064,0.0047118602,99.411007,0,0,1,,,,3.1808E-7,13.54223,3.1241116,1.0342396,0
22564690.58,Error: Warning: Current field is 5793.08 Oe;
22564690.88,Error: but addenda was obtained at 10000.058 Oe.
22564747.13,,4881,0,1.7499,5793.08,9.3E-6,1.7678091,0.038500141,1.8239146,0.00721,0.29524051,0.001859,2.1191551,0.00721,1.0448446,6.7263716,0.0057782911,99.28108,0,0,1,,,,3.1674E-7,14,3.1251489,1.0317373,0
22564796.14,,4881,0,1.7499,5793.08,9.3E-6,1.7674202,0.038026231,1.8193594,0.008312,0.29504714,0.001857,2.1144066,0.008312,0.50674335,6.6895042,0.0052942191,99.338747,0,0,1,,,,3.1764E-7,13.45274,3.123774,1.029387,0
22564845.3,,4881,0,1.7502,5793.08,9.3E-6,1.7676306,0.037809557,1.829585,0.0077,0.29513337,0.001857,2.1247184,0.0077,0.46110012,6.7300831,0.0049849575,99.378865,0,0,1,,,,3.1717E-7,13.37901,3.124518,1.0350494,0
22564981.13,Error: Warning: Current field is 5586.189 Oe;
22564981.39,Error: but addenda was obtained at 10000.058 Oe.
22565037.45,,4881,0,1.7503,5586.189,9.3E-6,1.7679737,0.038578133,1.8291646,0.00757,0.29531974,0.001859,2.1244843,0.00757,1.2868917,6.7768513,0.0050202979,99.379167,0,0,1,,,,3.1494E-7,14,3.1257309,1.0346108,0
22565086.02,,4881,0,1.7502,5586.189,9.2E-6,1.7679509,0.038227723,1.8133331,0.008727,0.29526066,0.001859,2.1085937,0.008727,0.13848895,6.6328637,0.0046842669,99.411866,0,0,1,,,,3.1929E-7,13.5537,3.1256502,1.0256694,0
22565135.11,,4881,0,1.75,5586.189,9.4E-6,1.7674045,0.037757107,1.8187812,0.007859,0.29504614,0.001857,2.1138273,0.007859,0.32560774,6.750175,0.0058653961,99.273926,0,0,1,,,,3.1485E-7,13.26573,3.1237187,1.029069,0
22565270.52,Error: Warning: Current field is 5379.284 Oe;
22565270.73,Error: but addenda was obtained at 10000.058 Oe.
22565328.5,,4881,0,1.7504,5379.284,9.3E-6,1.7678775,0.038858166,1.8078758,0.007266,0.29530879,0.001859,2.1031846,0.007266,1.0544907,6.7830288,0.0078155568,99.040907,0,0,1,,,,3.1229E-7,14,3.125391,1.022625,0
22565377.2,,4881,0,1.7501,5379.284,9.4E-6,1.7677137,0.038166856,1.8150354,0.007074,0.29515924,0.001858,2.1101946,0.007074,0.4009242,6.6389793,0.0044576774,99.440391,0,0,1,,,,3.1917E-7,13.56606,3.1248116,1.02677,0
22565430.2,,4881,0,1.7501,5379.284,9.2E-6,1.7671572,0.037854655,1.8234406,0.007897,0.29496694,0.001856,2.1184075,0.007897,0.38719278,6.8159777,0.0067812622,99.166513,0,0,1,,,,3.1274E-7,13.27796,3.1228447,1.0318497,0
22565566.05,Error: Warning: Current field is 5172.384 Oe;
22565566.2,Error: but addenda was obtained at 10000.058 Oe.
22565621.25,,4881,0,1.7499,5172.384,9.4E-6,1.7674176,0.03871602,1.8161257,0.006639,0.29509107,0.001857,2.1112168,0.006639,1.1258038,6.7496607,0.0057174357,99.293081,0,0,1,,,,3.1444E-7,14,3.1237649,1.0275589,0
22565670.09,,4881,0,1.7501,5172.384,9.3E-6,1.7676098,0.038205379,1.810823,0.007758,0.29512586,0.001857,2.1059489,0.007758,0.46641868,6.6577362,0.0051900397,99.351042,0,0,1,,,,3.1784E-7,13.49932,3.1244445,1.0244473,0
22565719.83,,4881,0,1.7502,5172.384,9.3E-6,1.7671994,0.037837975,1.8203735,0.00773,0.29496392,0.001856,2.1153374,0.00773,0.7805784,6.7446248,0.0060700392,99.247249,0,0,1,,,,3.154E-7,13.31547,3.1229938,1.0300894,0
22565855.11,Error: Warning: Current field is 4965.504 Oe;
22565855.27,Error: but addenda was obtained at 10000.058 Oe.
22565912.72,,4881,0,1.7499,4965.504,9.4E-6,1.7676903,0.038554822,1.8091639,0.007204,0.29515499,0.001858,2.1043189,0.007204,1.2636027,6.6062048,0.0039444211,99.503678,0,0,1,,,,3.1971E-7,14,3.1247289,1.023462,0
22565962.31,,4881,0,1.7501,4965.504,9.3E-6,1.7670571,0.037627868,1.8116799,0.00754,0.29487255,0.001855,2.1065524,0.00754,0.80887504,6.6577439,0.0054076692,99.323087,0,0,1,,,,3.18E-7,13.21241,3.1224909,1.0252526,0
22566010.52,,4881,0,1.7498,4965.504,9.3E-6,1.767527,0.037867726,1.8105306,0.007678,0.29507728,0.001857,2.1056079,0.007678,0.37536295,6.6640769,0.0049328257,99.383887,0,0,1,,,,3.1741E-7,13.31549,3.1241517,1.0243298,0
22566145.94,Error: Warning: Current field is 4758.589 Oe;
22566146.08,Error: but addenda was obtained at 10000.058 Oe.
22566203.97,,4881,0,1.7501,4758.589,9.3E-6,1.7677344,0.038800575,1.8038955,0.007883,0.29521537,0.001858,2.0991109,0.007883,0.98049587,6.6968676,0.005845316,99.275277,0,0,1,,,,3.1514E-7,14,3.1248848,1.0204562,0
22566252.98,,4881,0,1.7498,4758.589,9.3E-6,1.7675335,0.038106565,1.8063765,0.007493,0.29511303,0.001857,2.1014896,0.007493,0.42102837,6.7188843,0.0068386082,99.15335,0,0,1,,,,3.1475E-7,13.39374,3.1241747,1.0219758,0
22566303.02,,4881,0,1.7501,4758.589,9.2E-6,1.7673101,0.038068091,1.8128465,0.008127,0.29497863,0.001856,2.1078251,0.008127,0.59922816,6.6422979,0.0028616179,99.641441,0,0,1,,,,3.1818E-7,13.43777,3.1233851,1.0257659,0
22566437.84,Error: Warning: Current field is 4551.689 Oe;
22566438.05,Error: but addenda was obtained at 10000.058 Oe.
22566495.42,,4881,0,1.7501,4551.689,9.3E-6,1.7678438,0.0388676,1.797045,0.007233,0.29526968,0.001859,2.0923147,0.007233,0.69772883,6.7052658,0.0065260159,99.193898,0,0,1,,,,3.1391E-7,14,3.1252719,1.0165179,0
22566544.3,,4881,0,1.75,4551.689,9.3E-6,1.7673278,0.037966999,1.8112394,0.007942,0.29498547,0.001856,2.1062249,0.007942,0.87234842,6.6378792,0.0036999491,99.536158,0,0,1,,,,3.184E-7,13.41053,3.1234475,1.0248464,0
22566591.89,,4881,0,1.7498,4551.689,9.4E-6,1.7674866,0.03780197,1.8089972,0.007486,0.29503192,0.001856,2.1040291,0.007486,0.48787089,6.6078016,0.0025823305,99.67534,0,0,1,,,,3.1918E-7,13.27576,3.1240088,1.0234857,0
22566726.41,Error: Warning: Current field is 4344.806 Oe;
22566726.69,Error: but addenda was obtained at 10000.058 Oe.
22566783.08,,4881,0,1.7503,4344.806,9.3E-6,1.7672913,0.038936165,1.7938963,0.00693,0.29505253,0.001857,2.0889488,0.00693,0.89071028,6.7230536,0.0076668237,99.055549,0,0,1,,,,3.129E-7,14,3.1233186,1.0150541,0
22566831.31,,4881,0,1.7502,4344.806,9.3E-6,1.7672508,0.038236047,1.7960637,0.006864,0.2949761,0.001856,2.0910398,0.006864,0.69855453,6.6377108,0.0058108612,99.274981,0,0,1,,,,3.1672E-7,13.44611,3.1231752,1.0163038,0
22566880.98,,4881,0,1.7499,4344.806,9.2E-6,1.7671544,0.038114069,1.7940771,0.007904,0.29495826,0.001856,2.0890354,0.007904,0.24611826,6.7129312,0.0076492272,99.056011,0,0,1,,,,3.1339E-7,13.27542,3.1228347,1.0152351,0
22567016.56,Error: Warning: Current field is 4137.909 Oe;
22567016.81,Error: but addenda was obtained at 10000.058 Oe.
22567073.61,,4881,0,1.7498,4137.909,9.4E-6,1.7676017,0.038826438,1.801832,0.007596,0.29517334,0.001858,2.0970054,0.007596,1.3045755,6.7223594,0.006964884,99.139799,0,0,1,,,,3.1395E-7,14,3.1244158,1.0193654,0
22567122.41,,4881,0,1.7498,4137.909,9.4E-6,1.7677162,0.038596023,1.7811834,0.007187,0.2951931,0.001858,2.0763765,0.007187,0.36879164,6.6704079,0.0058746849,99.27535,0,0,1,,,,3.1296E-7,13.44472,3.1248207,1.0076184,0
22567171.98,,4881,0,1.7505,4137.909,9.4E-6,1.7671461,0.038310077,1.781619,0.006773,0.29493971,0.001856,2.0765587,0.006773,0.6584082,6.6462259,0.0062301211,99.227922,0,0,1,,,,3.1423E-7,13.34082,3.1228054,1.00819,0
22567307.06,Error: Warning: Current field is 3931.009 Oe;
22567307.27,Error: but addenda was obtained at 10000.058 Oe.
22567364.44,,4881,0,1.7498,3931.009,9.3E-6,1.7674168,0.039128223,1.7785217,0.00703,0.29509657,0.001857,2.0736183,0.00703,1.2011554,6.6717053,0.0069184139,99.14696,0,0,1,,,,3.1278E-7,14,3.1237622,1.0062831,0
22567414.06,,4881,0,1.7499,3931.009,9.4E-6,1.7672819,0.038211716,1.7835061,0.006937,0.29497171,0.001856,2.0784778,0.006937,0.66393275,6.5954166,0.0046385544,99.420873,0,0,1,,,,3.1649E-7,13.34341,3.1232853,1.0091803,0
22567463.44,,4881,0,1.75,3931.009,9.3E-6,1.7670265,0.038140336,1.7711633,0.007183,0.29487725,0.001855,2.0660406,0.007183,0.4972116,6.6063897,0.006901711,99.142687,0,0,1,,,,3.1472E-7,13.19083,3.1223827,1.0023411,0
22567597.41,Error: Warning: Current field is 3724.12 Oe;
22567597.84,Error: but addenda was obtained at 10000.058 Oe.
22567654.91,,4881,0,1.7498,3724.12,9.3E-6,1.7675934,0.039008279,1.7843947,0.006741,0.29514152,0.001858,2.0795362,0.006741,1.0562762,6.6209964,0.0048296314,99.399318,0,0,1,,,,3.1548E-7,14,3.1243863,1.0095052,0
22567703.55,,4881,0,1.7504,3724.12,9.3E-6,1.7675536,0.038150231,1.7722601,0.007497,0.29506959,0.001857,2.0673297,0.007497,0.35128869,6.536476,0.0047874434,99.399709,0,0,1,,,,3.1768E-7,13.24199,3.1242457,1.0026627,0
22567752.34,,4881,0,1.7499,3724.12,9.4E-6,1.7669866,0.037989906,1.7736357,0.006908,0.29485577,0.001855,2.0684914,0.006908,0.35490009,6.6300551,0.0061656036,99.236397,0,0,1,,,,3.1375E-7,13.07295,3.1222416,1.003763,0
22567887.13,Error: Warning: Current field is 3517.217 Oe;
22567887.33,Error: but addenda was obtained at 10000.058 Oe.
22567944.33,,4881,0,1.7498,3517.217,9.2E-6,1.7678479,0.039182313,1.7633107,0.006373,0.29524116,0.001859,2.0585519,0.006373,0.764635,6.5464063,0.0055526034,99.307323,0,0,1,,,,3.1607E-7,14,3.125286,0.99743352,0
22567993.77,,4881,0,1.7501,3517.217,9.4E-6,1.766869,0.03788755,1.7671568,0.007571,0.29477381,0.001854,2.0619306,0.007571,0.44747488,6.5235634,0.0054074711,99.321284,0,0,1,,,,3.1766E-7,13.09281,3.1218261,1.0001629,0
22568042.14,,4881,0,1.75,3517.217,9.2E-6,1.7671167,0.037789347,1.776572,0.00778,0.29500487,0.001856,2.0715769,0.00778,0.48166282,6.5887824,0.0044775497,99.442076,0,0,1,,,,3.1571E-7,13.04713,3.1227016,1.0053507,0
22568314.83,Error: Warning: Current field is 3103.427 Oe;
22568315.06,Error: but addenda was obtained at 10000.058 Oe.
22568372.38,,4881,0,1.75,3103.427,9.3E-6,1.7673751,0.038404398,1.8275582,0.007909,0.29506426,0.001857,2.1226225,0.007909,0.499529,6.7397825,0.0068056255,99.152822,0,0,1,,,,3.1694E-7,14,3.1236147,1.0340523,0
22568421.06,,4881,0,1.7496,3103.427,9.4E-6,1.7671674,0.037903486,1.8203663,0.008162,0.29492615,0.001855,2.1152925,0.008162,0.47824624,6.6499691,0.0050285502,99.367845,0,0,1,,,,3.1959E-7,13.47957,3.1228805,1.0301041,0
22568469.73,,4881,0,1.7503,3103.427,9.2E-6,1.7668399,0.037752195,1.808132,0.007641,0.29479964,0.001854,2.1029316,0.007641,0.41361679,6.6636892,0.0074122822,99.072999,0,0,1,,,,3.1777E-7,13.29994,3.1217234,1.0233706,0
22568603.45,Error: Warning: Current field is 2896.531 Oe;
22568603.66,Error: but addenda was obtained at 10000.058 Oe.
22568660.69,,4881,0,1.7499,2896.531,9.3E-6,1.7668905,0.037468049,1.9070401,0.008128,0.29487225,0.001855,2.2019124,0.008128,0.78152754,6.949177,0.0073689705,99.081461,0,0,1,,,,3.1907E-7,14,3.1219022,1.0793199,0
22568709.92,,4881,0,1.7497,2896.531,9.4E-6,1.7669934,0.037822493,1.8902758,0.008296,0.29490696,0.001855,2.1851827,0.008296,0.57223847,6.8743829,0.0061278948,99.233501,0,0,1,,,,3.1971E-7,13.89835,3.1222655,1.0697696,0
22568759.09,,4881,0,1.7502,2896.531,9.2E-6,1.7669664,0.037513269,1.8995483,0.009077,0.29490464,0.001855,2.194453,0.009077,0.306123,6.9390206,0.007553935,99.059724,0,0,1,,,,3.185E-7,13.74877,3.1221702,1.0750337,0
22568893.03,Error: Warning: Current field is 2689.646 Oe;
22568893.2,Error: but addenda was obtained at 10000.058 Oe.
22568949.67,,4881,0,1.7501,2689.646,9.4E-6,1.7666206,0.037127975,1.9462985,0.007722,0.29476363,0.001854,2.2410621,0.007722,0.97963702,7.0691998,0.0061758108,99.23218,0,0,1,,,,3.1887E-7,14,3.1209484,1.1017071,0
22568999.31,,4881,0,1.75,2689.646,9.3E-6,1.7673198,0.037659336,1.9524025,0.007913,0.29495683,0.001856,2.2473594,0.007913,0.37085975,7.0601533,0.0049892601,99.378236,0,0,1,,,,3.1982E-7,14.1384,3.1234192,1.1047251,0
22569048.89,,4881,0,1.75,2689.646,9.3E-6,1.7668201,0.037690903,1.9485117,0.008301,0.29475792,0.001854,2.2432697,0.008301,0.35161448,7.0826003,0.0056165111,99.302695,0,0,1,,,,3.1841E-7,14.12031,3.1216532,1.1028354,0
22569181.52,Error: Warning: Current field is 2482.738 Oe;
22569181.81,Error: but addenda was obtained at 10000.058 Oe.
22569238.45,,4881,0,1.7499,2482.738,9.4E-6,1.7667095,0.036872125,1.979363,0.008293,0.29480653,0.001854,2.2741695,0.008293,1.1700438,7.1832789,0.0050851192,99.370522,0,0,1,,,,3.1811E-7,14,3.1212624,1.120367,0
22569294.61,,4881,0,1.7499,2482.738,9.4E-6,1.7672885,0.03783706,1.9762809,0.007983,0.29496789,0.001856,2.2712488,0.007983,0.86415282,7.1481871,0.0046107628,99.427507,0,0,1,,,,3.1912E-7,14.36656,3.1233086,1.118256,0
22569344.59,,4881,0,1.7498,2482.738,9.3E-6,1.7670237,0.037699896,1.9724823,0.008637,0.29486272,0.001855,2.267345,0.008637,0.25228547,7.1660449,0.0059490673,99.263404,0,0,1,,,,3.1818E-7,14.29637,3.1223729,1.1162738,0
22569478.5,Error: Warning: Current field is 2275.836 Oe;
22569478.63,Error: but addenda was obtained at 10000.058 Oe.
22569536.39,,4881,0,1.7496,2275.836,9.4E-6,1.7663805,0.036787118,1.9959831,0.008654,0.29469726,0.001853,2.2906804,0.008654,0.85795268,7.3070611,0.0062392985,99.235237,0,0,1,,,,3.1532E-7,14,3.1201,1.1299848,0
22569586.47,,4881,0,1.7501,2275.836,9.4E-6,1.7674693,0.038123833,1.9899092,0.008168,0.29508949,0.001857,2.2849987,0.008168,0.54881812,7.2578912,0.0066408224,99.182951,0,0,1,,,,3.168E-7,14.61412,3.1239479,1.1258522,0
22569636.39,,4881,0,1.7499,2275.836,9.2E-6,1.7670072,0.037990166,1.9870181,0.008583,0.29489282,0.001855,2.281911,0.008583,0.23969206,7.2660531,0.0066494084,99.183294,0,0,1,,,,3.1601E-7,14.51578,3.1223145,1.1245105,0
22569768.11,Error: Warning: Current field is 2068.954 Oe;
22569768.27,Error: but addenda was obtained at 10000.058 Oe.
22569824.44,,4881,0,1.75,2068.954,9.2E-6,1.7666774,0.036729129,2.0003689,0.008167,0.29480029,0.001854,2.2951692,0.008167,1.1065276,7.2706705,0.0043969369,99.458253,0,0,1,,,,3.1698E-7,14,3.121149,1.1322774,0
22569873.45,,4881,0,1.7501,2068.954,9.3E-6,1.7675645,0.037803112,2.0144373,0.007635,0.29510582,0.001857,2.3095431,0.007635,0.37570108,7.2788591,0.0040063653,99.504851,0,0,1,,,,3.185E-7,14.54134,3.1242842,1.1396683,0
22569922.42,,4881,0,1.7503,2068.954,9.3E-6,1.7673264,0.03794557,2.000013,0.008025,0.29502205,0.001856,2.2950351,0.008025,0.30007489,7.267773,0.0061971071,99.235783,0,0,1,,,,3.1763E-7,14.55772,3.1234426,1.1316602,0
22570054.14,Error: Warning: Current field is 1862.051 Oe;
22570054.27,Error: but addenda was obtained at 10000.058 Oe.
22570111.81,,4881,0,1.7501,1862.051,9.3E-6,1.7665524,0.036729257,2.006065,0.00869,0.29478252,0.001854,2.3008475,0.00869,0.83634601,7.3699822,0.0068856678,99.15991,0,0,1,,,,3.142E-7,14,3.1207074,1.1355819,0
22570160.36,,4881,0,1.75,1862.051,9.3E-6,1.7673372,0.038037204,2.0226207,0.008459,0.29504985,0.001857,2.3176706,0.008459,0.40065054,7.3782766,0.005546824,99.320893,0,0,1,,,,3.1576E-7,14.73996,3.1234808,1.1444453,0
22570210.38,,4881,0,1.7498,1862.051,9.2E-6,1.767109,0.038240767,2.0138053,0.008388,0.29497438,0.001856,2.3087797,0.008388,0.46591563,7.392539,0.0070078105,99.14551,0,0,1,,,,3.1436E-7,14.75655,3.1226743,1.1396044,0
22570342.81,Error: Warning: Current field is 1655.137 Oe;
22570342.94,Error: but addenda was obtained at 10000.058 Oe.
22570399.22,,4881,0,1.7504,1655.137,9.4E-6,1.7663326,0.036659715,2.0230275,0.008856,0.29472179,0.001853,2.3177492,0.008856,1.4577826,7.5075954,0.0081058816,99.02216,0,0,1,,,,3.1105E-7,14,3.119931,1.1453264,0
22570448.98,,4881,0,1.7499,1655.137,9.3E-6,1.7674968,0.038447621,2.0203944,0.008594,0.29512541,0.001857,2.3155198,0.008594,0.26774816,7.3416386,0.0053721897,99.339728,0,0,1,,,,3.1699E-7,15.01519,3.1240451,1.1430823,0
22570498.7,,4881,0,1.7499,1655.137,9.3E-6,1.7670005,0.037872439,2.0269967,0.007957,0.29490011,0.001855,2.3218968,0.007957,0.27220543,7.3592277,0.0058336814,99.282345,0,0,1,,,,3.1725E-7,14.68328,3.1222907,1.1471399,0
22570630.36,Error: Warning: Current field is 1448.265 Oe;
22570630.5,Error: but addenda was obtained at 10000.058 Oe.
22570688.3,,4881,0,1.7501,1448.265,9.3E-6,1.7661649,0.036516708,2.0258577,0.008408,0.29460121,0.001852,2.3204589,0.008408,1.0168436,7.3786751,0.0048591152,99.403995,0,0,1,,,,3.1592E-7,14,3.1193383,1.1470377,0
22570737.55,,4881,0,1.75,1448.265,9.2E-6,1.7673685,0.038000183,2.024336,0.008104,0.29505913,0.001857,2.3193951,0.008104,0.42471095,7.3518959,0.0061249789,99.24666,0,0,1,,,,3.1731E-7,14.75735,3.1235914,1.1453955,0
22570787.97,,4881,0,1.7498,1448.265,9.2E-6,1.7673147,0.03802104,2.0165137,0.008232,0.29503576,0.001857,2.3115495,0.008232,0.29921033,7.3510562,0.0058411692,99.283661,0,0,1,,,,3.1618E-7,14.70379,3.1234012,1.1410043,0
22570918.53,Error: Warning: Current field is 1241.364 Oe;
22570918.72,Error: but addenda was obtained at 10000.058 Oe.
22570976.17,,4881,0,1.7501,1241.364,9.2E-6,1.7664323,0.036299407,2.0345157,0.008918,0.29469897,0.001853,2.3292147,0.008918,0.70248233,7.3457983,0.0052934755,99.345684,0,0,1,,,,3.1868E-7,14,3.120283,1.1517655,0
22571026.47,,4881,0,1.7498,1241.364,9.3E-6,1.7670707,0.037931046,2.0253771,0.008127,0.2949108,0.001855,2.3202879,0.008127,0.53407305,7.3199904,0.0034670481,99.572127,0,0,1,,,,3.1802E-7,14.6916,3.122539,1.1461777,0
22571076.88,,4881,0,1.75,1241.364,9.4E-6,1.7670561,0.037852304,2.0278883,0.008889,0.2949246,0.001855,2.3228129,0.008889,0.33257771,7.382549,0.0053642289,99.342215,0,0,1,,,,3.1622E-7,14.63998,3.1224872,1.1476084,0
22571207.95,Error: Warning: Current field is 1034.468 Oe;
22571208.23,Error: but addenda was obtained at 10000.058 Oe.
22571265.69,,4881,0,1.7502,1034.468,9.4E-6,1.7665573,0.036339617,2.042115,0.008315,0.29474847,0.001854,2.3368635,0.008315,1.158319,7.3798965,0.003438868,99.576284,0,0,1,,,,3.1768E-7,14,3.1207246,1.1559857,0
22571315.28,,4881,0,1.75,1034.468,9.3E-6,1.767535,0.0381864,2.0201319,0.008897,0.29514458,0.001858,2.3152765,0.008897,0.28905415,7.3937478,0.0060188331,99.265282,0,0,1,,,,3.1491E-7,14.75979,3.1241801,1.1429091,0
22571365.17,,4881,0,1.7496,1034.468,9.2E-6,1.7673798,0.037922237,2.0388994,0.008935,0.29505749,0.001857,2.3339569,0.008935,0.31680016,7.3769777,0.0046343327,99.429435,0,0,1,,,,3.1777E-7,14.7875,3.1236313,1.1536284,0
22571495.59,Error: Warning: Current field is 827.582 Oe;
22571495.7,Error: but addenda was obtained at 10000.058 Oe.
22571553.38,,4881,0,1.7501,827.582,9.2E-6,1.7667086,0.036456978,2.0390135,0.008287,0.29483877,0.001855,2.3338522,0.008287,0.95920642,7.4490405,0.0049004014,99.40207,0,0,1,,,,3.1475E-7,14,3.1212593,1.1541312,0
22571602.94,,4881,0,1.7497,827.582,9.4E-6,1.7678362,0.038045768,2.0393873,0.008566,0.29526497,0.001859,2.3346523,0.008566,0.45032293,7.3941565,0.0060998225,99.250297,0,0,1,,,,3.1756E-7,14.89808,3.1252447,1.1536065,0
22571653.5,,4881,0,1.7499,827.582,9.3E-6,1.7677007,0.037806826,2.044742,0.008603,0.29519021,0.001858,2.3399322,0.008603,0.28750264,7.3738723,0.0054047732,99.332751,0,0,1,,,,3.1896E-7,14.78831,3.1247659,1.1567241,0
22571784.19,Error: Warning: Current field is 620.673 Oe;
22571784.39,Error: but addenda was obtained at 10000.058 Oe.
22571841.36,,4881,0,1.7503,620.673,9.3E-6,1.7670563,0.036453556,2.0291133,0.00814,0.29497967,0.001856,2.324093,0.00814,0.84448401,7.3970849,0.0059223342,99.274718,0,0,1,,,,3.1594E-7,14,3.1224881,1.1483014,0
22571891.33,,4881,0,1.7501,620.673,9.2E-6,1.7677844,0.038033464,2.0317988,0.008119,0.29522588,0.001858,2.3270247,0.008119,0.37171154,7.3561304,0.0044659771,99.450339,0,0,1,,,,3.1767E-7,14.79417,3.1250617,1.1493476,0
22571941.58,,4881,0,1.7503,620.673,9.3E-6,1.7677668,0.037838063,2.0333034,0.007926,0.29521747,0.001858,2.3285209,0.007926,0.36529153,7.3566016,0.0057583407,99.290311,0,0,1,,,,3.1825E-7,14.71226,3.1249994,1.1502102,0
22572070.45,Error: Warning: Current field is 413.77 Oe;
22572070.63,Error: but addenda was obtained at 10000.058 Oe.
22572127.56,,4881,0,1.7501,413.77,9.2E-6,1.767213,0.036385332,2.0400137,0.009111,0.29505571,0.001857,2.3350694,0.009111,1.2131246,7.4514166,0.0064756512,99.209446,0,0,1,,,,3.1528E-7,14,3.1230419,1.1543677,0
22572178.36,,4881,0,1.7499,413.77,9.4E-6,1.7681003,0.038102386,2.0425867,0.008039,0.29537994,0.00186,2.3379667,0.008039,0.43001052,7.4143151,0.0057474225,99.295076,0,0,1,,,,3.1704E-7,14.90283,3.1261787,1.1552437,0
22572228.48,,4881,0,1.7503,413.77,9.4E-6,1.7681926,0.03785682,2.043584,0.008461,0.29537436,0.00186,2.3389583,0.008461,0.251792,7.3203265,0.003145538,99.609752,0,0,1,,,,3.2047E-7,14.82863,3.1265051,1.1557474,0
22572356.41,Error: Warning: Current field is 206.887 Oe;
22572356.56,Error: but addenda was obtained at 10000.058 Oe.
22572413.3,,4881,0,1.75,206.887,9.3E-6,1.7672501,0.03641803,2.0412471,0.007756,0.29506225,0.001857,2.3363094,0.007756,0.79591635,7.4404665,0.0050784942,99.379394,0,0,1,,,,3.155E-7,14,3.1231731,1.1550414,0
22572463.22,,4881,0,1.7501,206.887,9.4E-6,1.7682006,0.037987478,2.0472675,0.008347,0.29540903,0.00186,2.3426765,0.008347,0.43196752,7.3905668,0.0051931163,99.360187,0,0,1,,,,3.1854E-7,14.88093,3.1265335,1.1578253,0
22572513.53,,4881,0,1.75,206.887,9.4E-6,1.7683261,0.037974809,2.0355506,0.008861,0.29547447,0.001861,2.3310251,0.008861,0.50798096,7.4138018,0.0067801785,99.170143,0,0,1,,,,3.1643E-7,14.78113,3.1269774,1.1511172,0
22572641.27,Error: Warning: Current field is -0.011 Oe;
22572641.38,Error: but addenda was obtained at 10000.058 Oe.
22572697.88,,4881,0,1.7501,-0.011,9.2E-6,1.7678716,0.036551466,2.032436,0.008799,0.29533828,0.001859,2.3277743,0.008799,0.67473106,7.4483654,0.006571975,99.200129,0,0,1,,,,3.1444E-7,14,3.1253699,1.1496514,0
22572748.75,,4881,0,1.7504,-0.011,9.3E-6,1.7690958,0.038352813,2.0254577,0.009102,0.29579872,0.001864,2.3212564,0.009102,0.20743522,7.3856358,0.0053070952,99.351546,0,0,1,,,,3.1586E-7,14.89673,3.1296999,1.1449112,0
22572799.27,,4881,0,1.75,-0.011,9.4E-6,1.7688852,0.03795503,2.0375386,0.008239,0.29571245,0.001863,2.333251,0.008239,0.40076872,7.4354396,0.0068644066,99.162136,0,0,1,,,,3.1583E-7,14.77127,3.128955,1.1518772,0
22572966.33,Error: Warning: Current field is 0.004 Oe;
22572966.52,Error: but addenda was obtained at 10000.058 Oe.
22573171.73,,4881,0,1.5,0.004,9.3E-6,1.5152113,0.030062372,1.7783654,0.00709,0.20640293,0.00122,1.9847683,0.00709,0.75382067,7.8422855,0.0062190719,99.144469,0,0,1,,,,2.5484E-7,14,2.2958652,1.1736749,0
22573224.05,,4881,0,1.5001,0.004,9.4E-6,1.5168426,0.032525663,1.7733407,0.006385,0.20683373,0.001219,1.9801745,0.006385,0.20627202,7.7021994,0.0052902927,99.262423,0,0,1,,,,2.5863E-7,15.68457,2.3008115,1.1691,0
22573275.42,,4881,0,1.4999,0.004,9.3E-6,1.5165665,0.032204312,1.7783786,0.006373,0.20674782,0.001219,1.9851264,0.006373,0.29239094,7.7813781,0.0050988333,99.29467,0,0,1,,,,2.5657E-7,15.4044,2.2999739,1.1726348,0
22573404.13,Error: Warning: Current field is 205.134 Oe;
22573404.23,Error: but addenda was obtained at 10000.058 Oe.
22573461.31,,4881,0,1.5002,205.134,9.3E-6,1.5142779,0.030134127,1.7701049,0.006472,0.2061114,0.00122,1.9762163,0.006472,1.1894977,7.813589,0.0052920925,99.271766,0,0,1,,,,2.5441E-7,14,2.2930376,1.1689432,0
22573511.97,,4881,0,1.4999,205.134,9.4E-6,1.5156837,0.032379136,1.783797,0.007263,0.20646973,0.00122,1.9902667,0.007263,0.17009345,7.7426347,0.0031559713,99.56043,0,0,1,,,,2.5796E-7,15.62718,2.2972972,1.1768926,0
22573564.13,,4881,0,1.5003,205.134,9.4E-6,1.5156484,0.032182826,1.7824542,0.006156,0.20646589,0.00122,1.9889201,0.006156,0.27971342,7.777082,0.0056100391,99.220915,0,0,1,,,,2.5736E-7,15.48527,2.2971902,1.1760341,0
22573692.94,Error: Warning: Current field is 410.267 Oe;
22573693.08,Error: but addenda was obtained at 10000.058 Oe.
22573750.06,,4881,0,1.4999,410.267,9.3E-6,1.5138069,0.03003492,1.7767136,0.006536,0.20596147,0.00122,1.982675,0.006536,1.1474725,7.8132117,0.0048831577,99.325849,0,0,1,,,,2.5514E-7,14,2.2916113,1.1736725,0
22573801.36,,4881,0,1.4996,410.267,9.2E-6,1.5152375,0.032447726,1.7776186,0.006983,0.2063434,0.00122,1.983962,0.006983,0.2796851,7.7615547,0.0049614047,99.311161,0,0,1,,,,2.5704E-7,15.62642,2.2959446,1.1731617,0
22573852.47,,4881,0,1.4998,410.267,9.3E-6,1.5152821,0.032314296,1.7757267,0.005993,0.20635653,0.00122,1.9820832,0.005993,0.30612527,7.781726,0.0052552282,99.272738,0,0,1,,,,2.5621E-7,15.52311,2.2960799,1.1718786,0
22573982.41,Error: Warning: Current field is 615.386 Oe;
22573982.77,Error: but addenda was obtained at 10000.058 Oe.
22574040.45,,4881,0,1.5,615.386,9.3E-6,1.5138508,0.030047745,1.7735311,0.006922,0.20597457,0.00122,1.9795057,0.006922,0.89277646,7.7959215,0.0051327917,99.290707,0,0,1,,,,2.5537E-7,14,2.2917443,1.1715363,0
22574091.88,,4881,0,1.5001,615.386,9.2E-6,1.5148636,0.032288116,1.7768733,0.006914,0.20621753,0.00122,1.9830908,0.006914,0.18976893,7.7181579,0.0047808552,99.332482,0,0,1,,,,2.5833E-7,15.59184,2.2948117,1.1729592,0
22574142.8,,4881,0,1.5,615.386,9.3E-6,1.5147436,0.032148244,1.7785487,0.006608,0.20619018,0.00122,1.9847389,0.006608,0.30096003,7.8030747,0.0057457647,99.205189,0,0,1,,,,2.5599E-7,15.43632,2.2944483,1.1741583,0
22574272.39,Error: Warning: Current field is 820.524 Oe;
22574272.61,Error: but addenda was obtained at 10000.058 Oe.
22574329.95,,4881,0,1.4997,820.524,9.2E-6,1.513373,0.030014778,1.775331,0.0069,0.20583111,0.00122,1.9811621,0.0069,0.49950624,7.8152976,0.0056790837,99.215735,0,0,1,,,,2.5511E-7,14,2.2902978,1.1730955,0
22574381.19,,4881,0,1.4999,820.524,9.2E-6,1.5146342,0.032312417,1.7821196,0.006851,0.20614908,0.00122,1.9882687,0.006851,0.36782536,7.7423702,0.0043161938,99.397919,0,0,1,,,,2.5805E-7,15.6306,2.2941167,1.1766007,0
22574431.92,,4881,0,1.5001,820.524,9.3E-6,1.5144208,0.032206579,1.7779499,0.006012,0.20608668,0.00122,1.9840366,0.006012,0.2904835,7.7677831,0.0052402323,99.27203,0,0,1,,,,2.5692E-7,15.48474,2.2934704,1.1740131,0
22574561.22,Error: Warning: Current field is 1025.656 Oe;
22574561.41,Error: but addenda was obtained at 10000.058 Oe.
22574619.86,,4881,0,1.4999,1025.656,9.2E-6,1.5127234,0.030138508,1.7665441,0.006663,0.20564011,0.001221,1.9721842,0.006663,0.65666201,7.8394758,0.0060078647,99.175331,0,0,1,,,,2.5325E-7,14,2.2883319,1.1677906,0
22574671.33,,4881,0,1.5001,1025.656,9.4E-6,1.5139286,0.032484256,1.7708909,0.007157,0.20594653,0.00122,1.9768374,0.007157,0.28990765,7.7738779,0.0057226703,99.207397,0,0,1,,,,2.5592E-7,15.67895,2.2919798,1.1697321,0
22574722.16,,4881,0,1.4999,1025.656,9.2E-6,1.5144162,0.032244695,1.7748582,0.006715,0.20607796,0.00122,1.9809362,0.006715,0.45622849,7.7233647,0.0043987896,99.386668,0,0,1,,,,2.5776E-7,15.54776,2.2934565,1.1719752,0
22574853.05,Error: Warning: Current field is 1230.781 Oe;
22574853.36,Error: but addenda was obtained at 10000.058 Oe.
22574909.38,,4881,0,1.5002,1230.781,9.4E-6,1.5124298,0.030074072,1.7698935,0.006466,0.20553939,0.001221,1.9754329,0.006466,0.83769839,7.8009308,0.0050007886,99.309438,0,0,1,,,,2.5464E-7,14,2.287444,1.1702318,0
22574960.23,,4881,0,1.4996,1230.781,9.2E-6,1.5139659,0.03237304,1.7714783,0.007204,0.20595726,0.00122,1.9774356,0.007204,0.17912249,7.7713456,0.0065560631,99.09082,0,0,1,,,,2.5633E-7,15.60186,2.2920928,1.1700913,0
22575010.73,,4881,0,1.4995,1230.781,9.2E-6,1.5137466,0.032395326,1.7693459,0.006342,0.20588998,0.00122,1.9752358,0.006342,0.20307096,7.7854015,0.0059128057,99.182538,0,0,1,,,,2.5539E-7,15.54269,2.2914288,1.1688521,0
22575142.31,Error: Warning: Current field is 1435.916 Oe;
22575142.5,Error: but addenda was obtained at 10000.058 Oe.
22575199.86,,4881,0,1.4997,1435.916,9.3E-6,1.5124167,0.030175025,1.7642977,0.006977,0.20554527,0.001221,1.969843,0.006977,0.93930645,7.8378936,0.0055603385,99.237389,0,0,1,,,,2.5287E-7,14,2.2874042,1.1665421,0
22575251.89,,4881,0,1.5003,1435.916,9.4E-6,1.5140459,0.032526643,1.7684066,0.006347,0.20598268,0.00122,1.9743892,0.006347,0.24550016,7.7633127,0.0057600074,99.202115,0,0,1,,,,2.5597E-7,15.67579,2.2923349,1.1680007,0
22575303.14,,4881,0,1.4998,1435.916,9.2E-6,1.513314,0.032411877,1.7642164,0.006848,0.20577243,0.00122,1.9699888,0.006848,0.380993,7.8389006,0.0081767397,98.877226,0,0,1,,,,2.536E-7,15.52663,2.2901191,1.1657967,0
22575434.47,Error: Warning: Current field is 1641.052 Oe;
22575434.7,Error: but addenda was obtained at 10000.058 Oe.
22575491.11,,4881,0,1.5004,1641.052,9.3E-6,1.5122853,0.030130837,1.7607663,0.006577,0.20550417,0.001221,1.9662704,0.006577,0.65803686,7.8052003,0.0065899819,99.09288,0,0,1,,,,2.5377E-7,14,2.2870069,1.1643082,0
22575541.7,,4881,0,1.4999,1641.052,9.3E-6,1.5138321,0.032363941,1.7738238,0.005961,0.20590665,0.00122,1.9797304,0.005961,0.22125777,7.7440681,0.0049219724,99.315119,0,0,1,,,,2.5706E-7,15.6104,2.2916877,1.171744,0
22575593.09,,4881,0,1.5002,1641.052,9.3E-6,1.5135244,0.032295837,1.7703229,0.006421,0.20581213,0.00122,1.976135,0.006421,0.1707141,7.7582046,0.0050153667,99.304187,0,0,1,,,,2.5615E-7,15.48814,2.2907562,1.1696692,0
22575724.31,Error: Warning: Current field is 1846.165 Oe;
22575724.42,Error: but addenda was obtained at 10000.058 Oe.
22575782.78,,4881,0,1.5002,1846.165,9.3E-6,1.512136,0.030061499,1.7643561,0.006659,0.20544127,0.001221,1.9697974,0.006659,0.89256322,7.7372688,0.004861486,99.324639,0,0,1,,,,2.5598E-7,14,2.2865553,1.1667972,0
22575834.17,,4881,0,1.4998,1846.165,9.2E-6,1.513395,0.032242694,1.7693288,0.00615,0.20577645,0.00122,1.9751052,0.00615,0.52060641,7.7806729,0.0058340729,99.192636,0,0,1,,,,2.5551E-7,15.47454,2.2903644,1.1691124,0
22575885.45,,4881,0,1.5001,1846.165,9.2E-6,1.5133955,0.032531276,1.7544106,0.005813,0.20577849,0.00122,1.9601891,0.005813,0.33214699,7.7164264,0.00610215,99.154015,0,0,1,,,,2.5577E-7,15.56135,2.2903658,1.1592546,0
22576016.73,Error: Warning: Current field is 2051.297 Oe;
22576017,Error: but addenda was obtained at 10000.058 Oe.
22576073.69,,4881,0,1.5003,2051.297,9.4E-6,1.5122451,0.030114721,1.7624392,0.006519,0.20546775,0.001221,1.967907,0.006519,0.82452654,7.7087963,0.0035067244,99.512075,0,0,1,,,,2.5629E-7,14,2.2868851,1.1654455,0
22576125.08,,4881,0,1.5001,2051.297,9.3E-6,1.513364,0.032278259,1.7578512,0.006339,0.20575255,0.00122,1.9636038,0.006339,0.20574575,7.6768683,0.0050867011,99.29058,0,0,1,,,,2.5725E-7,15.41759,2.2902706,1.1615521,0
22576175.86,,4881,0,1.4998,2051.297,9.3E-6,1.513356,0.032126163,1.7605379,0.006491,0.20574002,0.00122,1.9662779,0.006491,0.32749462,7.6568799,0.0042464919,99.405885,0,0,1,,,,2.5803E-7,15.35374,2.2902464,1.1633336,0
22576308.5,Error: Warning: Current field is 2256.428 Oe;
22576308.77,Error: but addenda was obtained at 10000.058 Oe.
22576366.98,,4881,0,1.4997,2256.428,9.3E-6,1.5123001,0.030098141,1.7663323,0.007024,0.20549933,0.001221,1.9718317,0.007024,0.80921086,7.7846437,0.0051584817,99.287104,0,0,1,,,,2.5476E-7,14,2.2870517,1.1679774,0
22576418.3,,4881,0,1.5001,2256.428,9.4E-6,1.5135361,0.03249395,1.7557283,0.006177,0.20582001,0.00122,1.9615483,0.006177,0.29081259,7.7234767,0.0057208706,99.207513,0,0,1,,,,2.556E-7,15.56929,2.2907916,1.1600174,0
22576468.27,,4881,0,1.4999,2256.428,9.3E-6,1.5135251,0.032275672,1.7643728,0.006693,0.2058094,0.00122,1.9701822,0.006693,0.20093913,7.7341747,0.0051998349,99.278161,0,0,1,,,,2.5622E-7,15.44695,2.2907581,1.1657374,0
22576600.8,Error: Warning: Current field is 2461.563 Oe;
22576601.06,Error: but addenda was obtained at 10000.058 Oe.
22576658.02,,4881,0,1.5002,2461.563,9.3E-6,1.5124345,0.030185086,1.7565769,0.006454,0.20553255,0.001221,1.9621094,0.006454,0.66824385,7.7224757,0.0041800144,99.420777,0,0,1,,,,2.5526E-7,14,2.287458,1.1614235,0
22576709.09,,4881,0,1.5,2461.563,9.3E-6,1.5137104,0.032346903,1.7554618,0.006808,0.20586388,0.00122,1.9613257,0.006808,0.21759849,7.6951069,0.005269279,99.267861,0,0,1,,,,2.5639E-7,15.44495,2.2913193,1.1597078,0
22576759.92,,4881,0,1.5001,2461.563,9.3E-6,1.5135756,0.032255757,1.7547429,0.006191,0.20581292,0.00122,1.9605558,0.006191,0.27612694,7.6565007,0.0047086424,99.342845,0,0,1,,,,2.5742E-7,15.39021,2.2909111,1.1593361,0
22576893.13,Error: Warning: Current field is 2666.69 Oe;
22576893.39,Error: but addenda was obtained at 10000.058 Oe.
22576949.95,,4881,0,1.5003,2666.69,9.4E-6,1.5124242,0.030138891,1.7530605,0.006737,0.20552596,0.001221,1.9585864,0.006737,0.96555764,7.6748343,0.0050182478,99.300888,0,0,1,,,,2.5664E-7,14,2.2874269,1.1591064,0
22577001.28,,4881,0,1.5,2666.69,9.3E-6,1.5135718,0.032205111,1.7497677,0.005974,0.20580495,0.00122,1.9555727,0.005974,0.4436483,7.6082226,0.0049192588,99.310489,0,0,1,,,,2.5846E-7,15.34967,2.2908996,1.156052,0
22577052.28,,4881,0,1.5001,2666.69,9.2E-6,1.5135115,0.032118873,1.7452136,0.007203,0.20579499,0.00122,1.9510086,0.007203,0.23274288,7.6549749,0.0064410776,99.103379,0,0,1,,,,2.5671E-7,15.21645,2.2907172,1.1530891,0
22577185.63,Error: Warning: Current field is 2871.802 Oe;
22577185.91,Error: but addenda was obtained at 10000.058 Oe.
22577243.06,,4881,0,1.5002,2871.802,9.3E-6,1.5125736,0.030118958,1.7395658,0.006165,0.20554643,0.001221,1.9451123,0.006165,1.0251744,7.4947374,0.0040015772,99.433111,0,0,1,,,,2.6071E-7,14,2.2878789,1.1500702,0
22577293.02,,4881,0,1.4997,2871.802,9.3E-6,1.513346,0.031961044,1.7242537,0.006357,0.20577972,0.00122,1.9300334,0.006357,0.3281309,7.4861563,0.005156876,99.273645,0,0,1,,,,2.5932E-7,14.98947,2.2902162,1.1393651,0
22577343.22,,4881,0,1.5,2871.802,9.2E-6,1.5132868,0.031939837,1.726964,0.006605,0.205776,0.00122,1.93274,0.006605,0.24833838,7.5662376,0.0065040375,99.09145,0,0,1,,,,2.5731E-7,14.97231,2.290037,1.1412007,0
22577477.3,Error: Warning: Current field is 3076.94 Oe;
22577477.56,Error: but addenda was obtained at 10000.058 Oe.
22577534.06,,4881,0,1.5004,3076.94,9.2E-6,1.5123722,0.030510334,1.7053972,0.006344,0.20550219,0.001221,1.9108994,0.006344,0.66506962,7.4584308,0.0061235282,99.140152,0,0,1,,,,2.5798E-7,14,2.2872696,1.1276306,0
22577584.89,,4881,0,1.4998,3076.94,9.4E-6,1.5136087,0.032246983,1.6796077,0.007188,0.20585175,0.00122,1.8854594,0.007188,0.16798837,7.3219396,0.0060728917,99.14287,0,0,1,,,,2.5928E-7,14.91686,2.2910114,1.109671,0
22577635.09,,4881,0,1.4998,3076.94,9.4E-6,1.5134277,0.031776884,1.6841227,0.006958,0.20578105,0.00122,1.8899038,0.006958,0.32283104,7.3128834,0.0062628148,99.112704,0,0,1,,,,2.6027E-7,14.64388,2.2904635,1.112787,0
22577768.8,Error: Warning: Current field is 3282.079 Oe;
22577768.95,Error: but addenda was obtained at 10000.058 Oe.
22577825.86,,4881,0,1.5003,3282.079,9.4E-6,1.5130294,0.031096984,1.6380305,0.005813,0.2056617,0.001221,1.8436922,0.005813,0.72978871,7.0582582,0.0031183869,99.553046,0,0,1,,,,2.6214E-7,14,2.2892579,1.0826164,0
22577876.72,,4881,0,1.5,3282.079,9.2E-6,1.5139307,0.031740106,1.6237103,0.006561,0.20589125,0.00122,1.8296016,0.006561,0.26189023,7.0412764,0.0042446698,99.394266,0,0,1,,,,2.6109E-7,14.11652,2.2919861,1.072513,0
22577925.59,,4881,0,1.4999,3282.079,9.4E-6,1.5136106,0.031739471,1.6179767,0.006572,0.20587117,0.00122,1.8238479,0.006572,0.40015543,7.068389,0.0054285616,99.229611,0,0,1,,,,2.5961E-7,14.08255,2.2910171,1.0689517,0
22578059.44,Error: Warning: Current field is 3487.215 Oe;
22578059.63,Error: but addenda was obtained at 10000.058 Oe.
22578116.78,,4881,0,1.4998,3487.215,9.3E-6,1.5132997,0.031901214,1.5883826,0.006104,0.20580114,0.00122,1.7941837,0.006104,0.71007249,7.154382,0.0077074997,98.932584,0,0,1,,,,2.529E-7,14,2.2900761,1.0496153,0
22578166.55,,4881,0,1.4998,3487.215,9.2E-6,1.514197,0.032716334,1.5806818,0.005667,0.20602175,0.00122,1.7867036,0.005667,0.50840615,7.0932951,0.0076962791,98.929865,0,0,1,,,,2.5402E-7,14.30876,2.2927924,1.0439077,0
22578216.73,,4881,0,1.5002,3487.215,9.2E-6,1.5136855,0.032377698,1.5909903,0.0056,0.20583942,0.00122,1.7968297,0.0056,0.68908661,7.0414634,0.0054897027,99.227988,0,0,1,,,,2.5674E-7,14.18659,2.2912437,1.0510706,0
22578350.36,Error: Warning: Current field is 3692.335 Oe;
22578350.63,Error: but addenda was obtained at 10000.058 Oe.
22578407.36,,4881,0,1.5002,3692.335,9.2E-6,1.5133837,0.031830291,1.5893963,0.005702,0.20580679,0.00122,1.7952031,0.005702,1.1570394,7.0784309,0.005737965,99.197673,0,0,1,,,,2.5523E-7,14,2.2903302,1.0502269,0
22578460.25,,4881,0,1.5002,3692.335,9.4E-6,1.5139822,0.032509185,1.5798533,0.005723,0.20593931,0.00122,1.7857926,0.005723,0.58441336,7.0624987,0.0060487501,99.156465,0,0,1,,,,2.5454E-7,14.15686,2.2921422,1.0435085,0
22578513.69,,4881,0,1.5,3692.335,9.3E-6,1.513826,0.032208022,1.5868102,0.005399,0.20588045,0.00122,1.7926907,0.005399,0.79518005,7.0511054,0.0059669176,99.163546,0,0,1,,,,2.5592E-7,14.125,2.2916692,1.0482117,0
22578648,Error: Warning: Current field is 3897.472 Oe;
22578648.36,Error: but addenda was obtained at 10000.058 Oe.
22578705.63,,4881,0,1.4998,3897.472,9.3E-6,1.5133644,0.031863526,1.5872863,0.005553,0.20578852,0.00122,1.7930748,0.005553,1.2041777,7.0184557,0.0043426839,99.388843,0,0,1,,,,2.5671E-7,14,2.2902719,1.048846,0
22578754.7,,4881,0,1.4999,3897.472,9.3E-6,1.5138588,0.032225436,1.5843099,0.005652,0.20595726,0.00122,1.7902672,0.005652,0.48749342,7.0215314,0.005577262,99.216297,0,0,1,,,,2.5655E-7,14.03691,2.2917686,1.0465374,0
22578812.03,,4881,0,1.4996,3897.472,9.3E-6,1.5137238,0.032222067,1.5875206,0.006255,0.20592634,0.00122,1.7934469,0.006255,0.31268888,7.068912,0.0066495392,99.069536,0,0,1,,,,2.5558E-7,14.04306,2.2913597,1.0487518,0
22578946.66,Error: Warning: Current field is 4102.595 Oe;
22578946.83,Error: but addenda was obtained at 10000.058 Oe.
22579003.81,,4881,0,1.5,4102.595,9.4E-6,1.51371,0.031873914,1.5873898,0.005468,0.2058973,0.00122,1.7932871,0.005468,0.85047064,7.0378173,0.0042913958,99.39797,0,0,1,,,,2.5602E-7,14,2.2913181,1.048675,0
22579052.81,,4881,0,1.5003,4102.595,9.3E-6,1.513455,0.032302188,1.5835889,0.006011,0.20583596,0.00122,1.7894248,0.006011,0.77550113,7.0213114,0.0056410334,99.207187,0,0,1,,,,2.5645E-7,14.07563,2.2905459,1.0463403,0
22579101.91,,4881,0,1.5,4102.595,9.3E-6,1.5139782,0.032358411,1.5845637,0.006051,0.20600758,0.00122,1.7905713,0.006051,0.27354967,7.0787921,0.0059989858,99.163657,0,0,1,,,,2.5462E-7,14.04262,2.29213,1.0466225,0
22579235.13,Error: Warning: Current field is 4307.725 Oe;
22579235.47,Error: but addenda was obtained at 10000.058 Oe.
22579293.25,,4881,0,1.5002,4307.725,9.4E-6,1.513617,0.031789197,1.5929139,0.005797,0.20587636,0.00122,1.7987902,0.005797,0.548958,7.0728253,0.0057350642,99.196272,0,0,1,,,,2.5594E-7,14,2.2910364,1.052389,0
22579344.17,,4881,0,1.5,4307.725,9.2E-6,1.5139095,0.032178612,1.5961044,0.005347,0.2058922,0.00122,1.8019966,0.005347,0.36077198,7.0041782,0.0040928958,99.420677,0,0,1,,,,2.5845E-7,14.14565,2.291922,1.0542931,0
22579393.09,,4881,0,1.4999,4307.725,9.4E-6,1.514096,0.031972434,1.6004444,0.005481,0.20602014,0.00122,1.8064646,0.005481,0.63532109,7.0401982,0.0044787368,99.368092,0,0,1,,,,2.5787E-7,14.00836,2.2924867,1.0570297,0
22579528.22,Error: Warning: Current field is 4512.853 Oe;
22579528.36,Error: but addenda was obtained at 10000.058 Oe.
22579584.97,,4881,0,1.4997,4512.853,9.2E-6,1.5137821,0.031831731,1.5892932,0.006131,0.20592227,0.00122,1.7952155,0.006131,1.2632975,7.0437544,0.005148392,99.277249,0,0,1,,,,2.5632E-7,14,2.2915363,1.0498824,0
22579634.14,,4881,0,1.5001,4512.853,9.3E-6,1.513916,0.032220923,1.5919096,0.006221,0.20596905,0.00122,1.7978786,0.006221,0.30623847,7.0120658,0.0044737232,99.368765,0,0,1,,,,2.5768E-7,14.08751,2.2919418,1.0515177,0
[...]
22790701.53,,4881,0,2.8001,2153.87,9.2E-6,2.8285445,0.059278171,3.3406488,0.01531,1.1152142,0.003803,4.455863,0.01531,0.24125042,7.6180419,0.010808322,99.243149,0,0,1,,,,5.8742E-7,15.27339,8.0006641,1.1810487,0
22790829.5,Error: Warning: Current field is 2307.702 Oe;
22790829.69,Error: but addenda was obtained at -0.025 Oe.
22790886.61,,4881,0,2.7998,2307.702,9.3E-6,2.8273597,0.055685348,3.3412762,0.01376,1.1142312,0.003804,4.4555073,0.01376,2.2375973,7.6192119,0.010333664,99.276139,0,0,1,,,,5.8717E-7,14,7.9939627,1.1817655,0
22790937.55,,4881,0,2.7998,2307.702,9.3E-6,2.8263091,0.058870393,3.3618353,0.01558,1.1122077,0.003804,4.474043,0.01558,0.57735266,7.5682955,0.0062799564,99.555522,0,0,1,,,,5.9265E-7,15.23842,7.988023,1.189479,0
22791065,Error: Warning: Current field is 2461.555 Oe;
22791065.13,Error: but addenda was obtained at -0.025 Oe.
22791120.77,,4881,0,2.8,2461.555,9.3E-6,2.8297156,0.055607074,3.3551127,0.01381,1.1172093,0.003802,4.472322,0.01381,1.9599483,7.6498363,0.0090764109,99.366362,0,0,1,,,,5.8673E-7,14,8.0072901,1.1856713,0
22791171.38,,4881,0,2.7998,2461.555,9.3E-6,2.8296719,0.059064975,3.3821662,0.01625,1.1165365,0.003803,4.4987027,0.01625,0.3338662,7.6108027,0.0065237374,99.540339,0,0,1,,,,5.9264E-7,15.29967,8.007043,1.1952503,0
22791300.02,Error: Warning: Current field is 2615.398 Oe;
22791300.14,Error: but addenda was obtained at -0.025 Oe.
22791355.98,,4881,0,2.8,2615.398,9.4E-6,2.8267819,0.0555246,3.3851419,0.01561,1.1136087,0.003804,4.4987506,0.01561,1.9991526,7.7399652,0.011823781,99.178932,0,0,1,,,,5.8397E-7,14,7.9906961,1.197525,0
22791406.23,,4881,0,2.8004,2615.398,9.4E-6,2.8283141,0.059010726,3.4168123,0.01608,1.1147692,0.003803,4.5315816,0.01608,0.40198111,7.6197155,0.0038041608,99.730738,0,0,1,,,,5.9563E-7,15.47993,7.9993607,1.2080739,0
22791534.27,Error: Warning: Current field is 2769.257 Oe;
22791534.48,Error: but addenda was obtained at -0.025 Oe.
22791591.05,,4881,0,2.8002,2769.257,9.4E-6,2.8293306,0.055334563,3.3906346,0.01565,1.1168206,0.003803,4.5074552,0.01565,1.4620492,7.7557664,0.011595924,99.196931,0,0,1,,,,5.8384E-7,14,8.0051115,1.1983876,0
22791640.27,,4881,0,2.8,2769.257,9.3E-6,2.8299008,0.058916437,3.4358403,0.0165,1.1168148,0.003803,4.5526551,0.0165,0.3677332,7.6553853,0.004470179,99.684451,0,0,1,,,,5.9577E-7,15.51153,8.0083387,1.2141204,0
22791769.06,Error: Warning: Current field is 2923.095 Oe;
22791769.19,Error: but addenda was obtained at -0.025 Oe.
22791825.88,,4881,0,2.7999,2923.095,9.3E-6,2.8262583,0.054936155,3.4420651,0.01492,1.1128257,0.003804,4.5548908,0.01492,2.1878784,7.7716132,0.0086568943,99.396132,0,0,1,,,,5.8813E-7,14,7.9877358,1.2178877,0
22791877.06,,4881,0,2.8002,2923.095,9.4E-6,2.8295895,0.0589889,3.4527749,0.01622,1.1165567,0.003803,4.5693317,0.01622,0.37304021,7.7359323,0.0075116586,99.473728,0,0,1,,,,5.9245E-7,15.54323,8.0065765,1.2202388,0
22792004.41,Error: Warning: Current field is 3076.938 Oe;
22792004.69,Error: but addenda was obtained at -0.025 Oe.
22792061.92,,4881,0,2.8001,3076.938,9.3E-6,2.826601,0.054909267,3.4583302,0.01523,1.1133631,0.003804,4.5716933,0.01523,2.0830718,7.8309601,0.011645244,99.191823,0,0,1,,,,5.8652E-7,14,7.9896733,1.2234943,0
22792113.28,,4881,0,2.8002,3076.938,9.2E-6,2.8301209,0.059171803,3.4763794,0.01567,1.1173553,0.003802,4.5937347,0.01567,0.22966522,7.8173955,0.0089573427,99.376936,0,0,1,,,,5.8974E-7,15.66192,8.0095843,1.2283501,0
22792241.38,Error: Warning: Current field is 3230.8 Oe;
22792241.53,Error: but addenda was obtained at -0.025 Oe.
22792298.23,,4881,0,2.8003,3230.8,9.2E-6,2.8268441,0.054735126,3.4724338,0.01484,1.1137003,0.003804,4.5861341,0.01484,2.2890498,7.9008089,0.011550175,99.20397,0,0,1,,,,5.8314E-7,14,7.9910474,1.2283783,0
22792348.23,,4881,0,2.8003,3230.8,9.3E-6,2.830521,0.059433965,3.4675825,0.01444,1.1179583,0.003802,4.5855408,0.01444,0.22029549,7.8285532,0.011833032,99.179136,0,0,1,,,,5.8852E-7,15.80162,8.0118489,1.2250687,0
22792476.3,Error: Warning: Current field is 3384.646 Oe;
22792476.44,Error: but addenda was obtained at -0.025 Oe.
22792532.42,,4881,0,2.7994,3384.646,9.4E-6,2.8258765,0.054798625,3.4774245,0.0125,1.1125088,0.003804,4.5899333,0.0125,0.94527705,7.9001514,0.012790973,99.117113,0,0,1,,,,5.8397E-7,14,7.9855782,1.2305649,0
22792583.83,,4881,0,2.8003,3384.646,9.2E-6,2.8314118,0.059429928,3.4586513,0.01429,1.1191334,0.003801,4.5777847,0.01429,0.2180306,7.8269267,0.014423455,99.000834,0,0,1,,,,5.8825E-7,15.8003,8.0168928,1.2215289,0
22792712.81,Error: Warning: Current field is 3538.482 Oe;
22792713.02,Error: but addenda was obtained at -0.025 Oe.
22792768.48,,4881,0,2.8005,3538.482,9.2E-6,2.8254155,0.055049977,3.4470423,0.01217,1.1119886,0.003805,4.5590309,0.01217,1.2781128,7.8894258,0.014623979,98.993373,0,0,1,,,,5.8123E-7,14,7.9829726,1.2200125,0
22792819.28,,4881,0,2.7998,3538.482,9.2E-6,2.8306132,0.060384274,3.3752201,0.01741,1.1183832,0.003802,4.4936033,0.01741,0.42450285,7.8506522,0.02152539,98.53036,0,0,1,,,,5.7722E-7,15.77885,8.0123713,1.1923989,0
22792949.28,Error: Warning: Current field is 3692.331 Oe;
22792949.5,Error: but addenda was obtained at -0.025 Oe.
22793005.41,,4881,0,2.7999,3692.331,9.2E-6,2.8260901,0.056031702,3.3494107,0.01881,1.1130435,0.003804,4.4624542,0.01881,2.0558667,7.8655523,0.018804979,98.72076,0,0,1,,,,5.7149E-7,14,7.9867853,1.1851748,0
22793056.48,,4881,0,2.7997,3692.331,9.3E-6,2.829469,0.061824931,3.2449034,0.02601,1.1171729,0.003802,4.3620763,0.02601,1.4976047,7.7979077,0.028329358,98.088864,0,0,1,,,,5.6544E-7,15.7311,8.0058948,1.1468242,0
22793184.72,Error: Warning: Current field is 3846.178 Oe;
22793184.98,Error: but addenda was obtained at -0.025 Oe.
22793240.06,,4881,0,2.7998,3846.178,9.4E-6,2.8285742,0.05714714,3.2059062,0.02825,1.1162451,0.003803,4.3221512,0.02825,8.1970007,7.696515,0.020948161,98.576994,0,0,1,,,,5.6604E-7,14,8.0008317,1.1334001,0
22793290.34,,4881,0,2.8003,3846.178,9.3E-6,2.8288194,0.062051588,3.1201223,0.03446,1.1164832,0.003803,4.2366055,0.03446,4.0376916,7.7450002,0.039893989,97.339053,0,0,1,,,,5.5516E-7,15.39303,8.0022194,1.1029768,0
22793419.27,Error: Warning: Current field is 4000.037 Oe;
22793419.42,Error: but addenda was obtained at -0.025 Oe.
22793475.86,,4881,0,2.8001,4000.037,9.2E-6,2.8245933,0.059055346,3.0181734,0.03789,1.1113791,0.003805,4.1295525,0.03789,21.73302,7.4911605,0.026198182,98.219593,0,0,1,,,,5.5661E-7,14,7.9783275,1.0685338,0
22793525.34,,4881,0,2.7994,4000.037,9.3E-6,2.826888,0.063027476,2.9331814,0.04128,1.1143233,0.003804,4.0475047,0.04128,4.3502051,7.4404058,0.033464868,97.742538,0,0,1,,,,5.5062E-7,14.98232,7.9912959,1.0376008,0
22793886.2,Error: Warning: Current field is 4000.014 Oe;
22793886.34,Error: but addenda was obtained at -0.025 Oe.
22793986.45,,4881,0,2.9003,4000.014,9.2E-6,2.9322956,0.062143957,1.4447556,0.00696,1.2535914,0.003605,2.698347,0.00696,0.87454931,4.5649366,0.024030967,97.902403,0,0,1,,,,5.9475E-7,9.077711,8.5983572,0.49270463,0
22794031.2,,4881,0,2.8997,4000.014,9.3E-6,2.9320738,0.06276977,1.4373873,0.006815,1.2532053,0.003605,2.6905927,0.006815,1.0672072,4.540859,0.017670393,98.446445,0,0,1,,,,5.9521E-7,9.129873,8.597057,0.49022891,0
22794160.47,Error: Warning: Current field is 3846.146 Oe;
22794160.66,Error: but addenda was obtained at -0.025 Oe.
22794260.36,,4881,0,2.8999,3846.146,9.2E-6,2.9275349,0.062132297,1.4721694,0.007282,1.2469892,0.003616,2.7191585,0.007282,0.65779875,4.567307,0.022006132,98.074706,0,0,1,,,,5.988E-7,9.163159,8.5704606,0.50286997,0
22794305.61,,4881,0,2.9004,3846.146,9.3E-6,2.9282343,0.062060721,1.4753596,0.006769,1.2479723,0.003615,2.7233319,0.006769,1.1722747,4.592144,0.021219006,98.152786,0,0,1,,,,5.9633E-7,9.134614,8.5745559,0.50383933,0
22794435.23,Error: Warning: Current field is 3692.307 Oe;
22794435.39,Error: but addenda was obtained at -0.025 Oe.
22794536.67,,4881,0,2.8999,3692.307,9.2E-6,2.9323387,0.062343417,1.4855702,0.007148,1.2536884,0.003604,2.7392586,0.007148,1.1351573,4.6057095,0.020484387,98.221107,0,0,1,,,,5.9794E-7,9.27546,8.5986101,0.50661617,0
22794579.95,,4881,0,2.8997,3692.307,9.3E-6,2.9303288,0.061863321,1.500195,0.007523,1.2507542,0.00361,2.7509492,0.007523,1.4930614,4.5908741,0.017356723,98.484463,0,0,1,,,,6.0197E-7,9.211419,8.5868269,0.51195449,0
22794708.36,Error: Warning: Current field is 3538.455 Oe;
22794708.5,Error: but addenda was obtained at -0.025 Oe.
22794808.72,,4881,0,2.9001,3538.455,9.3E-6,2.9250336,0.062190571,1.5346873,0.007532,1.243654,0.003622,2.7783413,0.007532,1.6275071,4.6600538,0.01851022,98.403426,0,0,1,,,,5.9917E-7,9.351628,8.5558217,0.52467337,0
22794852.38,,4881,0,2.9002,3538.455,9.2E-6,2.9254967,0.062161408,1.534213,0.007702,1.2442116,0.003621,2.7784246,0.007702,0.79839112,4.6520788,0.015666273,98.645266,0,0,1,,,,5.9975E-7,9.320108,8.5585309,0.52442821,0
22794980.53,Error: Warning: Current field is 3384.611 Oe;
22794980.86,Error: but addenda was obtained at -0.025 Oe.
22795081.48,,4881,0,2.8996,3384.611,9.4E-6,2.9258228,0.062367061,1.5438758,0.0079,1.2448413,0.00362,2.7887171,0.0079,1.5195717,4.6950806,0.019215301,98.354335,0,0,1,,,,5.9702E-7,9.41207,8.560439,0.52767236,0
22795126,,4881,0,2.8997,3384.611,9.2E-6,2.9300106,0.062395846,1.5403426,0.007808,1.2505233,0.00361,2.7908659,0.007808,1.2323106,4.6883916,0.015453157,98.674056,0,0,1,,,,5.9772E-7,9.390161,8.584962,0.52571229,0
22795254.25,Error: Warning: Current field is 3230.76 Oe;
22795254.45,Error: but addenda was obtained at -0.025 Oe.
22795355.44,,4881,0,2.9003,3230.76,9.4E-6,2.9278944,0.062813726,1.573327,0.00787,1.2479453,0.003615,2.8212722,0.00787,1.6448087,4.7719999,0.021716781,98.16773,0,0,1,,,,5.9466E-7,9.644664,8.5725654,0.53735784,0
22795399.94,,4881,0,2.9001,3230.76,9.4E-6,2.9253426,0.062806281,1.5780087,0.0082,1.2444423,0.003621,2.822451,0.0082,0.73135205,4.8019591,0.019731543,98.343327,0,0,1,,,,5.9088E-7,9.544,8.5576296,0.53942696,0
22795528.53,Error: Warning: Current field is 3076.916 Oe;
22795528.75,Error: but addenda was obtained at -0.025 Oe.
22795629.05,,4881,0,2.8996,3076.916,9.2E-6,2.9273641,0.063187848,1.6043563,0.008637,1.2473967,0.003616,2.851753,0.008637,2.2394369,4.8559288,0.020744623,98.274848,0,0,1,,,,5.9055E-7,9.728193,8.5694607,0.54805493,0
22795672.83,,4881,0,2.9004,3076.916,9.3E-6,2.9292743,0.063174554,1.5829082,0.008289,1.2499563,0.003611,2.8328645,0.008289,3.266667,4.8105878,0.021092835,98.233224,0,0,1,,,,5.922E-7,9.711858,8.5806477,0.54037557,0
22795800.47,Error: Warning: Current field is 2923.066 Oe;
22795800.64,Error: but addenda was obtained at -0.025 Oe.
22795900.55,,4881,0,2.8999,2923.066,9.4E-6,2.9257865,0.062619262,1.6301277,0.00958,1.2451429,0.00362,2.8752706,0.00958,2.7676548,4.8690067,0.019784178,98.35462,0,0,1,,,,5.9371E-7,9.722081,8.5602267,0.55715879,0
22795945.23,,4881,0,2.9,2923.066,9.4E-6,2.9269242,0.062719017,1.6308303,0.008823,1.2466314,0.003617,2.8774617,0.008823,0.95996606,4.8673518,0.015683517,98.6938,0,0,1,,,,5.937E-7,9.738013,8.566885,0.55718228,0
22796073.42,Error: Warning: Current field is 2769.223 Oe;
22796073.61,Error: but addenda was obtained at -0.025 Oe.
22796175.56,,4881,0,2.9002,2769.223,9.2E-6,2.9329051,0.063867792,1.6581447,0.009459,1.2544582,0.003603,2.9126029,0.009459,2.5707667,4.980252,0.02220414,98.193094,0,0,1,,,,5.8833E-7,10.1135,8.6019323,0.56535914,0
22796220.47,,4881,0,2.8998,2769.223,9.3E-6,2.9294512,0.063175228,1.650193,0.009289,1.2495782,0.003612,2.8997712,0.009289,1.627805,4.9480901,0.024521419,97.993203,0,0,1,,,,5.8994E-7,9.960504,8.5816841,0.56331132,0
22796348.39,Error: Warning: Current field is 2615.364 Oe;
22796348.7,Error: but addenda was obtained at -0.025 Oe.
22796449.73,,4881,0,2.9001,2615.364,9.4E-6,2.9277219,0.063456124,1.6910604,0.009424,1.2472501,0.003616,2.9383105,0.009424,2.6466184,5.0023363,0.020336614,98.345036,0,0,1,,,,5.9068E-7,10.13155,8.5715553,0.5776028,0
22796494.5,,4881,0,2.8999,2615.364,9.3E-6,2.9318998,0.063595709,1.6682905,0.009947,1.2532608,0.003605,2.9215513,0.009947,0.6445206,5.0608198,0.027462592,97.80134,0,0,1,,,,5.8154E-7,10.00467,8.5960364,0.56901347,0
22796622.77,Error: Warning: Current field is 2461.533 Oe;
22796623.09,Error: but addenda was obtained at -0.025 Oe.
22796725.89,,4881,0,2.8998,2461.533,9.3E-6,2.9301724,0.063806581,1.7159104,0.01032,1.2508935,0.003609,2.9668039,0.01032,2.3915731,5.1043654,0.022587189,98.196059,0,0,1,,,,5.8482E-7,10.24329,8.5859105,0.58560049,0
22796771.17,,4881,0,2.9002,2461.533,9.3E-6,2.9290915,0.063404601,1.7337463,0.0106,1.2494751,0.003612,2.9832214,0.0106,3.0826024,5.1390969,0.026588869,97.888744,0,0,1,,,,5.8475E-7,10.20873,8.5795769,0.59190584,0
22796898.48,Error: Warning: Current field is 2307.681 Oe;
22796898.72,Error: but addenda was obtained at -0.025 Oe.
22796999.78,,4881,0,2.9001,2307.681,9.3E-6,2.9303927,0.064056756,1.7377698,0.01158,1.2513513,0.003609,2.989121,0.01158,3.5145803,5.1705462,0.022976919,98.184694,0,0,1,,,,5.8173E-7,10.35268,8.5872015,0.593016,0
22797045.16,,4881,0,2.9006,2307.681,9.4E-6,2.9294438,0.063686619,1.7487072,0.01117,1.2498674,0.003611,2.9985745,0.01117,2.2494745,5.1154597,0.021349821,98.292281,0,0,1,,,,5.8966E-7,10.34109,8.5816408,0.5969417,0
22797172.44,Error: Warning: Current field is 2153.835 Oe;
22797172.64,Error: but addenda was obtained at -0.025 Oe.
22797273.42,,4881,0,2.8999,2153.835,9.3E-6,2.9276345,0.062764076,1.778926,0.01191,1.2475448,0.003615,3.0264708,0.01191,1.9595897,5.2493369,0.026094276,97.961043,0,0,1,,,,5.8071E-7,10.18507,8.571044,0.60763253,0
22797318,,4881,0,2.8998,2153.835,9.2E-6,2.9282819,0.064026045,1.776787,0.01219,1.2484421,0.003614,3.0252291,0.01219,1.060822,5.2093029,0.020003072,98.423359,0,0,1,,,,5.8396E-7,10.49867,8.5748351,0.60676772,0
22797445.5,Error: Warning: Current field is 1999.986 Oe;
22797445.8,Error: but addenda was obtained at -0.025 Oe.
22797547.72,,4881,0,2.9004,1999.986,9.3E-6,2.9266062,0.064425841,1.8283991,0.01304,1.2464367,0.003617,3.0748358,0.01304,2.549213,5.3388321,0.021733582,98.319331,0,0,1,,,,5.7943E-7,10.73383,8.5650239,0.62475065,0
22797592.41,,4881,0,2.9,1999.986,9.3E-6,2.9291454,0.063824216,1.8249297,0.01207,1.2497391,0.003611,3.0746688,0.01207,4.1684791,5.2801197,0.020979469,98.360887,0,0,1,,,,5.8574E-7,10.67766,8.5798925,0.62302463,0
22797719.92,Error: Warning: Current field is 1846.132 Oe;
22797720.23,Error: but addenda was obtained at -0.025 Oe.
22797822.03,,4881,0,2.9004,1846.132,9.3E-6,2.928532,0.062959274,1.847294,0.01342,1.2489654,0.003613,3.0962593,0.01342,5.6274116,5.3631238,0.024573618,98.106299,0,0,1,,,,5.8131E-7,10.39578,8.5762994,0.63079181,0
22797866.13,,4881,0,2.8993,1846.132,9.3E-6,2.9297913,0.064297363,1.8456118,0.01394,1.2509672,0.003609,3.096579,0.01394,2.2362571,5.4182383,0.023394162,98.215895,0,0,1,,,,5.7521E-7,10.72625,8.5836771,0.62994652,0
22797992.91,Error: Warning: Current field is 1692.297 Oe;
22797993.16,Error: but addenda was obtained at -0.025 Oe.
22798049.31,,4881,0,2.8994,1692.297,9.2E-6,2.9354779,0.074237465,1.8278051,0.01287,1.2581003,0.003597,3.0859053,0.01287,8.0900726,5.5071716,0.045403173,96.619138,0,0,1,,,,5.6728E-7,14,8.6170303,0.62266014,0
22798095.52,,4881,0,2.9001,1692.297,9.2E-6,2.9295533,0.064519657,1.89229,0.01385,1.2499083,0.003611,3.1421983,0.01385,3.3704172,5.4607875,0.024630773,98.126596,0,0,1,,,,5.7941E-7,11.01434,8.5822824,0.64593125,0
22798222.2,Error: Warning: Current field is 1538.451 Oe;
22798222.44,Error: but addenda was obtained at -0.025 Oe.
22798278.33,,4881,0,2.8998,1538.451,9.4E-6,2.9333696,0.07380587,1.8637351,0.0143,1.2551459,0.003602,3.118881,0.0143,3.0835018,5.5310563,0.043120355,96.78688,0,0,1,,,,5.7062E-7,14,8.6046572,0.63535639,0
22798324.61,,4881,0,2.8999,1538.451,9.4E-6,2.9342067,0.063049589,1.9312336,0.02376,1.2566192,0.003599,3.1878528,0.02348,3.2294167,5.3975655,0,100,0,0,1,,,,5.9061E-7,11.06211,8.6095689,0.65817914,0
22798451.22,Error: Warning: Current field is 1384.61 Oe;
22798451.56,Error: but addenda was obtained at -0.025 Oe.
22798507.84,,4881,0,2.9006,1384.61,9.3E-6,2.9312534,0.073314199,1.9051704,0.01378,1.2522271,0.003607,3.1573974,0.01378,9.2325458,5.5873604,0.040293041,97.010178,0,0,1,,,,5.7148E-7,14,8.5922466,0.64995075,0
22798553.38,,4881,0,2.8997,1384.61,9.4E-6,2.9289627,0.063755385,1.9543589,0.0243,1.2495791,0.003612,3.203938,0.02403,1.4602181,5.4658342,0,100,0,0,1,,,,5.8618E-7,11.17472,8.5788225,0.66725293,0
22798678.25,Error: Warning: Current field is 1230.761 Oe;
22798678.45,Error: but addenda was obtained at -0.025 Oe.
22798734.25,,4881,0,2.8997,1230.761,9.4E-6,2.9308939,0.072979212,1.9301204,0.01514,1.2517862,0.003608,3.1819065,0.01514,3.5922098,5.6346841,0.041097333,96.967215,0,0,1,,,,5.7125E-7,14,8.5901392,0.65854323,0
22798780.33,,4881,0,2.9004,1230.761,9.4E-6,2.9295378,0.064537957,1.9880088,0.01497,1.2501451,0.003611,3.2381539,0.01497,2.7847648,5.6392186,0.02323092,98.269179,0,0,1,,,,5.7805E-7,11.26937,8.5821916,0.67860834,0
22798907.31,Error: Warning: Current field is 1076.908 Oe;
22798907.52,Error: but addenda was obtained at -0.025 Oe.
22798964.34,,4881,0,2.9003,1076.908,9.3E-6,2.9369452,0.072585598,1.962288,0.01541,1.2603097,0.003593,3.2225977,0.01541,8.3002305,5.7348379,0.042655562,96.900649,0,0,1,,,,5.6865E-7,14,8.6256468,0.66813913,0
22799009.67,,4881,0,2.8993,1076.908,9.4E-6,2.9325872,0.065111358,2.0160981,0.01553,1.25459,0.003603,3.2706881,0.01553,1.8736937,5.7295964,0.023858734,98.246119,0,0,1,,,,5.7473E-7,11.46968,8.6000676,0.68748106,0
22799135.84,Error: Warning: Current field is 923.064 Oe;
22799135.95,Error: but addenda was obtained at -0.025 Oe.
22799192.94,,4881,0,2.8999,923.064,9.4E-6,2.9378789,0.070567076,2.0040199,0.02754,1.2615551,0.00359,3.2655749,0.0273,11.223691,5.5569383,0,100,0,0,1,,,,5.8766E-7,14,8.6311325,0.68213154,0
22799239.77,,4881,0,2.9003,923.064,9.3E-6,2.933494,0.0633087,2.0418856,0.01514,1.2556274,0.003601,3.2975129,0.01514,4.0995457,5.7566072,0.024128626,98.229499,0,0,1,,,,5.768E-7,11.11388,8.605387,0.69605923,0
22799365.16,Error: Warning: Current field is 769.223 Oe;
22799365.25,Error: but addenda was obtained at -0.025 Oe.
22799420.66,,4881,0,2.9005,769.223,9.4E-6,2.9328178,0.072019111,2.0313924,0.01531,1.2546942,0.003603,3.2860865,0.01531,19.324866,5.8509425,0.040491586,97.087281,0,0,1,,,,5.6812E-7,14,8.6014202,0.69264186,0
22799466.48,,4881,0,2.9004,769.223,9.3E-6,2.9279998,0.06509238,2.0702697,0.01637,1.2483899,0.003614,3.3186597,0.01637,2.0250812,5.8048836,0.024987221,98.172911,0,0,1,,,,5.7586E-7,11.70189,8.5731827,0.70705939,0
22799592.22,Error: Warning: Current field is 615.37 Oe;
22799592.36,Error: but addenda was obtained at -0.025 Oe.
22799649.16,,4881,0,2.9003,615.37,9.4E-6,2.933209,0.069697,2.082916,0.028,1.2551661,0.003602,3.3380821,0.02777,9.4303831,5.6779554,0,100,0,0,1,,,,5.879E-7,14,8.6037149,0.71011512,0
22799695.45,,4881,0,2.9002,615.37,9.2E-6,2.9275076,0.062138188,2.1352514,0.02716,1.2476931,0.003615,3.3829445,0.02692,5.9045938,5.7189641,0,100,0,0,1,,,,5.9153E-7,11.35591,8.5703005,0.72937519,0
22799818.86,Error: Warning: Current field is 461.531 Oe;
22799819.14,Error: but addenda was obtained at -0.025 Oe.
22799874.83,,4881,0,2.9001,461.531,9.4E-6,2.9319797,0.071665128,2.0763066,0.01662,1.2536716,0.003604,3.3299782,0.01662,16.507356,5.9653663,0.039764808,97.177371,0,0,1,,,,5.6457E-7,14,8.5965051,0.70815859,0
22799921.66,,4881,0,2.8998,461.531,9.3E-6,2.9280042,0.064954145,2.1392397,0.01756,1.2485336,0.003614,3.3877732,0.01756,2.41782,5.933559,0.023205823,98.324988,0,0,1,,,,5.7484E-7,11.93073,8.5732088,0.73061359,0
22800045.14,Error: Warning: Current field is 307.679 Oe;
22800045.5,Error: but addenda was obtained at -0.025 Oe.
22800101.77,,4881,0,2.8993,307.679,9.3E-6,2.9312712,0.071083079,2.124726,0.01772,1.2527493,0.003606,3.3774753,0.01772,9.3323788,6.0572726,0.038530679,97.288575,0,0,1,,,,5.6378E-7,14,8.5923506,0.72484798,0
22800148.75,,4881,0,2.8998,307.679,9.3E-6,2.9315935,0.064307808,2.1581822,0.02841,1.2530732,0.003606,3.4112554,0.02818,3.0022446,5.8061716,0,100,0,0,1,,,,5.8752E-7,12.11455,8.5942404,0.73618058,0