File: Data/HeatCapacity/IQM_IQMPPMS_20200223_1_TB_0-DRHCextra0T.dat
[Header]
TITLE,finish_0T_0p1_2p4
BYAPP,HeatCapacity,3.8.14,1.7
INFO,0,MASS:Sample Mass (mg)
INFO,0,MASSERR:Sample Mass Error (mg)
INFO,0,MOLWGHT:Formula Weight (g/mole)
INFO,0,ATOMS:Atoms per Formula Unit
INFO,PPMS Heat Capacity Option 3.8.14 Build 19,APPNAME
DATATYPE,TIME,1
DATATYPE,COMMENT,2
STARTUPAXIS, X, 8, LINEAR, AUTO
STARTUPAXIS, Y1, 10, LINEAR, AUTO
[Data]
Time Stamp (Seconds),Comment (),System Status (Code),Puck Temp (Kelvin),System Temp (Kelvin),Field (Oersted),Pressure (Torr),Sample Temp (Kelvin),Temp Rise (Kelvin),Samp HC (µJ/K),Samp HC Err (µJ/K),Addenda HC (µJ/K),Addenda HC Err (µJ/K),Total HC (µJ/K),Total HC Err (µJ/K),Fit Deviation (ChiSquare),Time Const tau1 (seconds),Time Const tau2 (seconds),Sample Coupling (Percent),Debye Temp (Kelvin),Debye Temp Err (Kelvin),Cal Correction (Factor),Therm Resist (Ohms),Htr Resist (Ohms),Puck Resist (Ohms),Wire Cond (W/K),Meas Time (seconds),Temp Squared (K^2),Samp HC/Temp (µJ/K/K),Addenda Offset HC (µJ/K)
4803276.77,Error: Warning: Current field is -0.022 Oe;
4803276.91,Error: but addenda was obtained at 20000.107 Oe.
4811534.17,,4881,0,0.099978,-0.022,9.3E-6,0.10054113,0.0022832538,0.78509588,0.02261,0.0040382781,-0.02177,0.78913416,0.006091,2.3003472,255.66461,0,100,0,0,1,,,,3.0866E-9,796.9986,0.010108518,7.8087037,0
4813655.58,,4881,0,0.099976,-0.022,9.4E-6,0.10046926,0.0022533052,0.78456538,0.02277,0.0040394294,-0.02179,0.78860481,0.006612,2.9012242,256.82888,0,100,0,0,1,,,,3.0705E-9,766.9938,0.010094073,7.809009,0
4816124.28,,4881,0,0.221,-0.022,9.2E-6,0.22259208,0.0054365704,0.19620064,0.003445,0.004834327,7.064E-5,0.20103497,0.003445,1.6286915,16.048273,0,100,0,0,1,,,,1.2527E-8,48.65435,0.049547236,0.88143585,0
4816268.28,,4881,0,0.2209,-0.022,9.4E-6,0.22239128,0.005439457,0.19831287,0.003121,0.004828565,6.139E-5,0.20314143,0.00312,1.5421687,16.109946,0,100,0,0,1,,,,1.261E-8,48.14482,0.049457882,0.89172951,0
4816731.22,,4881,0,0.342,-0.022,9.3E-6,0.34381261,0.0079910557,0.28632775,0.004319,0.010702084,0.0008906,0.29702983,0.004226,1.1587679,10.442016,0,100,0,0,1,,,,2.8446E-8,31.97964,0.11820711,0.83280177,0
4816834.5,,4881,0,0.342,-0.022,9.3E-6,0.34398472,0.0081304662,0.28905785,0.0036,0.010709576,0.0008908,0.29976743,0.0036,1.1635001,10.595707,0.00026850618,99.926394,0,0,1,,,,2.8311E-8,31.32605,0.11832549,0.84032177,0
4817330.95,,4881,0,0.4633,-0.022,9.3E-6,0.46556381,0.010618555,0.98641011,0.005915,0.02003732,0.0009456,1.0064474,0.005915,1.4344363,20.012001,0.00050593782,99.870279,0,0,1,,,,5.0355E-8,62.42291,0.21674966,2.1187431,0
4817499.23,,4881,0,0.463,-0.022,9.4E-6,0.46552453,0.010430045,0.97962705,0.006377,0.020038175,0.0009457,0.99966522,0.006377,0.8316507,20.116796,0.0020643159,99.475056,0,0,1,,,,4.9945E-8,60.036,0.21671309,2.1043511,0
4818171.27,,4881,0,0.5841,-0.022,9.4E-6,0.58648804,0.012619167,2.4381681,0.01367,0.032239536,0.001793,2.4704076,0.01367,0.98688808,32.755174,0.0024453346,99.417158,0,0,1,,,,7.5851E-8,100.136,0.34396822,4.1572341,0
4818429.72,,4881,0,0.5841,-0.022,9.3E-6,0.58628331,0.012426514,2.4471469,0.01588,0.03222079,0.00179,2.4793677,0.01588,1.6650766,32.55726,0.0012022671,99.711311,0,0,1,,,,7.6369E-8,98.26552,0.34372812,4.1740006,0
4818905.67,,4881,0,0.7052,-0.022,9.3E-6,0.70672521,0.012395716,4.4405965,0.0198,0.045510179,0.001408,4.4861067,0.0198,1.6858025,43.521512,0.0020287013,99.533715,0,0,1,,,,1.0355E-7,97.67178,0.49946053,6.2833424,0
4819240.22,,4881,0,0.705,-0.022,9.3E-6,0.70776117,0.014530303,4.4722844,0.01632,0.045614555,0.001416,4.5178989,0.01632,1.4730976,43.56372,0.0022986647,99.469349,0,0,1,,,,1.0425E-7,130.5645,0.50092587,6.3189174,0
4819800.69,,4881,0,0.8261,-0.022,9.4E-6,0.82786664,0.015038322,6.8584874,0.02564,0.061874316,0.002101,6.9203617,0.02564,1.4097532,50.923298,0.001623429,99.638964,0,0,1,,,,1.3638E-7,130.6912,0.68536318,8.2845317,0
4820245.52,,4881,0,0.8261,-0.022,9.4E-6,0.82863575,0.016493629,6.9192652,0.02503,0.062003694,0.002105,6.9812689,0.02503,1.4511936,51.273281,0.0023957524,99.466439,0,0,1,,,,1.3688E-7,152.7699,0.6866372,8.3501891,0
4820867.91,,4881,0,0.947,-0.022,9.3E-6,0.94950148,0.017413543,9.4722261,0.02396,0.082738731,0.001676,9.5549649,0.02396,0.92800014,56.448813,0.0019004607,99.606309,0,0,1,,,,1.6993E-7,153.8198,0.90155307,9.9759993,0
4821351.14,,4881,0,0.947,-0.022,9.3E-6,0.95027461,0.018737955,9.4927209,0.02008,0.082748639,0.001664,9.5754695,0.02008,1.5099037,56.576938,0.0019999173,99.585731,0,0,1,,,,1.6994E-7,169.3464,0.90302183,9.9894503,0
4822015.06,,4881,0,1.0682,-0.022,9.4E-6,1.0706381,0.019958245,12.114313,0.02342,0.084275591,0.001758,12.198589,0.02342,0.90287849,60.033084,0.0019326606,99.528611,0,0,1,,,,2.0415E-7,169.7308,1.1462659,11.315041,0
4822527.02,,4881,0,1.0677,-0.022,9.3E-6,1.0712792,0.021094433,12.093583,0.02571,0.084344091,0.001761,12.177927,0.02571,0.97262942,59.629126,0.001845009,99.548155,0,0,1,,,,2.0514E-7,180.0993,1.147639,11.288918,0
4835083.47,,4881,0,1.1901,-0.022,9.3E-6,1.1928238,0.023703752,14.559688,0.03718,0.099619146,0.001864,14.659307,0.03718,1.9778966,61.950547,0.003173053,99.235447,0,0,1,,,,2.3843E-7,178.8874,1.4228287,12.206067,0
4835609.34,,4881,0,1.1894,-0.022,9.3E-6,1.1923446,0.023404937,14.410458,0.03486,0.099520103,0.001863,14.509978,0.03486,1.4491875,59.260831,0.00097984298,99.756688,0,0,1,,,,2.4544E-7,185.8516,1.4216857,12.085816,0
4836304.83,,4881,0,1.3113,-0.022,9.2E-6,1.313242,0.024711939,16.667536,0.03545,0.12001115,0.002379,16.787547,0.03545,0.93392853,60.691931,0.0019902197,99.535897,0,0,1,,,,2.7787E-7,177.7825,1.7246047,12.691899,0
4836820.83,,4881,0,1.3114,-0.022,9.2E-6,1.3138716,0.02554168,16.668257,0.03458,0.12012099,0.002383,16.788378,0.03458,0.97201409,60.339515,0.0017845341,99.581978,0,0,1,,,,2.7938E-7,182.0758,1.7262587,12.686367,0
4837525.05,,4881,0,1.4319,-0.022,9.4E-6,1.4343632,0.027344771,18.724813,0.04535,0.14369969,0.002411,18.868513,0.04535,1.0458629,60.157257,0.0021727539,99.519878,0,0,1,,,,3.1514E-7,181.0185,2.0573978,13.054443,0
4837977.19,,4881,0,1.4322,-0.022,9.3E-6,1.4347507,0.027782305,18.704404,0.04186,0.14378069,0.002407,18.848185,0.04186,0.99243706,59.415477,0.0019402881,99.566799,0,0,1,,,,3.1859E-7,180.4718,2.0585096,13.036693,0
4838674.03,,4881,0,1.5523,-0.022,9.3E-6,1.5562847,0.029356105,20.457146,0.04108,0.17209596,0.001823,20.629242,0.04108,3.5172964,56.969194,0.00038958776,99.91727,0,0,1,,,,3.6241E-7,178.2464,2.422022,13.144861,0
4839159.8,,4881,0,1.553,-0.022,9.4E-6,1.5565054,0.029655509,20.388636,0.02874,0.1721959,0.001825,20.560832,0.02874,0.17893595,57.641129,0.0018207964,99.618227,0,0,1,,,,3.5805E-7,170.9076,2.4227089,13.098982,0
4839837.58,,4881,0,1.6738,-0.022,9.2E-6,1.6773818,0.031961592,21.840101,0.02864,0.20511118,0.002758,22.045212,0.02864,1.0981095,56.345504,0.0020481193,99.604142,0,0,1,,,,3.9278E-7,172.9234,2.8136098,13.020352,0
4840318.22,,4881,0,1.6738,-0.022,9.3E-6,1.6774278,0.03239654,21.733495,0.03344,0.20515592,0.00276,21.938651,0.03344,1.526812,56.401869,0.0027564894,99.469736,0,0,1,,,,3.9101E-7,169.0365,2.813764,12.956441,0
4840980.73,,4881,0,1.795,-0.022,9.4E-6,1.7980411,0.034592862,23.052719,0.03441,0.24361232,0.00334,23.296331,0.03441,2.003763,54.9725,0.0029678624,99.475627,0,0,1,,,,4.2597E-7,169.2056,3.2329516,12.821019,0
4841449.11,,4881,0,1.7948,-0.022,9.2E-6,1.7981824,0.034711399,23.0513,0.03252,0.24368089,0.00334,23.294981,0.03252,0.93878181,54.490215,0.0022816435,99.593902,0,0,1,,,,4.2921E-7,164.9175,3.2334599,12.819223,0
4843276.41,,4881,0,1.9158,-0.022,9.4E-6,1.919226,0.037074531,24.294659,0.03511,0.28983903,0.003673,24.584498,0.03511,1.0387302,53.03253,0.0031126364,99.493776,0,0,1,,,,4.6588E-7,163.4706,3.6834285,12.658571,0
4843731.41,,4881,0,1.9163,-0.022,9.2E-6,1.9190884,0.036969993,24.286745,0.03429,0.28981345,0.003673,24.576559,0.03429,0.84921734,52.925585,0.0026698788,99.565306,0,0,1,,,,4.6634E-7,159.0976,3.6829005,12.655355,0
4844366.56,,4881,0,2.0366,-0.022,9.3E-6,2.0396873,0.039226223,25.463806,0.03864,0.3447509,0.00461,25.808557,0.03864,0.75413894,51.338473,0.0027385814,99.593691,0,0,1,,,,5.0471E-7,158.7768,4.1603243,12.484171,0
4844754.8,,4881,0,2.037,-0.022,9.3E-6,2.0397346,0.039288103,25.468045,0.04033,0.34483185,0.004612,25.812877,0.04033,0.40952533,51.178521,0.0023491913,99.650586,0,0,1,,,,5.0609E-7,154.0154,4.1605173,12.48596,0
4845375.31,,4881,0,2.1576,-0.022,9.4E-6,2.1601196,0.041483409,26.702068,0.04335,0.40873594,0.005366,27.110804,0.04335,1.3429655,50.256163,0.0032863744,99.557784,0,0,1,,,,5.4178E-7,153.5356,4.6661166,12.361384,0
4845808.64,,4881,0,2.1577,-0.022,9.3E-6,2.1604043,0.041611138,26.743493,0.04409,0.40892999,0.005364,27.152423,0.04409,1.3458583,49.998126,0.0026637835,99.639612,0,0,1,,,,5.4497E-7,150.7685,4.6673466,12.37893,0
4846510.19,,4881,0,2.2792,-0.022,9.2E-6,2.2841388,0.043551021,28.032861,0.02785,0.48059716,0.003321,28.513458,0.02785,0.9700755,49.209291,0.0029891308,99.632174,0,0,1,,,,5.815E-7,149.9944,5.21729,12.272836,0
4846933.03,,4881,0,2.279,-0.022,9.2E-6,2.2832892,0.043641372,28.067008,0.03259,0.48013939,0.003333,28.547147,0.03259,2.091671,49.274328,0.003160373,99.610721,0,0,1,,,,5.8154E-7,147.6279,5.2134094,12.292358,0
4847524.08,,4881,0,2.4003,-0.022,9.3E-6,2.4073803,0.045738521,29.40708,0.02888,0.55983746,0.002904,29.966918,0.02888,0.77089203,48.703252,0.0032599432,99.633648,0,0,1,,,,6.1747E-7,147.823,5.7954801,12.215386,0
4847896.86,,4881,0,2.3999,-0.022,9.3E-6,2.4026216,0.046007511,29.457793,0.03152,0.55665894,0.002884,30.014452,0.03152,0.26746128,48.576894,0.0033653421,99.618046,0,0,1,,,,6.2016E-7,146.1098,5.7725905,12.260688,0